Workbook

Sheet 뱅샐현황
B3: 1.고객정보
B4: 사용자의 기본 정보에 해당하는 항목입니다.
B5: 이름 | C5: 성별 | D5: 연령 (만 나이) | E5: 신용점수 (KCB) | F5: 이메일
B6: 김용 | C6: 남 | D6: 46 | E6: 1000 | F6: -
B9: 2.현금흐름현황
B10: 최근 1년 동안의 현금흐름을 분석합니다.
B11: 항목 | C11: 총계 | D11: 월평균 | E11: 2025-07 | F11: 2025-08 | G11: 2025-09 | H11: 2025-10 | I11: 2025-11 | J11: 2025-12 | K11: 2026-01 | L11: 2026-02 | M11: 2026-03 | N11: 2026-04 | O11: 2026-05 | P11: 2026-06 | Q11: 2026-07
B12: 금융수입 | C12: =SUM(E12:Q12) | D12: =C12/13 | E12: 0 | F12: 0 | G12: 80000 | H12: 1 | I12: 0 | J12: 20000 | K12: 0 | L12: 0 | M12: 4 | N12: 0 | O12: 1 | P12: 0 | Q12: 0
B13: 급여 | C13: =SUM(E13:Q13) | D13: =C13/13 | E13: 0 | F13: 5107809 | G13: 5863980 | H13: 10584640 | I13: 5897358 | J13: 9609713 | K13: 5869380 | L13: 12652275 | M13: 6055700 | N13: 6132550 | O13: 6052268 | P13: 6022650 | Q13: 6065877
B14: 기타수입 | C14: =SUM(E14:Q14) | D14: =C14/13 | E14: 0 | F14: 0 | G14: 0 | H14: 0 | I14: 0 | J14: 0 | K14: 0 | L14: 0 | M14: 0 | N14: 0 | O14: 0 | P14: 10430 | Q14: 0
B15: 사업수입 | C15: =SUM(E15:Q15) | D15: =C15/13 | E15: 0 | F15: 0 | G15: 0 | H15: 0 | I15: 0 | J15: 0 | K15: 0 | L15: 0 | M15: 0 | N15: 1064432 | O15: 0 | P15: 0 | Q15: 0
B16: 상여금 | C16: =SUM(E16:Q16) | D16: =C16/13 | E16: 0 | F16: 0 | G16: 0 | H16: 0 | I16: 0 | J16: 0 | K16: 0 | L16: 0 | M16: 0 | N16: 0 | O16: 0 | P16: 2378785 | Q16: 0
B17: 미분류 | C17: =SUM(E17:Q17) | D17: =C17/13 | E17: 0 | F17: 0 | G17: 0 | H17: 0 | I17: 0 | J17: 0 | K17: 0 | L17: 0 | M17: 0 | N17: 0 | O17: 0 | P17: 0 | Q17: 2279856
B18: 월수입 총계 | C18: =SUM(E18:Q18) | D18: =C18/13 | E18: =SUM(E12:E17) | F18: =SUM(F12:F17) | G18: =SUM(G12:G17) | H18: =SUM(H12:H17) | I18: =SUM(I12:I17) | J18: =SUM(J12:J17) | K18: =SUM(K12:K17) | L18: =SUM(L12:L17) | ... Q18: =SUM(Q12:Q17)
A19: 필수 | B19: 경조/선물 | C19: =SUM(E19:Q19) | D19: =C19/13 | E19: 700000 | F19: 730000 | G19: 700000 | H19: 930000 | I19: 750000 | J19: 750000 | K19: 750000 | L19: 760336 | M19: 721000 | N19: 750000 | O19: 750000 | P19: 750000 | Q19: 50000
A20: 선택 | B20: 교육/학습 | C20: =SUM(E20:Q20) | D20: =C20/13 | E20: 0 | F20: 0 | G20: 10200 | H20: 0 | I20: 0 | J20: 12000 | K20: 85700 | L20: 92190 | M20: 0 | N20: 6000 | O20: 0 | P20: 0 | Q20: 0
A21: 필수 | B21: 교통 | C21: =SUM(E21:Q21) | D21: =C21/13 | E21: 0 | F21: 2900 | G21: 30000 | H21: 30000 | I21: 60750 | J21: 50000 | K21: 63200 | L21: 75300 | M21: 60000 | N21: 53200 | O21: 60000 | P21: 63400 | Q21: 71500
A22: 필수 | B22: 금융 | C22: =SUM(E22:Q22) | D22: =C22/13 | E22: 60380 | F22: 1313802 | G22: 121577701 | H22: 1659562 | I22: 1384699 | J22: 1498194 | K22: 2075322 | L22: 1863655 | M22: 2015670 | N22: 1818208 | O22: 2053519 | P22: 2005859 | Q22: 1995597
A23: 선택 | B23: 문화/여가 | C23: =SUM(E23:Q23) | D23: =C23/13 | E23: 0 | F23: 21900 | G23: 9270 | H23: 0 | I23: 7000 | J23: 18000 | K23: 71490 | L23: 34900 | M23: 54490 | N23: 37900 | O23: 4000 | P23: 48700 | Q23: 11000
A24: 선택 | B24: 반려동물 | C24: =SUM(E24:Q24) | D24: =C24/13 | E24: 0 | F24: 0 | G24: 0 | H24: 0 | I24: 0 | J24: 0 | K24: 0 | L24: 0 | M24: 0 | N24: 0 | O24: 0 | P24: 32500 | Q24: 0
A25: 선택 | B25: 뷰티/미용 | C25: =SUM(E25:Q25) | D25: =C25/13 | E25: 0 | F25: 52400 | G25: 81670 | H25: 41200 | I25: 102433 | J25: 83333 | K25: 150833 | L25: 83333 | M25: 101933 | N25: 83333 | O25: 43610 | P25: 37660 | Q25: 88170
A26: 선택 | B26: 생활 | C26: =SUM(E26:Q26) | D26: =C26/13 | E26: 0 | F26: 517390 | G26: 562764 | H26: 384580 | I26: 657570 | J26: 562880 | K26: 406777 | L26: 664860 | M26: 238890 | N26: 248160 | O26: 611080 | P26: 180400 | Q26: 231160
A27: 선택 | B27: 술/유흥 | C27: =SUM(E27:Q27) | D27: =C27/13 | E27: 0 | F27: 0 | G27: 0 | H27: 0 | I27: 28500 | J27: 0 | K27: 0 | L27: 0 | M27: 0 | N27: 121400 | O27: 0 | P27: 0 | Q27: 0
A28: 선택 | B28: 식비 | C28: =SUM(E28:Q28) | D28: =C28/13 | E28: 198963 | F28: 1064704 | G28: 534182 | H28: 619454 | I28: 814865 | J28: 586715 | K28: 951826 | L28: 1051308 | M28: 1223049 | N28: 824610 | O28: 1109662 | P28: 717950 | Q28: 1162035
A29: 선택 | B29: 여행/숙박 | C29: =SUM(E29:Q29) | D29: =C29/13 | E29: 0 | F29: 0 | G29: 0 | H29: 42000 | I29: 0 | J29: 0 | K29: 28500 | L29: 126254 | M29: 3000 | N29: 61400 | O29: 10000 | P29: 220900 | Q29: 0
A30: 선택 | B30: 온라인쇼핑 | C30: =SUM(E30:Q30) | D30: =C30/13 | E30: 95160 | F30: 796617 | G30: 5908354 | H30: 478950 | I30: 1478034 | J30: 251792 | K30: 894758 | L30: 253822 | M30: 505824 | N30: 365333 | O30: 286309 | P30: 688755 | Q30: 188672
... A37: 선택 | B37: 미분류 | C37: =SUM(E37:Q37) | D37: =C37/13 | E37: 0 | F37: 0 | G37: 0 | H37: 0 | I37: 0 | J37: 0 | K37: 0 | L37: 0 | M37: 0 | N37: 0 | O37: 0 | P37: 0 | Q37: 0
B38: 월지출 총계 | C38: =SUM(E38:Q38) | D38: =C38/13 | E38: =SUM(E19:E37) | F38: =SUM(F19:F37) | G38: =SUM(G19:G37) | H38: =SUM(H19:H37) | I38: =SUM(I19:I37) | J38: =SUM(J19:J37) | K38: =SUM(K19:K37) | L38: =SUM(L19:L37) | ... Q38: =SUM(Q19:Q37)
B39: 순수입 총계 | C39: =SUM(E39:Q39) | D39: =C39/13 | E39: =E18-E38 | F39: =F18-F38 | G39: =G18-G38 | H39: =H18-H38 | I39: =I18-I38 | J39: =J18-J38 | K39: =K18-K38 | L39: =L18-L38 | ... Q39: =Q18-Q38
B42: 3.재무현황
B43: 데이터를 내보낸 시점의 자산과 부채 상태를 분석합니다.
B44: 자산 | F44: 부채
B45: 항목 | C45: 상품명 | E45: 금액 | F45: 항목 | G45: 상품명 | I45: 금액
B46: 자유입출금 자산 | C46: AMA+급여 MMDA | E46: 0 | F46: 장기대출 | G46: 하나은행 마이너스 통장 | I46: 121685737
C47: AMA+급여 저축예금 | E47: 0 | G47: 가계일반자금대출(분할상환)-하나 아파트론(혼합금리형) | I47: 207103001
C48: MY 입출금통장 | E48: 1 | G48: 하나은행 마이너스 통장 | I48: 1726305
C49: NH주거래우대통장(비대면실명확인) | E49: 0 | G49: 2020년 2학기 일반상환학자금_등록금 | I49: 5448520
C50: 넘버엔 통장 | E50: -121685737 | G50: 2021년 2학기 일반상환학자금_등록금 | I50: 5441312
C51: 달달 하나 통장 | E51: -1726305 | G51: 2020년 1학기 일반상환학자금_등록금 | I51: 5198750
C52: 샐러리맨리치예금(스페셜플러스예금) | E52: 86 | G52: 2021년 1학기 일반상환학자금_등록금 | I52: 5129730
...

Sheet 대시보드
B1: 전체 투자금 | C1: 16666666 | G1: 채권 | H1: =C3/3
B2: 한국 개별주 퀀트 | C2: =C1*60% | G2: 변형 듀얼모멘텀 | H2: =C3/3
B3: 동적자산배분 | C3: =C1*40% | G3: BAA | H3: =C3/3
B5: ㅣBAA | H5: ㅣ변형 듀얼모멘텀 | O5: ㅣ채권 동적자산배분
B6: Q. 카나리아 자산 중 "0"이하인 모멘텀 스코어가 있나요? | H6: Step1. 공격자산 수익률이 모두 "0"이상인 경우, 수익률이 높은 자산에 100%투자합니다
B7: ㅣBAA중도형_카나리아 자산
C8: =BD!Z28 | H8: ㅣ변형 듀얼모멘텀_공격자산
B9: SPY | C9: =BD!Z29 | H9: =BD!A36 | I9: =BD!B36
B10: EFA | C10: =BD!Z30 | H10: =BD!A37 | I10: =BD!B37
B11: EEM | C11: =BD!Z31 | H11: =BD!A38 | I11: =BD!B38
B12: AGG | C12: =BD!Z32
H13: Step2. SPY의 수익률이 "0"이하인 경우, 안전자산 중 수익률 높은 채권 3개를 매수합니다 But, 수익률이 "0" 이하인 자산은 현금보유
B14: A-1. 네, "0" 이하가 있어요
B15: 공격자산 투자중단! ↓아래있는 안전자산의 최근수익률이 높은 3개 자산에 투자합니다 But,(현재가격<12개월 이동평균)이면 현금으로 보유
H16: 종목당 투자금액 | I16: =H2/3
B17: 종목당 투자액 | C17: =H3/3 | H17: ㅣ변형 듀얼모멘텀_안전자산
B18: ㅣBAA 안전자산 | H18: =BD!A41 | I18: =BD!T41 | N18: 216 9002
C19: 현재/12개월이평 | D19: =BD!B18 | E19: =BD!P18 | H19: =BD!A42 | I19: =BD!T42
B20: =BD!A19 | C20: =BD!Q19 | D20: =BD!B19 | E20: =BD!P19 | H20: =BD!A43 | I20: =BD!T43
B21: =BD!A20 | C21: =BD!Q20 | D21: =BD!B20 | E21: =BD!P20 | H21: =BD!A44 | I21: =BD!T44
B22: =BD!A21 | C22: =BD!Q21 | D22: =BD!B21 | E22: =BD!P21 | H22: =BD!A45 | I22: =BD!T45
B23: =BD!A22 | C23: =BD!Q22 | D23: =BD!B22 | E23: =BD!P22 | H23: =BD!A46 | I23: =BD!T46
B24: =BD!A23 | C24: =BD!Q23 | D24: =BD!B23 | E24: =BD!P23 | H24: =BD!A47 | I24: =BD!T47
B25: =BD!A24 | C25: =BD!Q24 | D25: =BD!B24 | E25: =BD!P24 | H25: =BD!A48 | I25: =BD!T48
B26: =BD!A25 | C26: =BD!Q25 | D26: =BD!B25 | E26: =BD!P25 | H26: =BD!A49 | I26: =BD!T49
B28: A-2. 모두 "0" 보다 커요(BAA중도형) | E28: A-2. 모두 "0" 보다 커요(BAA공격형)
B29: ↓아래있는 [BAA중도형_공격자산 12종목] 또는 [BAA공격형]중 모멘텀 스코어가 높은 6개 자산에 투자합니다 | E29: BAA 공격형 투자는 최근수익률이 높은 1개 자산에 몰빵! 합니다
B31: 종목당 투자액 | C31: =H3/6 | E31: 종목당 투자액 | F31: =H3
B32: ㅣBAA 중도형_공격자산 12종목 | E32: ㅣBAA공격형(수익↑, MDD↑)
C33: =BD!Z4 | D33: 현재/12개월이평 | F33: 모멘텀 스코어 | G33: 현재/12개월이평
B34: =BD!A5 | C34: =BD!Z5 | D34: =BD!Q5 | E34: =관심종목!D26 | F34: =BD!Z33 | G34: =BD!Q29
B35: =BD!A6 | C35: =BD!Z6 | D35: =BD!Q6 | E35: =관심종목!D23 | F35: =BD!Z30 | G35: =BD!Q30
B36: =BD!A7 | C36: =BD!Z7 | D36: =BD!Q7 | E36: =관심종목!D24 | F36: =BD!Z31 | G36: =BD!Q31
B37: =BD!A8 | C37: =BD!Z8 | D37: =BD!Q8 | E37: =관심종목!D25 | F37: =BD!Z32 | G37: =BD!Q32
B38: =BD!A9 | C38: =BD!Z9 | D38: =BD!Q9
B39: =BD!A10 | C39: =BD!Z10 | D39: =BD!Q10
B40: =BD!A11 | C40: =BD!Z11 | D40: =BD!Q11
B41: =BD!A12 | C41: =BD!Z12 | D41: =BD!Q12
B42: =BD!A13 | C42: =BD!Z13 | D42: =BD!Q13
B43: =BD!A14 | C43: =BD!Z14 | D43: =BD!Q14
...

Sheet 관심종목
D1: 안내 B열에 추적할 주식의 종목코드를 입력합니다. H열에 평가금액을 추적할 주식의 수량을 입력합니다. | L1: 제공: | P1: 차트 보기 안내 | X1: 관심종목 통합 차트
L2: Google Finance | P2: D열 Ticker를 클릭하면 오른쪽 통합 차트 영역으로 이동합니다. | X2: 선택 Ticker | Y2: SPY | Z2: 차트 기간 | AA2: 최근 1년
P3: Y2에서 Ticker를 선택하면 차트가 업데이트됩니다. | X3: 사용법 | Y3: Y2에서 Ticker를 선택하면 아래 차트가 해당 종목으로 갱신됩니다. D열 Ticker 클릭 시 이 차트 영역으로 이동합니다.
F4: 관심종목
F5: 평가금액 | P5: 이벤트 관리로 이동
F6: =SUM(N9:N55)
A8: 전략 명 | B8: 투자비율 | C8: 포트폴리오 명 | D8: 종목코드 | E8: 거래소 (선택사항) | F8: 종목명 | H8: 현재가 | I8: 전일대비 | J8: 등락률(%) | K8: 주식수 | L8: 평가금액 | M8: 종목 합계 | O8: 모멘텀스코어 | P8: 1개월수익률 | Q8: 3개월수익률 | R8: 6개월수익률 | S8: 12개월수익률 | T8: 12개월 이동평균 | U8: 현재가격/ 12개월이동평균
E9: NASDAQ | F9: =IFERROR(__xludf.DUMMYFUNCTION("IF(ISBLANK(D9), ""-"", GOOGLEFINANCE(IF(ISBLANK(E9), D9, E9&"":""&D9), ""name""))"),"-") | H9: =IFERROR(__xludf.DUMMYFUNCTION("IF(ISBLANK(D9), 0, GOOGLEFINANCE(IF(ISBLANK(E9), D9, E9&"":""&D9), ""price""))"),0) | I9: =IFERROR(__xludf.DUMMYFUNCTION("IF(ISBLANK(D9), 0, GOOGLEFINANCE(IF(ISBLANK(E9), D9, E9&"":""&D9), ""change""))"),0) | J9: =IFERROR(__xludf.DUMMYFUNCTION("IF(ISBLANK(D9), 0, GOOGLEFINANCE(IF(ISBLANK(E9), D9, E9&"":""&D9), ""changepct"")/100)"),0) | K9: 0 | L9: =K9 * H9 | O9: =(P9*12)+(Q9*4)+(R9*2)+(S9*1)
C10: BAA 공격자산 | D10: SPY | F10: =IFERROR(__xludf.DUMMYFUNCTION("IF(ISBLANK(D10), ""-"", GOOGLEFINANCE(IF(ISBLANK(E10), D10, E10&"":""&D10), ""name""))"),"State Street SPDR S&P 500 ETF Trust") | H10: =IFERROR(__xludf.DUMMYFUNCTION("IF(ISBLANK(D10), 0, GOOGLEFINANCE(IF(ISBLANK(E10), D10, E10&"":""&D10), ""price""))"),729.46) | I10: =IFERROR(__xludf.DUMMYFUNCTION("IF(ISBLANK(D10), 0, GOOGLEFINANCE(IF(ISBLANK(E10), D10, E10&"":""&D10), ""change""))"),-11.4) | J10: =IFERROR(__xludf.DUMMYFUNCTION("IF(ISBLANK(D10), 0, GOOGLEFINANCE(IF(ISBLANK(E10), D10, E10&"":""&D10), ""changepct"")/100)"),-0.0154) | K10: 1 | L10: =K10 * H10 | O10: =(P10*12)+(Q10*4)+(R10*2)+(S10*1) | P10: =IFERROR((INDEX(차트데이터!$A:$BZ,254,MATCH(D10,차트데이터!$1:$1,0)+1)-INDEX(차트데이터!$A:$BZ,232,MATCH(D10,차트데이터!$1:$1,0)+1))/INDEX(차트데이터!$A:$BZ,232,MATCH(D10,차트데이터!$1:$1,0)+1),"") | Q10: =IFERROR((INDEX(차트데이터!$A:$BZ,254,MATCH(D10,차트데이터!$1:$1,0)+1)-INDEX(차트데이터!$A:$BZ,190,MATCH(D10,차트데이터!$1:$1,0)+1))/INDEX(차트데이터!$A:$BZ,190,MATCH(D10,차트데이터!$1:$1,0)+1),"") | R10: =IFERROR((INDEX(차트데이터!$A:$BZ,254,MATCH(D10,차트데이터!$1:$1,0)+1)-INDEX(차트데이터!$A:$BZ,127,MATCH(D10,차트데이터!$1:$1,0)+1))/INDEX(차트데이터!$A:$BZ,127,MATCH(D10,차트데이터!$1:$1,0)+1),"") | S10: =IFERROR((INDEX(차트데이터!$A:$BZ,254,MATCH(D10,차트데이터!$1:$1,0)+1)-INDEX(차트데이터!$A:$BZ,4,MATCH(D10,차트데이터!$1:$1,0)+1))/INDEX(차트데이터!$A:$BZ,4,MATCH(D10,차트데이터!$1:$1,0)+1),"")
D11: QQQ | F11: =IFERROR(__xludf.DUMMYFUNCTION("IF(ISBLANK(D11), ""-"", GOOGLEFINANCE(IF(ISBLANK(E11), D11, E11&"":""&D11), ""name""))"),"Invesco QQQ Trust, Series 1") | H11: =IFERROR(__xludf.DUMMYFUNCTION("IF(ISBLANK(D11), 0, GOOGLEFINANCE(IF(ISBLANK(E11), D11, E11&"":""&D11), ""price""))"),661.73) | I11: =IFERROR(__xludf.DUMMYFUNCTION("IF(ISBLANK(D11), 0, GOOGLEFINANCE(IF(ISBLANK(E11), D11, E11&"":""&D11), ""change""))"),-13.76) | J11: =IFERROR(__xludf.DUMMYFUNCTION("IF(ISBLANK(D11), 0, GOOGLEFINANCE(IF(ISBLANK(E11), D11, E11&"":""&D11), ""changepct"")/100)"),-0.0204) | K11: 1 | L11: =K11 * H11 | O11: =(P11*12)+(Q11*4)+(R11*2)+(S11*1) | P11: =IFERROR((INDEX(차트데이터!$A:$BZ,254,MATCH(D11,차트데이터!$1:$1,0)+1)-INDEX(차트데이터!$A:$BZ,232,MATCH(D11,차트데이터!$1:$1,0)+1))/INDEX(차트데이터!$A:$BZ,232,MATCH(D11,차트데이터!$1:$1,0)+1),"") | Q11: =IFERROR((INDEX(차트데이터!$A:$BZ,254,MATCH(D11,차트데이터!$1:$1,0)+1)-INDEX(차트데이터!$A:$BZ,190,MATCH(D11,차트데이터!$1:$1,0)+1))/INDEX(차트데이터!$A:$BZ,190,MATCH(D11,차트데이터!$1:$1,0)+1),"") | R11: =IFERROR((INDEX(차트데이터!$A:$BZ,254,MATCH(D11,차트데이터!$1:$1,0)+1)-INDEX(차트데이터!$A:$BZ,127,MATCH(D11,차트데이터!$1:$1,0)+1))/INDEX(차트데이터!$A:$BZ,127,MATCH(D11,차트데이터!$1:$1,0)+1),"") | S11: =IFERROR((INDEX(차트데이터!$A:$BZ,254,MATCH(D11,차트데이터!$1:$1,0)+1)-INDEX(차트데이터!$A:$BZ,4,MATCH(D11,차트데이터!$1:$1,0)+1))/INDEX(차트데이터!$A:$BZ,4,MATCH(D11,차트데이터!$1:$1,0)+1),"")
D12: IWM | F12: =IFERROR(__xludf.DUMMYFUNCTION("IF(ISBLANK(D12), ""-"", GOOGLEFINANCE(IF(ISBLANK(E12), D12, E12&"":""&D12), ""name""))"),"iShares Russell 2000 ETF") | H12: =IFERROR(__xludf.DUMMYFUNCTION("IF(ISBLANK(D12), 0, GOOGLEFINANCE(IF(ISBLANK(E12), D12, E12&"":""&D12), ""price""))"),288.57) | I12: =IFERROR(__xludf.DUMMYFUNCTION("IF(ISBLANK(D12), 0, GOOGLEFINANCE(IF(ISBLANK(E12), D12, E12&"":""&D12), ""change""))"),-4.8) | J12: =IFERROR(__xludf.DUMMYFUNCTION("IF(ISBLANK(D12), 0, GOOGLEFINANCE(IF(ISBLANK(E12), D12, E12&"":""&D12), ""changepct"")/100)"),-0.0163999999999999) | K12: 1 | L12: =K12 * H12 | O12: =(P12*12)+(Q12*4)+(R12*2)+(S12*1) | P12: =IFERROR((INDEX(차트데이터!$A:$BZ,254,MATCH(D12,차트데이터!$1:$1,0)+1)-INDEX(차트데이터!$A:$BZ,232,MATCH(D12,차트데이터!$1:$1,0)+1))/INDEX(차트데이터!$A:$BZ,232,MATCH(D12,차트데이터!$1:$1,0)+1),"") | Q12: =IFERROR((INDEX(차트데이터!$A:$BZ,254,MATCH(D12,차트데이터!$1:$1,0)+1)-INDEX(차트데이터!$A:$BZ,190,MATCH(D12,차트데이터!$1:$1,0)+1))/INDEX(차트데이터!$A:$BZ,190,MATCH(D12,차트데이터!$1:$1,0)+1),"") | R12: =IFERROR((INDEX(차트데이터!$A:$BZ,254,MATCH(D12,차트데이터!$1:$1,0)+1)-INDEX(차트데이터!$A:$BZ,127,MATCH(D12,차트데이터!$1:$1,0)+1))/INDEX(차트데이터!$A:$BZ,127,MATCH(D12,차트데이터!$1:$1,0)+1),"") | S12: =IFERROR((INDEX(차트데이터!$A:$BZ,254,MATCH(D12,차트데이터!$1:$1,0)+1)-INDEX(차트데이터!$A:$BZ,4,MATCH(D12,차트데이터!$1:$1,0)+1))/INDEX(차트데이터!$A:$BZ,4,MATCH(D12,차트데이터!$1:$1,0)+1),"")
D13: VGK | F13: =IFERROR(__xludf.DUMMYFUNCTION("IF(ISBLANK(D13), ""-"", GOOGLEFINANCE(IF(ISBLANK(E13), D13, E13&"":""&D13), ""name""))"),"Vanguard European Stock Index Fund ETF") | H13: =IFERROR(__xludf.DUMMYFUNCTION("IF(ISBLANK(D13), 0, GOOGLEFINANCE(IF(ISBLANK(E13), D13, E13&"":""&D13), ""price""))"),88.86) | I13: =IFERROR(__xludf.DUMMYFUNCTION("IF(ISBLANK(D13), 0, GOOGLEFINANCE(IF(ISBLANK(E13), D13, E13&"":""&D13), ""change""))"),-0.37) | J13: =IFERROR(__xludf.DUMMYFUNCTION("IF(ISBLANK(D13), 0, GOOGLEFINANCE(IF(ISBLANK(E13), D13, E13&"":""&D13), ""changepct"")/100)"),-0.00409999999999999) | K13: 1 | L13: =K13 * H13 | O13: =(P13*12)+(Q13*4)+(R13*2)+(S13*1) | P13: =IFERROR((INDEX(차트데이터!$A:$BZ,254,MATCH(D13,차트데이터!$1:$1,0)+1)-INDEX(차트데이터!$A:$BZ,232,MATCH(D13,차트데이터!$1:$1,0)+1))/INDEX(차트데이터!$A:$BZ,232,MATCH(D13,차트데이터!$1:$1,0)+1),"") | Q13: =IFERROR((INDEX(차트데이터!$A:$BZ,254,MATCH(D13,차트데이터!$1:$1,0)+1)-INDEX(차트데이터!$A:$BZ,190,MATCH(D13,차트데이터!$1:$1,0)+1))/INDEX(차트데이터!$A:$BZ,190,MATCH(D13,차트데이터!$1:$1,0)+1),"") | R13: =IFERROR((INDEX(차트데이터!$A:$BZ,254,MATCH(D13,차트데이터!$1:$1,0)+1)-INDEX(차트데이터!$A:$BZ,127,MATCH(D13,차트데이터!$1:$1,0)+1))/INDEX(차트데이터!$A:$BZ,127,MATCH(D13,차트데이터!$1:$1,0)+1),"") | S13: =IFERROR((INDEX(차트데이터!$A:$BZ,254,MATCH(D13,차트데이터!$1:$1,0)+1)-INDEX(차트데이터!$A:$BZ,4,MATCH(D13,차트데이터!$1:$1,0)+1))/INDEX(차트데이터!$A:$BZ,4,MATCH(D13,차트데이터!$1:$1,0)+1),"")
D14: EWJ | F14: =IFERROR(__xludf.DUMMYFUNCTION("IF(ISBLANK(D14), ""-"", GOOGLEFINANCE(IF(ISBLANK(E14), D14, E14&"":""&D14), ""name""))"),"iShares MSCI Japan ETF") | H14: =IFERROR(__xludf.DUMMYFUNCTION("IF(ISBLANK(D14), 0, GOOGLEFINANCE(IF(ISBLANK(E14), D14, E14&"":""&D14), ""price""))"),89.35) | I14: =IFERROR(__xludf.DUMMYFUNCTION("IF(ISBLANK(D14), 0, GOOGLEFINANCE(IF(ISBLANK(E14), D14, E14&"":""&D14), ""change""))"),-0.48) | J14: =IFERROR(__xludf.DUMMYFUNCTION("IF(ISBLANK(D14), 0, GOOGLEFINANCE(IF(ISBLANK(E14), D14, E14&"":""&D14), ""changepct"")/100)"),-0.0053) | K14: 1 | L14: =K14 * H14 | P14: =IFERROR((INDEX(차트데이터!$A:$BZ,254,MATCH(D14,차트데이터!$1:$1,0)+1)-INDEX(차트데이터!$A:$BZ,232,MATCH(D14,차트데이터!$1:$1,0)+1))/INDEX(차트데이터!$A:$BZ,232,MATCH(D14,차트데이터!$1:$1,0)+1),"") | Q14: =IFERROR((INDEX(차트데이터!$A:$BZ,254,MATCH(D14,차트데이터!$1:$1,0)+1)-INDEX(차트데이터!$A:$BZ,190,MATCH(D14,차트데이터!$1:$1,0)+1))/INDEX(차트데이터!$A:$BZ,190,MATCH(D14,차트데이터!$1:$1,0)+1),"") | R14: =IFERROR((INDEX(차트데이터!$A:$BZ,254,MATCH(D14,차트데이터!$1:$1,0)+1)-INDEX(차트데이터!$A:$BZ,127,MATCH(D14,차트데이터!$1:$1,0)+1))/INDEX(차트데이터!$A:$BZ,127,MATCH(D14,차트데이터!$1:$1,0)+1),"") | S14: =IFERROR((INDEX(차트데이터!$A:$BZ,254,MATCH(D14,차트데이터!$1:$1,0)+1)-INDEX(차트데이터!$A:$BZ,4,MATCH(D14,차트데이터!$1:$1,0)+1))/INDEX(차트데이터!$A:$BZ,4,MATCH(D14,차트데이터!$1:$1,0)+1),"")
D15: VWO | F15: =IFERROR(__xludf.DUMMYFUNCTION("IF(ISBLANK(D15), ""-"", GOOGLEFINANCE(IF(ISBLANK(E15), D15, E15&"":""&D15), ""name""))"),"Vanguard Emerging Markets Stock Index Fund ETF") | H15: =IFERROR(__xludf.DUMMYFUNCTION("IF(ISBLANK(D15), 0, GOOGLEFINANCE(IF(ISBLANK(E15), D15, E15&"":""&D15), ""price""))"),56.92) | I15: =IFERROR(__xludf.DUMMYFUNCTION("IF(ISBLANK(D15), 0, GOOGLEFINANCE(IF(ISBLANK(E15), D15, E15&"":""&D15), ""change""))"),-0.82) | J15: =IFERROR(__xludf.DUMMYFUNCTION("IF(ISBLANK(D15), 0, GOOGLEFINANCE(IF(ISBLANK(E15), D15, E15&"":""&D15), ""changepct"")/100)"),-0.0141999999999999) | K15: 1 | L15: =K15 * H15 | P15: =IFERROR((INDEX(차트데이터!$A:$BZ,254,MATCH(D15,차트데이터!$1:$1,0)+1)-INDEX(차트데이터!$A:$BZ,232,MATCH(D15,차트데이터!$1:$1,0)+1))/INDEX(차트데이터!$A:$BZ,232,MATCH(D15,차트데이터!$1:$1,0)+1),"") | Q15: =IFERROR((INDEX(차트데이터!$A:$BZ,254,MATCH(D15,차트데이터!$1:$1,0)+1)-INDEX(차트데이터!$A:$BZ,190,MATCH(D15,차트데이터!$1:$1,0)+1))/INDEX(차트데이터!$A:$BZ,190,MATCH(D15,차트데이터!$1:$1,0)+1),"") | R15: =IFERROR((INDEX(차트데이터!$A:$BZ,254,MATCH(D15,차트데이터!$1:$1,0)+1)-INDEX(차트데이터!$A:$BZ,127,MATCH(D15,차트데이터!$1:$1,0)+1))/INDEX(차트데이터!$A:$BZ,127,MATCH(D15,차트데이터!$1:$1,0)+1),"") | S15: =IFERROR((INDEX(차트데이터!$A:$BZ,254,MATCH(D15,차트데이터!$1:$1,0)+1)-INDEX(차트데이터!$A:$BZ,4,MATCH(D15,차트데이터!$1:$1,0)+1))/INDEX(차트데이터!$A:$BZ,4,MATCH(D15,차트데이터!$1:$1,0)+1),"")
D16: VEA | F16: =IFERROR(__xludf.DUMMYFUNCTION("IF(ISBLANK(D16), ""-"", GOOGLEFINANCE(IF(ISBLANK(E16), D16, E16&"":""&D16), ""name""))"),"Vanguard Tax Managed Fund FTSE Developed Markets ETF") | H16: =IFERROR(__xludf.DUMMYFUNCTION("IF(ISBLANK(D16), 0, GOOGLEFINANCE(IF(ISBLANK(E16), D16, E16&"":""&D16), ""price""))"),68.95) | I16: =IFERROR(__xludf.DUMMYFUNCTION("IF(ISBLANK(D16), 0, GOOGLEFINANCE(IF(ISBLANK(E16), D16, E16&"":""&D16), ""change""))"),-0.65) | J16: =IFERROR(__xludf.DUMMYFUNCTION("IF(ISBLANK(D16), 0, GOOGLEFINANCE(IF(ISBLANK(E16), D16, E16&"":""&D16), ""changepct"")/100)"),-0.0093) | K16: 1 | L16: =K16 * H16 | P16: =IFERROR((INDEX(차트데이터!$A:$BZ,254,MATCH(D16,차트데이터!$1:$1,0)+1)-INDEX(차트데이터!$A:$BZ,232,MATCH(D16,차트데이터!$1:$1,0)+1))/INDEX(차트데이터!$A:$BZ,232,MATCH(D16,차트데이터!$1:$1,0)+1),"") | Q16: =IFERROR((INDEX(차트데이터!$A:$BZ,254,MATCH(D16,차트데이터!$1:$1,0)+1)-INDEX(차트데이터!$A:$BZ,190,MATCH(D16,차트데이터!$1:$1,0)+1))/INDEX(차트데이터!$A:$BZ,190,MATCH(D16,차트데이터!$1:$1,0)+1),"") | R16: =IFERROR((INDEX(차트데이터!$A:$BZ,254,MATCH(D16,차트데이터!$1:$1,0)+1)-INDEX(차트데이터!$A:$BZ,127,MATCH(D16,차트데이터!$1:$1,0)+1))/INDEX(차트데이터!$A:$BZ,127,MATCH(D16,차트데이터!$1:$1,0)+1),"") | S16: =IFERROR((INDEX(차트데이터!$A:$BZ,254,MATCH(D16,차트데이터!$1:$1,0)+1)-INDEX(차트데이터!$A:$BZ,4,MATCH(D16,차트데이터!$1:$1,0)+1))/INDEX(차트데이터!$A:$BZ,4,MATCH(D16,차트데이터!$1:$1,0)+1),"")
D17: VNQ | F17: =IFERROR(__xludf.DUMMYFUNCTION("IF(ISBLANK(D17), ""-"", GOOGLEFINANCE(IF(ISBLANK(E17), D17, E17&"":""&D17), ""name""))"),"Vanguard Real Estate Index Fund ETF") | H17: =IFERROR(__xludf.DUMMYFUNCTION("IF(ISBLANK(D17), 0, GOOGLEFINANCE(IF(ISBLANK(E17), D17, E17&"":""&D17), ""price""))"),100.66) | I17: =IFERROR(__xludf.DUMMYFUNCTION("IF(ISBLANK(D17), 0, GOOGLEFINANCE(IF(ISBLANK(E17), D17, E17&"":""&D17), ""change""))"),-0.29) | J17: =IFERROR(__xludf.DUMMYFUNCTION("IF(ISBLANK(D17), 0, GOOGLEFINANCE(IF(ISBLANK(E17), D17, E17&"":""&D17), ""changepct"")/100)"),-0.0029) | K17: 1 | L17: =K17 * H17 | P17: =IFERROR((INDEX(차트데이터!$A:$BZ,254,MATCH(D17,차트데이터!$1:$1,0)+1)-INDEX(차트데이터!$A:$BZ,232,MATCH(D17,차트데이터!$1:$1,0)+1))/INDEX(차트데이터!$A:$BZ,232,MATCH(D17,차트데이터!$1:$1,0)+1),"") | Q17: =IFERROR((INDEX(차트데이터!$A:$BZ,254,MATCH(D17,차트데이터!$1:$1,0)+1)-INDEX(차트데이터!$A:$BZ,190,MATCH(D17,차트데이터!$1:$1,0)+1))/INDEX(차트데이터!$A:$BZ,190,MATCH(D17,차트데이터!$1:$1,0)+1),"") | R17: =IFERROR((INDEX(차트데이터!$A:$BZ,254,MATCH(D17,차트데이터!$1:$1,0)+1)-INDEX(차트데이터!$A:$BZ,127,MATCH(D17,차트데이터!$1:$1,0)+1))/INDEX(차트데이터!$A:$BZ,127,MATCH(D17,차트데이터!$1:$1,0)+1),"") | S17: =IFERROR((INDEX(차트데이터!$A:$BZ,254,MATCH(D17,차트데이터!$1:$1,0)+1)-INDEX(차트데이터!$A:$BZ,4,MATCH(D17,차트데이터!$1:$1,0)+1))/INDEX(차트데이터!$A:$BZ,4,MATCH(D17,차트데이터!$1:$1,0)+1),"")
D18: DBC | F18: =IFERROR(__xludf.DUMMYFUNCTION("IF(ISBLANK(D18), ""-"", GOOGLEFINANCE(IF(ISBLANK(E18), D18, E18&"":""&D18), ""name""))"),"Invesco DB Commodity Index Tracking Fund") | H18: =IFERROR(__xludf.DUMMYFUNCTION("IF(ISBLANK(D18), 0, GOOGLEFINANCE(IF(ISBLANK(E18), D18, E18&"":""&D18), ""price""))"),29.42) | I18: =IFERROR(__xludf.DUMMYFUNCTION("IF(ISBLANK(D18), 0, GOOGLEFINANCE(IF(ISBLANK(E18), D18, E18&"":""&D18), ""change""))"),0.82) | J18: =IFERROR(__xludf.DUMMYFUNCTION("IF(ISBLANK(D18), 0, GOOGLEFINANCE(IF(ISBLANK(E18), D18, E18&"":""&D18), ""changepct"")/100)"),0.0287) | K18: 1 | L18: =K18 * H18 | P18: =IFERROR((INDEX(차트데이터!$A:$BZ,254,MATCH(D18,차트데이터!$1:$1,0)+1)-INDEX(차트데이터!$A:$BZ,232,MATCH(D18,차트데이터!$1:$1,0)+1))/INDEX(차트데이터!$A:$BZ,232,MATCH(D18,차트데이터!$1:$1,0)+1),"") | Q18: =IFERROR((INDEX(차트데이터!$A:$BZ,254,MATCH(D18,차트데이터!$1:$1,0)+1)-INDEX(차트데이터!$A:$BZ,190,MATCH(D18,차트데이터!$1:$1,0)+1))/INDEX(차트데이터!$A:$BZ,190,MATCH(D18,차트데이터!$1:$1,0)+1),"") | R18: =IFERROR((INDEX(차트데이터!$A:$BZ,254,MATCH(D18,차트데이터!$1:$1,0)+1)-INDEX(차트데이터!$A:$BZ,127,MATCH(D18,차트데이터!$1:$1,0)+1))/INDEX(차트데이터!$A:$BZ,127,MATCH(D18,차트데이터!$1:$1,0)+1),"") | S18: =IFERROR((INDEX(차트데이터!$A:$BZ,254,MATCH(D18,차트데이터!$1:$1,0)+1)-INDEX(차트데이터!$A:$BZ,4,MATCH(D18,차트데이터!$1:$1,0)+1))/INDEX(차트데이터!$A:$BZ,4,MATCH(D18,차트데이터!$1:$1,0)+1),"")
D19: GLD | F19: =IFERROR(__xludf.DUMMYFUNCTION("IF(ISBLANK(D19), ""-"", GOOGLEFINANCE(IF(ISBLANK(E19), D19, E19&"":""&D19), ""name""))"),"SPDR Gold Trust") | H19: =IFERROR(__xludf.DUMMYFUNCTION("IF(ISBLANK(D19), 0, GOOGLEFINANCE(IF(ISBLANK(E19), D19, E19&"":""&D19), ""price""))"),371.08) | I19: =IFERROR(__xludf.DUMMYFUNCTION("IF(ISBLANK(D19), 0, GOOGLEFINANCE(IF(ISBLANK(E19), D19, E19&"":""&D19), ""change""))"),1.71) | J19: =IFERROR(__xludf.DUMMYFUNCTION("IF(ISBLANK(D19), 0, GOOGLEFINANCE(IF(ISBLANK(E19), D19, E19&"":""&D19), ""changepct"")/100)"),0.0046) | K19: 1 | L19: =K19 * H19 | P19: =IFERROR((INDEX(차트데이터!$A:$BZ,254,MATCH(D19,차트데이터!$1:$1,0)+1)-INDEX(차트데이터!$A:$BZ,232,MATCH(D19,차트데이터!$1:$1,0)+1))/INDEX(차트데이터!$A:$BZ,232,MATCH(D19,차트데이터!$1:$1,0)+1),"") | Q19: =IFERROR((INDEX(차트데이터!$A:$BZ,254,MATCH(D19,차트데이터!$1:$1,0)+1)-INDEX(차트데이터!$A:$BZ,190,MATCH(D19,차트데이터!$1:$1,0)+1))/INDEX(차트데이터!$A:$BZ,190,MATCH(D19,차트데이터!$1:$1,0)+1),"") | R19: =IFERROR((INDEX(차트데이터!$A:$BZ,254,MATCH(D19,차트데이터!$1:$1,0)+1)-INDEX(차트데이터!$A:$BZ,127,MATCH(D19,차트데이터!$1:$1,0)+1))/INDEX(차트데이터!$A:$BZ,127,MATCH(D19,차트데이터!$1:$1,0)+1),"") | S19: =IFERROR((INDEX(차트데이터!$A:$BZ,254,MATCH(D19,차트데이터!$1:$1,0)+1)-INDEX(차트데이터!$A:$BZ,4,MATCH(D19,차트데이터!$1:$1,0)+1))/INDEX(차트데이터!$A:$BZ,4,MATCH(D19,차트데이터!$1:$1,0)+1),"")
D20: LQD | F20: =IFERROR(__xludf.DUMMYFUNCTION("IF(ISBLANK(D20), ""-"", GOOGLEFINANCE(IF(ISBLANK(E20), D20, E20&"":""&D20), ""name""))"),"iShares iBoxx $ Inv Grade Corporate Bond ETF") | H20: =IFERROR(__xludf.DUMMYFUNCTION("IF(ISBLANK(D20), 0, GOOGLEFINANCE(IF(ISBLANK(E20), D20, E20&"":""&D20), ""price""))"),106.22) | I20: =IFERROR(__xludf.DUMMYFUNCTION("IF(ISBLANK(D20), 0, GOOGLEFINANCE(IF(ISBLANK(E20), D20, E20&"":""&D20), ""change""))"),-0.61) | J20: =IFERROR(__xludf.DUMMYFUNCTION("IF(ISBLANK(D20), 0, GOOGLEFINANCE(IF(ISBLANK(E20), D20, E20&"":""&D20), ""changepct"")/100)"),-0.00569999999999999) | K20: 1 | L20: =K20 * H20 | P20: =IFERROR((INDEX(차트데이터!$A:$BZ,254,MATCH(D20,차트데이터!$1:$1,0)+1)-INDEX(차트데이터!$A:$BZ,232,MATCH(D20,차트데이터!$1:$1,0)+1))/INDEX(차트데이터!$A:$BZ,232,MATCH(D20,차트데이터!$1:$1,0)+1),"") | Q20: =IFERROR((INDEX(차트데이터!$A:$BZ,254,MATCH(D20,차트데이터!$1:$1,0)+1)-INDEX(차트데이터!$A:$BZ,190,MATCH(D20,차트데이터!$1:$1,0)+1))/INDEX(차트데이터!$A:$BZ,190,MATCH(D20,차트데이터!$1:$1,0)+1),"") | R20: =IFERROR((INDEX(차트데이터!$A:$BZ,254,MATCH(D20,차트데이터!$1:$1,0)+1)-INDEX(차트데이터!$A:$BZ,127,MATCH(D20,차트데이터!$1:$1,0)+1))/INDEX(차트데이터!$A:$BZ,127,MATCH(D20,차트데이터!$1:$1,0)+1),"") | S20: =IFERROR((INDEX(차트데이터!$A:$BZ,254,MATCH(D20,차트데이터!$1:$1,0)+1)-INDEX(차트데이터!$A:$BZ,4,MATCH(D20,차트데이터!$1:$1,0)+1))/INDEX(차트데이터!$A:$BZ,4,MATCH(D20,차트데이터!$1:$1,0)+1),"")
D21: HYG | F21: =IFERROR(__xludf.DUMMYFUNCTION("IF(ISBLANK(D21), ""-"", GOOGLEFINANCE(IF(ISBLANK(E21), D21, E21&"":""&D21), ""name""))"),"iShares iBoxx $ High Yield Corporate Bond ETF") | H21: =IFERROR(__xludf.DUMMYFUNCTION("IF(ISBLANK(D21), 0, GOOGLEFINANCE(IF(ISBLANK(E21), D21, E21&"":""&D21), ""price""))"),79.24) | I21: =IFERROR(__xludf.DUMMYFUNCTION("IF(ISBLANK(D21), 0, GOOGLEFINANCE(IF(ISBLANK(E21), D21, E21&"":""&D21), ""change""))"),-0.18) | J21: =IFERROR(__xludf.DUMMYFUNCTION("IF(ISBLANK(D21), 0, GOOGLEFINANCE(IF(ISBLANK(E21), D21, E21&"":""&D21), ""changepct"")/100)"),-0.0023) | K21: 1 | L21: =K21 * H21 | P21: =IFERROR((INDEX(차트데이터!$A:$BZ,254,MATCH(D21,차트데이터!$1:$1,0)+1)-INDEX(차트데이터!$A:$BZ,232,MATCH(D21,차트데이터!$1:$1,0)+1))/INDEX(차트데이터!$A:$BZ,232,MATCH(D21,차트데이터!$1:$1,0)+1),"") | Q21: =IFERROR((INDEX(차트데이터!$A:$BZ,254,MATCH(D21,차트데이터!$1:$1,0)+1)-INDEX(차트데이터!$A:$BZ,190,MATCH(D21,차트데이터!$1:$1,0)+1))/INDEX(차트데이터!$A:$BZ,190,MATCH(D21,차트데이터!$1:$1,0)+1),"") | R21: =IFERROR((INDEX(차트데이터!$A:$BZ,254,MATCH(D21,차트데이터!$1:$1,0)+1)-INDEX(차트데이터!$A:$BZ,127,MATCH(D21,차트데이터!$1:$1,0)+1))/INDEX(차트데이터!$A:$BZ,127,MATCH(D21,차트데이터!$1:$1,0)+1),"") | S21: =IFERROR((INDEX(차트데이터!$A:$BZ,254,MATCH(D21,차트데이터!$1:$1,0)+1)-INDEX(차트데이터!$A:$BZ,4,MATCH(D21,차트데이터!$1:$1,0)+1))/INDEX(차트데이터!$A:$BZ,4,MATCH(D21,차트데이터!$1:$1,0)+1),"")
C22: BAA 카나리아 | D22: SPY | F22: =IFERROR(__xludf.DUMMYFUNCTION("IF(ISBLANK(D22), ""-"", GOOGLEFINANCE(IF(ISBLANK(E22), D22, E22&"":""&D22), ""name""))"),"State Street SPDR S&P 500 ETF Trust") | G22: 미국 주식 | H22: =IFERROR(__xludf.DUMMYFUNCTION("IF(ISBLANK(D22), 0, GOOGLEFINANCE(IF(ISBLANK(E22), D22, E22&"":""&D22), ""price""))"),729.46) | I22: =IFERROR(__xludf.DUMMYFUNCTION("IF(ISBLANK(D22), 0, GOOGLEFINANCE(IF(ISBLANK(E22), D22, E22&"":""&D22), ""change""))"),-11.4) | J22: =IFERROR(__xludf.DUMMYFUNCTION("IF(ISBLANK(D22), 0, GOOGLEFINANCE(IF(ISBLANK(E22), D22, E22&"":""&D22), ""changepct"")/100)"),-0.0154) | K22: 1 | L22: =K22 * H22 | O22: =(P22*12)+(Q22*4)+(R22*2)+(S22*1) | P22: =IFERROR((INDEX(차트데이터!$A:$BZ,254,MATCH(D22,차트데이터!$1:$1,0)+1)-INDEX(차트데이터!$A:$BZ,232,MATCH(D22,차트데이터!$1:$1,0)+1))/INDEX(차트데이터!$A:$BZ,232,MATCH(D22,차트데이터!$1:$1,0)+1),"") | Q22: =IFERROR((INDEX(차트데이터!$A:$BZ,254,MATCH(D22,차트데이터!$1:$1,0)+1)-INDEX(차트데이터!$A:$BZ,190,MATCH(D22,차트데이터!$1:$1,0)+1))/INDEX(차트데이터!$A:$BZ,190,MATCH(D22,차트데이터!$1:$1,0)+1),"") | R22: =IFERROR((INDEX(차트데이터!$A:$BZ,254,MATCH(D22,차트데이터!$1:$1,0)+1)-INDEX(차트데이터!$A:$BZ,127,MATCH(D22,차트데이터!$1:$1,0)+1))/INDEX(차트데이터!$A:$BZ,127,MATCH(D22,차트데이터!$1:$1,0)+1),"") | S22: =IFERROR((INDEX(차트데이터!$A:$BZ,254,MATCH(D22,차트데이터!$1:$1,0)+1)-INDEX(차트데이터!$A:$BZ,4,MATCH(D22,차트데이터!$1:$1,0)+1))/INDEX(차트데이터!$A:$BZ,4,MATCH(D22,차트데이터!$1:$1,0)+1),"") | V22: 모멘텀 스코어가 0이하인 ETF가 하나라도 있으면 공격자산 투자중단->안전자산으로 이동
D23: EFA | F23: =IFERROR(__xludf.DUMMYFUNCTION("IF(ISBLANK(D23), ""-"", GOOGLEFINANCE(IF(ISBLANK(E23), D23, E23&"":""&D23), ""name""))"),"iShares MSCI EAFE ETF") | G23: 선진국 주식 | H23: =IFERROR(__xludf.DUMMYFUNCTION("IF(ISBLANK(D23), 0, GOOGLEFINANCE(IF(ISBLANK(E23), D23, E23&"":""&D23), ""price""))"),103.37) | I23: =IFERROR(__xludf.DUMMYFUNCTION("IF(ISBLANK(D23), 0, GOOGLEFINANCE(IF(ISBLANK(E23), D23, E23&"":""&D23), ""change""))"),-0.52) | J23: =IFERROR(__xludf.DUMMYFUNCTION("IF(ISBLANK(D23), 0, GOOGLEFINANCE(IF(ISBLANK(E23), D23, E23&"":""&D23), ""changepct"")/100)"),-0.005) | K23: 1 | L23: =K23 * H23 | O23: =(P23*12)+(Q23*4)+(R23*2)+(S23*1) | P23: =IFERROR((INDEX(차트데이터!$A:$BZ,254,MATCH(D23,차트데이터!$1:$1,0)+1)-INDEX(차트데이터!$A:$BZ,232,MATCH(D23,차트데이터!$1:$1,0)+1))/INDEX(차트데이터!$A:$BZ,232,MATCH(D23,차트데이터!$1:$1,0)+1),"") | Q23: =IFERROR((INDEX(차트데이터!$A:$BZ,254,MATCH(D23,차트데이터!$1:$1,0)+1)-INDEX(차트데이터!$A:$BZ,190,MATCH(D23,차트데이터!$1:$1,0)+1))/INDEX(차트데이터!$A:$BZ,190,MATCH(D23,차트데이터!$1:$1,0)+1),"") | R23: =IFERROR((INDEX(차트데이터!$A:$BZ,254,MATCH(D23,차트데이터!$1:$1,0)+1)-INDEX(차트데이터!$A:$BZ,127,MATCH(D23,차트데이터!$1:$1,0)+1))/INDEX(차트데이터!$A:$BZ,127,MATCH(D23,차트데이터!$1:$1,0)+1),"") | S23: =IFERROR((INDEX(차트데이터!$A:$BZ,254,MATCH(D23,차트데이터!$1:$1,0)+1)-INDEX(차트데이터!$A:$BZ,4,MATCH(D23,차트데이터!$1:$1,0)+1))/INDEX(차트데이터!$A:$BZ,4,MATCH(D23,차트데이터!$1:$1,0)+1),"")
D24: EEM | F24: =IFERROR(__xludf.DUMMYFUNCTION("IF(ISBLANK(D24), ""-"", GOOGLEFINANCE(IF(ISBLANK(E24), D24, E24&"":""&D24), ""name""))"),"iShares MSCI Emerging Markets ETF") | G24: 개발도상국 | H24: =IFERROR(__xludf.DUMMYFUNCTION("IF(ISBLANK(D24), 0, GOOGLEFINANCE(IF(ISBLANK(E24), D24, E24&"":""&D24), ""price""))"),61.07) | I24: =IFERROR(__xludf.DUMMYFUNCTION("IF(ISBLANK(D24), 0, GOOGLEFINANCE(IF(ISBLANK(E24), D24, E24&"":""&D24), ""change""))"),-1.29) | J24: =IFERROR(__xludf.DUMMYFUNCTION("IF(ISBLANK(D24), 0, GOOGLEFINANCE(IF(ISBLANK(E24), D24, E24&"":""&D24), ""changepct"")/100)"),-0.0207) | K24: 1 | L24: =K24 * H24 | O24: =(P24*12)+(Q24*4)+(R24*2)+(S24*1) | P24: =IFERROR((INDEX(차트데이터!$A:$BZ,254,MATCH(D24,차트데이터!$1:$1,0)+1)-INDEX(차트데이터!$A:$BZ,232,MATCH(D24,차트데이터!$1:$1,0)+1))/INDEX(차트데이터!$A:$BZ,232,MATCH(D24,차트데이터!$1:$1,0)+1),"") | Q24: =IFERROR((INDEX(차트데이터!$A:$BZ,254,MATCH(D24,차트데이터!$1:$1,0)+1)-INDEX(차트데이터!$A:$BZ,190,MATCH(D24,차트데이터!$1:$1,0)+1))/INDEX(차트데이터!$A:$BZ,190,MATCH(D24,차트데이터!$1:$1,0)+1),"") | R24: =IFERROR((INDEX(차트데이터!$A:$BZ,254,MATCH(D24,차트데이터!$1:$1,0)+1)-INDEX(차트데이터!$A:$BZ,127,MATCH(D24,차트데이터!$1:$1,0)+1))/INDEX(차트데이터!$A:$BZ,127,MATCH(D24,차트데이터!$1:$1,0)+1),"") | S24: =IFERROR((INDEX(차트데이터!$A:$BZ,254,MATCH(D24,차트데이터!$1:$1,0)+1)-INDEX(차트데이터!$A:$BZ,4,MATCH(D24,차트데이터!$1:$1,0)+1))/INDEX(차트데이터!$A:$BZ,4,MATCH(D24,차트데이터!$1:$1,0)+1),"") | X24: Date | Y24: Close | Z24: Ticker
D25: AGG | F25: =IFERROR(__xludf.DUMMYFUNCTION("IF(ISBLANK(D25), ""-"", GOOGLEFINANCE(IF(ISBLANK(E25), D25, E25&"":""&D25), ""name""))"),"iShares Core US Aggregate Bond ETF") | G25: 혼합채권 | H25: =IFERROR(__xludf.DUMMYFUNCTION("IF(ISBLANK(D25), 0, GOOGLEFINANCE(IF(ISBLANK(E25), D25, E25&"":""&D25), ""price""))"),97.55) | I25: =IFERROR(__xludf.DUMMYFUNCTION("IF(ISBLANK(D25), 0, GOOGLEFINANCE(IF(ISBLANK(E25), D25, E25&"":""&D25), ""change""))"),-0.37) | J25: =IFERROR(__xludf.DUMMYFUNCTION("IF(ISBLANK(D25), 0, GOOGLEFINANCE(IF(ISBLANK(E25), D25, E25&"":""&D25), ""changepct"")/100)"),-0.0038) | K25: 1 | L25: =K25 * H25 | O25: =(P25*12)+(Q25*4)+(R25*2)+(S25*1) | P25: =IFERROR((INDEX(차트데이터!$A:$BZ,254,MATCH(D25,차트데이터!$1:$1,0)+1)-INDEX(차트데이터!$A:$BZ,232,MATCH(D25,차트데이터!$1:$1,0)+1))/INDEX(차트데이터!$A:$BZ,232,MATCH(D25,차트데이터!$1:$1,0)+1),"") | Q25: =IFERROR((INDEX(차트데이터!$A:$BZ,254,MATCH(D25,차트데이터!$1:$1,0)+1)-INDEX(차트데이터!$A:$BZ,190,MATCH(D25,차트데이터!$1:$1,0)+1))/INDEX(차트데이터!$A:$BZ,190,MATCH(D25,차트데이터!$1:$1,0)+1),"") | R25: =IFERROR((INDEX(차트데이터!$A:$BZ,254,MATCH(D25,차트데이터!$1:$1,0)+1)-INDEX(차트데이터!$A:$BZ,127,MATCH(D25,차트데이터!$1:$1,0)+1))/INDEX(차트데이터!$A:$BZ,127,MATCH(D25,차트데이터!$1:$1,0)+1),"") | S25: =IFERROR((INDEX(차트데이터!$A:$BZ,254,MATCH(D25,차트데이터!$1:$1,0)+1)-INDEX(차트데이터!$A:$BZ,4,MATCH(D25,차트데이터!$1:$1,0)+1))/INDEX(차트데이터!$A:$BZ,4,MATCH(D25,차트데이터!$1:$1,0)+1),"") | X25: =IFERROR(INDEX(차트데이터!$A:$BZ,3,MATCH($Y$2,차트데이터!$1:$1,0)),"") | Y25: =IFERROR(INDEX(차트데이터!$A:$BZ,3,MATCH($Y$2,차트데이터!$1:$1,0)+1),"") | Z25: =$Y$2
D26: QQQ | F26: =IFERROR(__xludf.DUMMYFUNCTION("IF(ISBLANK(D26), ""-"", GOOGLEFINANCE(IF(ISBLANK(E26), D26, E26&"":""&D26), ""name""))"),"Invesco QQQ Trust, Series 1") | G26: 미국 주식 | H26: =IFERROR(__xludf.DUMMYFUNCTION("IF(ISBLANK(D26), 0, GOOGLEFINANCE(IF(ISBLANK(E26), D26, E26&"":""&D26), ""price""))"),661.73) | I26: =IFERROR(__xludf.DUMMYFUNCTION("IF(ISBLANK(D26), 0, GOOGLEFINANCE(IF(ISBLANK(E26), D26, E26&"":""&D26), ""change""))"),-13.76) | J26: =IFERROR(__xludf.DUMMYFUNCTION("IF(ISBLANK(D26), 0, GOOGLEFINANCE(IF(ISBLANK(E26), D26, E26&"":""&D26), ""changepct"")/100)"),-0.0204) | K26: 1 | L26: =K26 * H26 | P26: =IFERROR((INDEX(차트데이터!$A:$BZ,254,MATCH(D26,차트데이터!$1:$1,0)+1)-INDEX(차트데이터!$A:$BZ,232,MATCH(D26,차트데이터!$1:$1,0)+1))/INDEX(차트데이터!$A:$BZ,232,MATCH(D26,차트데이터!$1:$1,0)+1),"") | Q26: =IFERROR((INDEX(차트데이터!$A:$BZ,254,MATCH(D26,차트데이터!$1:$1,0)+1)-INDEX(차트데이터!$A:$BZ,190,MATCH(D26,차트데이터!$1:$1,0)+1))/INDEX(차트데이터!$A:$BZ,190,MATCH(D26,차트데이터!$1:$1,0)+1),"") | R26: =IFERROR((INDEX(차트데이터!$A:$BZ,254,MATCH(D26,차트데이터!$1:$1,0)+1)-INDEX(차트데이터!$A:$BZ,127,MATCH(D26,차트데이터!$1:$1,0)+1))/INDEX(차트데이터!$A:$BZ,127,MATCH(D26,차트데이터!$1:$1,0)+1),"") | S26: =IFERROR((INDEX(차트데이터!$A:$BZ,254,MATCH(D26,차트데이터!$1:$1,0)+1)-INDEX(차트데이터!$A:$BZ,4,MATCH(D26,차트데이터!$1:$1,0)+1))/INDEX(차트데이터!$A:$BZ,4,MATCH(D26,차트데이터!$1:$1,0)+1),"") | X26: =IFERROR(INDEX(차트데이터!$A:$BZ,4,MATCH($Y$2,차트데이터!$1:$1,0)),"") | Y26: =IFERROR(INDEX(차트데이터!$A:$BZ,4,MATCH($Y$2,차트데이터!$1:$1,0)+1),"") | Z26: =$Y$2
C27: BAA 안전자산 | D27: LQD | F27: =IFERROR(__xludf.DUMMYFUNCTION("IF(ISBLANK(D27), ""-"", GOOGLEFINANCE(IF(ISBLANK(E27), D27, E27&"":""&D27), ""name""))"),"iShares iBoxx $ Inv Grade Corporate Bond ETF") | G27: 미국회사채 | H27: =IFERROR(__xludf.DUMMYFUNCTION("IF(ISBLANK(D27), 0, GOOGLEFINANCE(IF(ISBLANK(E27), D27, E27&"":""&D27), ""price""))"),106.22) | I27: =IFERROR(__xludf.DUMMYFUNCTION("IF(ISBLANK(D27), 0, GOOGLEFINANCE(IF(ISBLANK(E27), D27, E27&"":""&D27), ""change""))"),-0.61) | J27: =IFERROR(__xludf.DUMMYFUNCTION("IF(ISBLANK(D27), 0, GOOGLEFINANCE(IF(ISBLANK(E27), D27, E27&"":""&D27), ""changepct"")/100)"),-0.00569999999999999) | K27: 1 | L27: =K27 * H27 | O27: =(P27*12)+(Q27*4)+(R27*2)+(S27*1) | P27: =IFERROR((INDEX(차트데이터!$A:$BZ,254,MATCH(D27,차트데이터!$1:$1,0)+1)-INDEX(차트데이터!$A:$BZ,232,MATCH(D27,차트데이터!$1:$1,0)+1))/INDEX(차트데이터!$A:$BZ,232,MATCH(D27,차트데이터!$1:$1,0)+1),"") | Q27: =IFERROR((INDEX(차트데이터!$A:$BZ,254,MATCH(D27,차트데이터!$1:$1,0)+1)-INDEX(차트데이터!$A:$BZ,190,MATCH(D27,차트데이터!$1:$1,0)+1))/INDEX(차트데이터!$A:$BZ,190,MATCH(D27,차트데이터!$1:$1,0)+1),"") | R27: =IFERROR((INDEX(차트데이터!$A:$BZ,254,MATCH(D27,차트데이터!$1:$1,0)+1)-INDEX(차트데이터!$A:$BZ,127,MATCH(D27,차트데이터!$1:$1,0)+1))/INDEX(차트데이터!$A:$BZ,127,MATCH(D27,차트데이터!$1:$1,0)+1),"") | S27: =IFERROR((INDEX(차트데이터!$A:$BZ,254,MATCH(D27,차트데이터!$1:$1,0)+1)-INDEX(차트데이터!$A:$BZ,4,MATCH(D27,차트데이터!$1:$1,0)+1))/INDEX(차트데이터!$A:$BZ,4,MATCH(D27,차트데이터!$1:$1,0)+1),"") | V27: 현재가격/12개월 이동평균이 높은 3개에 투자 But,현재가격이 이동평균보다 낮으면 현금으로 보유 | X27: =IFERROR(INDEX(차트데이터!$A:$BZ,5,MATCH($Y$2,차트데이터!$1:$1,0)),"") | Y27: =IFERROR(INDEX(차트데이터!$A:$BZ,5,MATCH($Y$2,차트데이터!$1:$1,0)+1),"") | Z27: =$Y$2
D28: IEF | F28: =IFERROR(__xludf.DUMMYFUNCTION("IF(ISBLANK(D28), ""-"", GOOGLEFINANCE(IF(ISBLANK(E28), D28, E28&"":""&D28), ""name""))"),"iShares 7-10 Year Treasury Bond ETF") | G28: 미국중기국채 | H28: =IFERROR(__xludf.DUMMYFUNCTION("IF(ISBLANK(D28), 0, GOOGLEFINANCE(IF(ISBLANK(E28), D28, E28&"":""&D28), ""price""))"),93.17) | I28: =IFERROR(__xludf.DUMMYFUNCTION("IF(ISBLANK(D28), 0, GOOGLEFINANCE(IF(ISBLANK(E28), D28, E28&"":""&D28), ""change""))"),-0.39) | J28: =IFERROR(__xludf.DUMMYFUNCTION("IF(ISBLANK(D28), 0, GOOGLEFINANCE(IF(ISBLANK(E28), D28, E28&"":""&D28), ""changepct"")/100)"),-0.0042) | K28: 1 | L28: =K28 * H28 | O28: =(P28*12)+(Q28*4)+(R28*2)+(S28*1) | P28: =IFERROR((INDEX(차트데이터!$A:$BZ,254,MATCH(D28,차트데이터!$1:$1,0)+1)-INDEX(차트데이터!$A:$BZ,232,MATCH(D28,차트데이터!$1:$1,0)+1))/INDEX(차트데이터!$A:$BZ,232,MATCH(D28,차트데이터!$1:$1,0)+1),"") | Q28: =IFERROR((INDEX(차트데이터!$A:$BZ,254,MATCH(D28,차트데이터!$1:$1,0)+1)-INDEX(차트데이터!$A:$BZ,190,MATCH(D28,차트데이터!$1:$1,0)+1))/INDEX(차트데이터!$A:$BZ,190,MATCH(D28,차트데이터!$1:$1,0)+1),"") | R28: =IFERROR((INDEX(차트데이터!$A:$BZ,254,MATCH(D28,차트데이터!$1:$1,0)+1)-INDEX(차트데이터!$A:$BZ,127,MATCH(D28,차트데이터!$1:$1,0)+1))/INDEX(차트데이터!$A:$BZ,127,MATCH(D28,차트데이터!$1:$1,0)+1),"") | S28: =IFERROR((INDEX(차트데이터!$A:$BZ,254,MATCH(D28,차트데이터!$1:$1,0)+1)-INDEX(차트데이터!$A:$BZ,4,MATCH(D28,차트데이터!$1:$1,0)+1))/INDEX(차트데이터!$A:$BZ,4,MATCH(D28,차트데이터!$1:$1,0)+1),"") | X28: =IFERROR(INDEX(차트데이터!$A:$BZ,6,MATCH($Y$2,차트데이터!$1:$1,0)),"") | Y28: =IFERROR(INDEX(차트데이터!$A:$BZ,6,MATCH($Y$2,차트데이터!$1:$1,0)+1),"") | Z28: =$Y$2
D29: BIL | F29: =IFERROR(__xludf.DUMMYFUNCTION("IF(ISBLANK(D29), ""-"", GOOGLEFINANCE(IF(ISBLANK(E29), D29, E29&"":""&D29), ""name""))"),"State Street SPDR Bloomberg 1-3 Month T-Bill ETF") | G29: 미국초단기채권 | H29: =IFERROR(__xludf.DUMMYFUNCTION("IF(ISBLANK(D29), 0, GOOGLEFINANCE(IF(ISBLANK(E29), D29, E29&"":""&D29), ""price""))"),91.64) | I29: =IFERROR(__xludf.DUMMYFUNCTION("IF(ISBLANK(D29), 0, GOOGLEFINANCE(IF(ISBLANK(E29), D29, E29&"":""&D29), ""change""))"),0.01) | J29: =IFERROR(__xludf.DUMMYFUNCTION("IF(ISBLANK(D29), 0, GOOGLEFINANCE(IF(ISBLANK(E29), D29, E29&"":""&D29), ""changepct"")/100)"),0.0001) | K29: 1 | L29: =K29 * H29 | O29: =(P29*12)+(Q29*4)+(R29*2)+(S29*1) | P29: =IFERROR((INDEX(차트데이터!$A:$BZ,254,MATCH(D29,차트데이터!$1:$1,0)+1)-INDEX(차트데이터!$A:$BZ,232,MATCH(D29,차트데이터!$1:$1,0)+1))/INDEX(차트데이터!$A:$BZ,232,MATCH(D29,차트데이터!$1:$1,0)+1),"") | Q29: =IFERROR((INDEX(차트데이터!$A:$BZ,254,MATCH(D29,차트데이터!$1:$1,0)+1)-INDEX(차트데이터!$A:$BZ,190,MATCH(D29,차트데이터!$1:$1,0)+1))/INDEX(차트데이터!$A:$BZ,190,MATCH(D29,차트데이터!$1:$1,0)+1),"") | R29: =IFERROR((INDEX(차트데이터!$A:$BZ,254,MATCH(D29,차트데이터!$1:$1,0)+1)-INDEX(차트데이터!$A:$BZ,127,MATCH(D29,차트데이터!$1:$1,0)+1))/INDEX(차트데이터!$A:$BZ,127,MATCH(D29,차트데이터!$1:$1,0)+1),"") | S29: =IFERROR((INDEX(차트데이터!$A:$BZ,254,MATCH(D29,차트데이터!$1:$1,0)+1)-INDEX(차트데이터!$A:$BZ,4,MATCH(D29,차트데이터!$1:$1,0)+1))/INDEX(차트데이터!$A:$BZ,4,MATCH(D29,차트데이터!$1:$1,0)+1),"") | X29: =IFERROR(INDEX(차트데이터!$A:$BZ,7,MATCH($Y$2,차트데이터!$1:$1,0)),"") | Y29: =IFERROR(INDEX(차트데이터!$A:$BZ,7,MATCH($Y$2,차트데이터!$1:$1,0)+1),"") | Z29: =$Y$2
D30: TLT | F30: =IFERROR(__xludf.DUMMYFUNCTION("IF(ISBLANK(D30), ""-"", GOOGLEFINANCE(IF(ISBLANK(E30), D30, E30&"":""&D30), ""name""))"),"iShares 20+ Year Treasury Bond ETF") | G30: 미국장기국채 | H30: =IFERROR(__xludf.DUMMYFUNCTION("IF(ISBLANK(D30), 0, GOOGLEFINANCE(IF(ISBLANK(E30), D30, E30&"":""&D30), ""price""))"),82.85) | I30: =IFERROR(__xludf.DUMMYFUNCTION("IF(ISBLANK(D30), 0, GOOGLEFINANCE(IF(ISBLANK(E30), D30, E30&"":""&D30), ""change""))"),-1.39) | J30: =IFERROR(__xludf.DUMMYFUNCTION("IF(ISBLANK(D30), 0, GOOGLEFINANCE(IF(ISBLANK(E30), D30, E30&"":""&D30), ""changepct"")/100)"),-0.0165) | K30: 1 | L30: =K30 * H30 | O30: =(P30*12)+(Q30*4)+(R30*2)+(S30*1) | P30: =IFERROR((INDEX(차트데이터!$A:$BZ,254,MATCH(D30,차트데이터!$1:$1,0)+1)-INDEX(차트데이터!$A:$BZ,232,MATCH(D30,차트데이터!$1:$1,0)+1))/INDEX(차트데이터!$A:$BZ,232,MATCH(D30,차트데이터!$1:$1,0)+1),"") | Q30: =IFERROR((INDEX(차트데이터!$A:$BZ,254,MATCH(D30,차트데이터!$1:$1,0)+1)-INDEX(차트데이터!$A:$BZ,190,MATCH(D30,차트데이터!$1:$1,0)+1))/INDEX(차트데이터!$A:$BZ,190,MATCH(D30,차트데이터!$1:$1,0)+1),"") | R30: =IFERROR((INDEX(차트데이터!$A:$BZ,254,MATCH(D30,차트데이터!$1:$1,0)+1)-INDEX(차트데이터!$A:$BZ,127,MATCH(D30,차트데이터!$1:$1,0)+1))/INDEX(차트데이터!$A:$BZ,127,MATCH(D30,차트데이터!$1:$1,0)+1),"") | S30: =IFERROR((INDEX(차트데이터!$A:$BZ,254,MATCH(D30,차트데이터!$1:$1,0)+1)-INDEX(차트데이터!$A:$BZ,4,MATCH(D30,차트데이터!$1:$1,0)+1))/INDEX(차트데이터!$A:$BZ,4,MATCH(D30,차트데이터!$1:$1,0)+1),"") | X30: =IFERROR(INDEX(차트데이터!$A:$BZ,8,MATCH($Y$2,차트데이터!$1:$1,0)),"") | Y30: =IFERROR(INDEX(차트데이터!$A:$BZ,8,MATCH($Y$2,차트데이터!$1:$1,0)+1),"") | Z30: =$Y$2
D31: TIP | F31: =IFERROR(__xludf.DUMMYFUNCTION("IF(ISBLANK(D31), ""-"", GOOGLEFINANCE(IF(ISBLANK(E31), D31, E31&"":""&D31), ""name""))"),"iShares TIPS Bond ETF") | G31: 미국물가연동채 | H31: =IFERROR(__xludf.DUMMYFUNCTION("IF(ISBLANK(D31), 0, GOOGLEFINANCE(IF(ISBLANK(E31), D31, E31&"":""&D31), ""price""))"),107.77) | I31: =IFERROR(__xludf.DUMMYFUNCTION("IF(ISBLANK(D31), 0, GOOGLEFINANCE(IF(ISBLANK(E31), D31, E31&"":""&D31), ""change""))"),0.11) | J31: =IFERROR(__xludf.DUMMYFUNCTION("IF(ISBLANK(D31), 0, GOOGLEFINANCE(IF(ISBLANK(E31), D31, E31&"":""&D31), ""changepct"")/100)"),0.001) | K31: 1 | L31: =K31 * H31 | O31: =(P31*12)+(Q31*4)+(R31*2)+(S31*1) | P31: =IFERROR((INDEX(차트데이터!$A:$BZ,254,MATCH(D31,차트데이터!$1:$1,0)+1)-INDEX(차트데이터!$A:$BZ,232,MATCH(D31,차트데이터!$1:$1,0)+1))/INDEX(차트데이터!$A:$BZ,232,MATCH(D31,차트데이터!$1:$1,0)+1),"") | Q31: =IFERROR((INDEX(차트데이터!$A:$BZ,254,MATCH(D31,차트데이터!$1:$1,0)+1)-INDEX(차트데이터!$A:$BZ,190,MATCH(D31,차트데이터!$1:$1,0)+1))/INDEX(차트데이터!$A:$BZ,190,MATCH(D31,차트데이터!$1:$1,0)+1),"") | R31: =IFERROR((INDEX(차트데이터!$A:$BZ,254,MATCH(D31,차트데이터!$1:$1,0)+1)-INDEX(차트데이터!$A:$BZ,127,MATCH(D31,차트데이터!$1:$1,0)+1))/INDEX(차트데이터!$A:$BZ,127,MATCH(D31,차트데이터!$1:$1,0)+1),"") | S31: =IFERROR((INDEX(차트데이터!$A:$BZ,254,MATCH(D31,차트데이터!$1:$1,0)+1)-INDEX(차트데이터!$A:$BZ,4,MATCH(D31,차트데이터!$1:$1,0)+1))/INDEX(차트데이터!$A:$BZ,4,MATCH(D31,차트데이터!$1:$1,0)+1),"") | X31: =IFERROR(INDEX(차트데이터!$A:$BZ,9,MATCH($Y$2,차트데이터!$1:$1,0)),"") | Y31: =IFERROR(INDEX(차트데이터!$A:$BZ,9,MATCH($Y$2,차트데이터!$1:$1,0)+1),"") | Z31: =$Y$2
D32: BND | F32: =IFERROR(__xludf.DUMMYFUNCTION("IF(ISBLANK(D32), ""-"", GOOGLEFINANCE(IF(ISBLANK(E32), D32, E32&"":""&D32), ""name""))"),"Vanguard Total Bond Market Index Fund ETF") | G32: 미국잡채권 | H32: =IFERROR(__xludf.DUMMYFUNCTION("IF(ISBLANK(D32), 0, GOOGLEFINANCE(IF(ISBLANK(E32), D32, E32&"":""&D32), ""price""))"),72.38) | I32: =IFERROR(__xludf.DUMMYFUNCTION("IF(ISBLANK(D32), 0, GOOGLEFINANCE(IF(ISBLANK(E32), D32, E32&"":""&D32), ""change""))"),-0.26) | J32: =IFERROR(__xludf.DUMMYFUNCTION("IF(ISBLANK(D32), 0, GOOGLEFINANCE(IF(ISBLANK(E32), D32, E32&"":""&D32), ""changepct"")/100)"),-0.0036) | K32: 1 | L32: =K32 * H32 | O32: =(P32*12)+(Q32*4)+(R32*2)+(S32*1) | P32: =IFERROR((INDEX(차트데이터!$A:$BZ,254,MATCH(D32,차트데이터!$1:$1,0)+1)-INDEX(차트데이터!$A:$BZ,232,MATCH(D32,차트데이터!$1:$1,0)+1))/INDEX(차트데이터!$A:$BZ,232,MATCH(D32,차트데이터!$1:$1,0)+1),"") | Q32: =IFERROR((INDEX(차트데이터!$A:$BZ,254,MATCH(D32,차트데이터!$1:$1,0)+1)-INDEX(차트데이터!$A:$BZ,190,MATCH(D32,차트데이터!$1:$1,0)+1))/INDEX(차트데이터!$A:$BZ,190,MATCH(D32,차트데이터!$1:$1,0)+1),"") | R32: =IFERROR((INDEX(차트데이터!$A:$BZ,254,MATCH(D32,차트데이터!$1:$1,0)+1)-INDEX(차트데이터!$A:$BZ,127,MATCH(D32,차트데이터!$1:$1,0)+1))/INDEX(차트데이터!$A:$BZ,127,MATCH(D32,차트데이터!$1:$1,0)+1),"") | S32: =IFERROR((INDEX(차트데이터!$A:$BZ,254,MATCH(D32,차트데이터!$1:$1,0)+1)-INDEX(차트데이터!$A:$BZ,4,MATCH(D32,차트데이터!$1:$1,0)+1))/INDEX(차트데이터!$A:$BZ,4,MATCH(D32,차트데이터!$1:$1,0)+1),"") | X32: =IFERROR(INDEX(차트데이터!$A:$BZ,10,MATCH($Y$2,차트데이터!$1:$1,0)),"") | Y32: =IFERROR(INDEX(차트데이터!$A:$BZ,10,MATCH($Y$2,차트데이터!$1:$1,0)+1),"") | Z32: =$Y$2
D33: DBC | F33: =IFERROR(__xludf.DUMMYFUNCTION("IF(ISBLANK(D33), ""-"", GOOGLEFINANCE(IF(ISBLANK(E33), D33, E33&"":""&D33), ""name""))"),"Invesco DB Commodity Index Tracking Fund") | G33: 원자재 | H33: =IFERROR(__xludf.DUMMYFUNCTION("IF(ISBLANK(D33), 0, GOOGLEFINANCE(IF(ISBLANK(E33), D33, E33&"":""&D33), ""price""))"),29.42) | I33: =IFERROR(__xludf.DUMMYFUNCTION("IF(ISBLANK(D33), 0, GOOGLEFINANCE(IF(ISBLANK(E33), D33, E33&"":""&D33), ""change""))"),0.82) | J33: =IFERROR(__xludf.DUMMYFUNCTION("IF(ISBLANK(D33), 0, GOOGLEFINANCE(IF(ISBLANK(E33), D33, E33&"":""&D33), ""changepct"")/100)"),0.0287) | K33: 1 | L33: =K33 * H33 | O33: =(P33*12)+(Q33*4)+(R33*2)+(S33*1) | P33: =IFERROR((INDEX(차트데이터!$A:$BZ,254,MATCH(D33,차트데이터!$1:$1,0)+1)-INDEX(차트데이터!$A:$BZ,232,MATCH(D33,차트데이터!$1:$1,0)+1))/INDEX(차트데이터!$A:$BZ,232,MATCH(D33,차트데이터!$1:$1,0)+1),"") | Q33: =IFERROR((INDEX(차트데이터!$A:$BZ,254,MATCH(D33,차트데이터!$1:$1,0)+1)-INDEX(차트데이터!$A:$BZ,190,MATCH(D33,차트데이터!$1:$1,0)+1))/INDEX(차트데이터!$A:$BZ,190,MATCH(D33,차트데이터!$1:$1,0)+1),"") | R33: =IFERROR((INDEX(차트데이터!$A:$BZ,254,MATCH(D33,차트데이터!$1:$1,0)+1)-INDEX(차트데이터!$A:$BZ,127,MATCH(D33,차트데이터!$1:$1,0)+1))/INDEX(차트데이터!$A:$BZ,127,MATCH(D33,차트데이터!$1:$1,0)+1),"") | S33: =IFERROR((INDEX(차트데이터!$A:$BZ,254,MATCH(D33,차트데이터!$1:$1,0)+1)-INDEX(차트데이터!$A:$BZ,4,MATCH(D33,차트데이터!$1:$1,0)+1))/INDEX(차트데이터!$A:$BZ,4,MATCH(D33,차트데이터!$1:$1,0)+1),"") | X33: =IFERROR(INDEX(차트데이터!$A:$BZ,11,MATCH($Y$2,차트데이터!$1:$1,0)),"") | Y33: =IFERROR(INDEX(차트데이터!$A:$BZ,11,MATCH($Y$2,차트데이터!$1:$1,0)+1),"") | Z33: =$Y$2
X34: =IFERROR(INDEX(차트데이터!$A:$BZ,12,MATCH($Y$2,차트데이터!$1:$1,0)),"") | Y34: =IFERROR(INDEX(차트데이터!$A:$BZ,12,MATCH($Y$2,차트데이터!$1:$1,0)+1),"") | Z34: =$Y$2
X35: =IFERROR(INDEX(차트데이터!$A:$BZ,13,MATCH($Y$2,차트데이터!$1:$1,0)),"") | Y35: =IFERROR(INDEX(차트데이터!$A:$BZ,13,MATCH($Y$2,차트데이터!$1:$1,0)+1),"") | Z35: =$Y$2
A36: 변형듀얼모멘텀 | C36: 공격자산 | D36: SPY | F36: =IFERROR(__xludf.DUMMYFUNCTION("IF(ISBLANK(D36), ""-"", GOOGLEFINANCE(IF(ISBLANK(E36), D36, E36&"":""&D36), ""name""))"),"State Street SPDR S&P 500 ETF Trust") | G36: 미국 주식 | H36: =IFERROR(__xludf.DUMMYFUNCTION("IF(ISBLANK(D36), 0, GOOGLEFINANCE(IF(ISBLANK(E36), D36, E36&"":""&D36), ""price""))"),729.46) | I36: =IFERROR(__xludf.DUMMYFUNCTION("IF(ISBLANK(D36), 0, GOOGLEFINANCE(IF(ISBLANK(E36), D36, E36&"":""&D36), ""change""))"),-11.4) | J36: =IFERROR(__xludf.DUMMYFUNCTION("IF(ISBLANK(D36), 0, GOOGLEFINANCE(IF(ISBLANK(E36), D36, E36&"":""&D36), ""changepct"")/100)"),-0.0154) | K36: 1 | L36: =K36 * H36 | O36: =(P36*12)+(Q36*4)+(R36*2)+(S36*1) | P36: =IFERROR((INDEX(차트데이터!$A:$BZ,254,MATCH(D36,차트데이터!$1:$1,0)+1)-INDEX(차트데이터!$A:$BZ,232,MATCH(D36,차트데이터!$1:$1,0)+1))/INDEX(차트데이터!$A:$BZ,232,MATCH(D36,차트데이터!$1:$1,0)+1),"") | Q36: =IFERROR((INDEX(차트데이터!$A:$BZ,254,MATCH(D36,차트데이터!$1:$1,0)+1)-INDEX(차트데이터!$A:$BZ,190,MATCH(D36,차트데이터!$1:$1,0)+1))/INDEX(차트데이터!$A:$BZ,190,MATCH(D36,차트데이터!$1:$1,0)+1),"") | R36: =IFERROR((INDEX(차트데이터!$A:$BZ,254,MATCH(D36,차트데이터!$1:$1,0)+1)-INDEX(차트데이터!$A:$BZ,127,MATCH(D36,차트데이터!$1:$1,0)+1))/INDEX(차트데이터!$A:$BZ,127,MATCH(D36,차트데이터!$1:$1,0)+1),"") | S36: =IFERROR((INDEX(차트데이터!$A:$BZ,254,MATCH(D36,차트데이터!$1:$1,0)+1)-INDEX(차트데이터!$A:$BZ,4,MATCH(D36,차트데이터!$1:$1,0)+1))/INDEX(차트데이터!$A:$BZ,4,MATCH(D36,차트데이터!$1:$1,0)+1),"") | V36: 둘중 높은자산에 투자 But, 1년 수익이 0 이하면 | X36: =IFERROR(INDEX(차트데이터!$A:$BZ,14,MATCH($Y$2,차트데이터!$1:$1,0)),"") | Y36: =IFERROR(INDEX(차트데이터!$A:$BZ,14,MATCH($Y$2,차트데이터!$1:$1,0)+1),"") | Z36: =$Y$2
D37: EFA | F37: =IFERROR(__xludf.DUMMYFUNCTION("IF(ISBLANK(D37), ""-"", GOOGLEFINANCE(IF(ISBLANK(E37), D37, E37&"":""&D37), ""name""))"),"iShares MSCI EAFE ETF") | H37: =IFERROR(__xludf.DUMMYFUNCTION("IF(ISBLANK(D37), 0, GOOGLEFINANCE(IF(ISBLANK(E37), D37, E37&"":""&D37), ""price""))"),103.37) | I37: =IFERROR(__xludf.DUMMYFUNCTION("IF(ISBLANK(D37), 0, GOOGLEFINANCE(IF(ISBLANK(E37), D37, E37&"":""&D37), ""change""))"),-0.52) | J37: =IFERROR(__xludf.DUMMYFUNCTION("IF(ISBLANK(D37), 0, GOOGLEFINANCE(IF(ISBLANK(E37), D37, E37&"":""&D37), ""changepct"")/100)"),-0.005) | K37: 1 | L37: =K37 * H37 | O37: =(P37*12)+(Q37*4)+(R37*2)+(S37*1) | P37: =IFERROR((INDEX(차트데이터!$A:$BZ,254,MATCH(D37,차트데이터!$1:$1,0)+1)-INDEX(차트데이터!$A:$BZ,232,MATCH(D37,차트데이터!$1:$1,0)+1))/INDEX(차트데이터!$A:$BZ,232,MATCH(D37,차트데이터!$1:$1,0)+1),"") | Q37: =IFERROR((INDEX(차트데이터!$A:$BZ,254,MATCH(D37,차트데이터!$1:$1,0)+1)-INDEX(차트데이터!$A:$BZ,190,MATCH(D37,차트데이터!$1:$1,0)+1))/INDEX(차트데이터!$A:$BZ,190,MATCH(D37,차트데이터!$1:$1,0)+1),"") | R37: =IFERROR((INDEX(차트데이터!$A:$BZ,254,MATCH(D37,차트데이터!$1:$1,0)+1)-INDEX(차트데이터!$A:$BZ,127,MATCH(D37,차트데이터!$1:$1,0)+1))/INDEX(차트데이터!$A:$BZ,127,MATCH(D37,차트데이터!$1:$1,0)+1),"") | S37: =IFERROR((INDEX(차트데이터!$A:$BZ,254,MATCH(D37,차트데이터!$1:$1,0)+1)-INDEX(차트데이터!$A:$BZ,4,MATCH(D37,차트데이터!$1:$1,0)+1))/INDEX(차트데이터!$A:$BZ,4,MATCH(D37,차트데이터!$1:$1,0)+1),"") | X37: =IFERROR(INDEX(차트데이터!$A:$BZ,15,MATCH($Y$2,차트데이터!$1:$1,0)),"") | Y37: =IFERROR(INDEX(차트데이터!$A:$BZ,15,MATCH($Y$2,차트데이터!$1:$1,0)+1),"") | Z37: =$Y$2
F38: =IFERROR(__xludf.DUMMYFUNCTION("IF(ISBLANK(D38), ""-"", GOOGLEFINANCE(IF(ISBLANK(E38), D38, E38&"":""&D38), ""name""))"),"-") | H38: =IFERROR(__xludf.DUMMYFUNCTION("IF(ISBLANK(D38), 0, GOOGLEFINANCE(IF(ISBLANK(E38), D38, E38&"":""&D38), ""price""))"),0) | I38: =IFERROR(__xludf.DUMMYFUNCTION("IF(ISBLANK(D38), 0, GOOGLEFINANCE(IF(ISBLANK(E38), D38, E38&"":""&D38), ""change""))"),0) | J38: =IFERROR(__xludf.DUMMYFUNCTION("IF(ISBLANK(D38), 0, GOOGLEFINANCE(IF(ISBLANK(E38), D38, E38&"":""&D38), ""changepct"")/100)"),0) | L38: =K38 * H38 | O38: =(P38*12)+(Q38*4)+(R38*2)+(S38*1) | P38: =IFERROR((INDEX(차트데이터!$A:$BZ,254,MATCH(D38,차트데이터!$1:$1,0)+1)-INDEX(차트데이터!$A:$BZ,232,MATCH(D38,차트데이터!$1:$1,0)+1))/INDEX(차트데이터!$A:$BZ,232,MATCH(D38,차트데이터!$1:$1,0)+1),"") | Q38: =IFERROR((INDEX(차트데이터!$A:$BZ,254,MATCH(D38,차트데이터!$1:$1,0)+1)-INDEX(차트데이터!$A:$BZ,190,MATCH(D38,차트데이터!$1:$1,0)+1))/INDEX(차트데이터!$A:$BZ,190,MATCH(D38,차트데이터!$1:$1,0)+1),"") | R38: =IFERROR((INDEX(차트데이터!$A:$BZ,254,MATCH(D38,차트데이터!$1:$1,0)+1)-INDEX(차트데이터!$A:$BZ,127,MATCH(D38,차트데이터!$1:$1,0)+1))/INDEX(차트데이터!$A:$BZ,127,MATCH(D38,차트데이터!$1:$1,0)+1),"") | S38: =IFERROR((INDEX(차트데이터!$A:$BZ,254,MATCH(D38,차트데이터!$1:$1,0)+1)-INDEX(차트데이터!$A:$BZ,4,MATCH(D38,차트데이터!$1:$1,0)+1))/INDEX(차트데이터!$A:$BZ,4,MATCH(D38,차트데이터!$1:$1,0)+1),"") | X38: =IFERROR(INDEX(차트데이터!$A:$BZ,16,MATCH($Y$2,차트데이터!$1:$1,0)),"") | Y38: =IFERROR(INDEX(차트데이터!$A:$BZ,16,MATCH($Y$2,차트데이터!$1:$1,0)+1),"") | Z38: =$Y$2
C39: 안전자산 8개 채권 | D39: SHY | F39: =IFERROR(__xludf.DUMMYFUNCTION("IF(ISBLANK(D39), ""-"", GOOGLEFINANCE(IF(ISBLANK(E39), D39, E39&"":""&D39), ""name""))"),"iShares 1-3 Year Treasury Bond ETF") | G39: 미국단기국채 | H39: =IFERROR(__xludf.DUMMYFUNCTION("IF(ISBLANK(D39), 0, GOOGLEFINANCE(IF(ISBLANK(E39), D39, E39&"":""&D39), ""price""))"),81.99) | I39: =IFERROR(__xludf.DUMMYFUNCTION("IF(ISBLANK(D39), 0, GOOGLEFINANCE(IF(ISBLANK(E39), D39, E39&"":""&D39), ""change""))"),0.05) | J39: =IFERROR(__xludf.DUMMYFUNCTION("IF(ISBLANK(D39), 0, GOOGLEFINANCE(IF(ISBLANK(E39), D39, E39&"":""&D39), ""changepct"")/100)"),0.0006) | K39: 1 | L39: =K39 * H39 | O39: =(P39*12)+(Q39*4)+(R39*2)+(S39*1) | P39: =IFERROR((INDEX(차트데이터!$A:$BZ,254,MATCH(D39,차트데이터!$1:$1,0)+1)-INDEX(차트데이터!$A:$BZ,232,MATCH(D39,차트데이터!$1:$1,0)+1))/INDEX(차트데이터!$A:$BZ,232,MATCH(D39,차트데이터!$1:$1,0)+1),"") | Q39: =IFERROR((INDEX(차트데이터!$A:$BZ,254,MATCH(D39,차트데이터!$1:$1,0)+1)-INDEX(차트데이터!$A:$BZ,190,MATCH(D39,차트데이터!$1:$1,0)+1))/INDEX(차트데이터!$A:$BZ,190,MATCH(D39,차트데이터!$1:$1,0)+1),"") | R39: =IFERROR((INDEX(차트데이터!$A:$BZ,254,MATCH(D39,차트데이터!$1:$1,0)+1)-INDEX(차트데이터!$A:$BZ,127,MATCH(D39,차트데이터!$1:$1,0)+1))/INDEX(차트데이터!$A:$BZ,127,MATCH(D39,차트데이터!$1:$1,0)+1),"") | S39: =IFERROR((INDEX(차트데이터!$A:$BZ,254,MATCH(D39,차트데이터!$1:$1,0)+1)-INDEX(차트데이터!$A:$BZ,4,MATCH(D39,차트데이터!$1:$1,0)+1))/INDEX(차트데이터!$A:$BZ,4,MATCH(D39,차트데이터!$1:$1,0)+1),"") | V39: 6개월 최고수익 3개 채권매수 But, 3개 채권중 0이하인 자산은 현금으로 보유 | X39: =IFERROR(INDEX(차트데이터!$A:$BZ,17,MATCH($Y$2,차트데이터!$1:$1,0)),"") | Y39: =IFERROR(INDEX(차트데이터!$A:$BZ,17,MATCH($Y$2,차트데이터!$1:$1,0)+1),"") | Z39: =$Y$2
D40: IEF | F40: =IFERROR(__xludf.DUMMYFUNCTION("IF(ISBLANK(D40), ""-"", GOOGLEFINANCE(IF(ISBLANK(E40), D40, E40&"":""&D40), ""name""))"),"iShares 7-10 Year Treasury Bond ETF") | G40: 미국중기국채 | H40: =IFERROR(__xludf.DUMMYFUNCTION("IF(ISBLANK(D40), 0, GOOGLEFINANCE(IF(ISBLANK(E40), D40, E40&"":""&D40), ""price""))"),93.17) | I40: =IFERROR(__xludf.DUMMYFUNCTION("IF(ISBLANK(D40), 0, GOOGLEFINANCE(IF(ISBLANK(E40), D40, E40&"":""&D40), ""change""))"),-0.39) | J40: =IFERROR(__xludf.DUMMYFUNCTION("IF(ISBLANK(D40), 0, GOOGLEFINANCE(IF(ISBLANK(E40), D40, E40&"":""&D40), ""changepct"")/100)"),-0.0042) | K40: 1 | L40: =K40 * H40 | O40: =(P40*12)+(Q40*4)+(R40*2)+(S40*1) | P40: =IFERROR((INDEX(차트데이터!$A:$BZ,254,MATCH(D40,차트데이터!$1:$1,0)+1)-INDEX(차트데이터!$A:$BZ,232,MATCH(D40,차트데이터!$1:$1,0)+1))/INDEX(차트데이터!$A:$BZ,232,MATCH(D40,차트데이터!$1:$1,0)+1),"") | Q40: =IFERROR((INDEX(차트데이터!$A:$BZ,254,MATCH(D40,차트데이터!$1:$1,0)+1)-INDEX(차트데이터!$A:$BZ,190,MATCH(D40,차트데이터!$1:$1,0)+1))/INDEX(차트데이터!$A:$BZ,190,MATCH(D40,차트데이터!$1:$1,0)+1),"") | R40: =IFERROR((INDEX(차트데이터!$A:$BZ,254,MATCH(D40,차트데이터!$1:$1,0)+1)-INDEX(차트데이터!$A:$BZ,127,MATCH(D40,차트데이터!$1:$1,0)+1))/INDEX(차트데이터!$A:$BZ,127,MATCH(D40,차트데이터!$1:$1,0)+1),"") | S40: =IFERROR((INDEX(차트데이터!$A:$BZ,254,MATCH(D40,차트데이터!$1:$1,0)+1)-INDEX(차트데이터!$A:$BZ,4,MATCH(D40,차트데이터!$1:$1,0)+1))/INDEX(차트데이터!$A:$BZ,4,MATCH(D40,차트데이터!$1:$1,0)+1),"") | X40: =IFERROR(INDEX(차트데이터!$A:$BZ,18,MATCH($Y$2,차트데이터!$1:$1,0)),"") | Y40: =IFERROR(INDEX(차트데이터!$A:$BZ,18,MATCH($Y$2,차트데이터!$1:$1,0)+1),"") | Z40: =$Y$2
D41: TLT | F41: =IFERROR(__xludf.DUMMYFUNCTION("IF(ISBLANK(D41), ""-"", GOOGLEFINANCE(IF(ISBLANK(E41), D41, E41&"":""&D41), ""name""))"),"iShares 20+ Year Treasury Bond ETF") | G41: 미국장기국채 | H41: =IFERROR(__xludf.DUMMYFUNCTION("IF(ISBLANK(D41), 0, GOOGLEFINANCE(IF(ISBLANK(E41), D41, E41&"":""&D41), ""price""))"),82.85) | I41: =IFERROR(__xludf.DUMMYFUNCTION("IF(ISBLANK(D41), 0, GOOGLEFINANCE(IF(ISBLANK(E41), D41, E41&"":""&D41), ""change""))"),-1.39) | J41: =IFERROR(__xludf.DUMMYFUNCTION("IF(ISBLANK(D41), 0, GOOGLEFINANCE(IF(ISBLANK(E41), D41, E41&"":""&D41), ""changepct"")/100)"),-0.0165) | K41: 1 | L41: =K41 * H41 | O41: =(P41*12)+(Q41*4)+(R41*2)+(S41*1) | P41: =IFERROR((INDEX(차트데이터!$A:$BZ,254,MATCH(D41,차트데이터!$1:$1,0)+1)-INDEX(차트데이터!$A:$BZ,232,MATCH(D41,차트데이터!$1:$1,0)+1))/INDEX(차트데이터!$A:$BZ,232,MATCH(D41,차트데이터!$1:$1,0)+1),"") | Q41: =IFERROR((INDEX(차트데이터!$A:$BZ,254,MATCH(D41,차트데이터!$1:$1,0)+1)-INDEX(차트데이터!$A:$BZ,190,MATCH(D41,차트데이터!$1:$1,0)+1))/INDEX(차트데이터!$A:$BZ,190,MATCH(D41,차트데이터!$1:$1,0)+1),"") | R41: =IFERROR((INDEX(차트데이터!$A:$BZ,254,MATCH(D41,차트데이터!$1:$1,0)+1)-INDEX(차트데이터!$A:$BZ,127,MATCH(D41,차트데이터!$1:$1,0)+1))/INDEX(차트데이터!$A:$BZ,127,MATCH(D41,차트데이터!$1:$1,0)+1),"") | S41: =IFERROR((INDEX(차트데이터!$A:$BZ,254,MATCH(D41,차트데이터!$1:$1,0)+1)-INDEX(차트데이터!$A:$BZ,4,MATCH(D41,차트데이터!$1:$1,0)+1))/INDEX(차트데이터!$A:$BZ,4,MATCH(D41,차트데이터!$1:$1,0)+1),"") | X41: =IFERROR(INDEX(차트데이터!$A:$BZ,19,MATCH($Y$2,차트데이터!$1:$1,0)),"") | Y41: =IFERROR(INDEX(차트데이터!$A:$BZ,19,MATCH($Y$2,차트데이터!$1:$1,0)+1),"") | Z41: =$Y$2
...

Sheet 차트데이터
A1: SPY | D1: VNQ | G1: VEA | J1: EWJ | M1: IWM | P1: VGK | S1: QQQ | V1: DBC | Y1: BND | AB1: VWO | AE1: EMB | AH1: BWX | AK1: HYG | AN1: TIP | AQ1: EFA | AT1: EEM | AW1: AGG | AZ1: LQD | BC1: IEF | BF1: SHY | BI1: TLT | BL1: GLD | BO1: BIL | CB1: SPY
A2: Date | B2: Close | D2: Date | E2: Close | G2: Date | H2: Close | J2: Date | K2: Close | M2: Date | N2: Close | P2: Date | Q2: Close | S2: Date | T2: Close | V2: Date | W2: Close | Y2: Date | Z2: Close | AB2: Date | AC2: Close | AE2: Date | AF2: Close | AH2: Date | AI2: Close | AK2: Date | AL2: Close | AN2: Date | AO2: Close | AQ2: Date | AR2: Close | AT2: Date | AU2: Close | AW2: Date | AX2: Close | AZ2: Date | BA2: Close | BC2: Date | BD2: Close | BF2: Date | BG2: Close | BI2: Date | BJ2: Close | BL2: Date | BM2: Close | BO2: Date | BP2: Close | CB2: QQQ
A3: =IFERROR(__xludf.DUMMYFUNCTION("GOOGLEFINANCE(B18, ""all"", EDATE(TODAY(), -LEFT(G15, FIND("" "", G15))), TODAY(), ""DAILY"")"),"Date") | B3: =IFERROR(__xludf.DUMMYFUNCTION("""COMPUTED_VALUE"""),"Close") | D3: =IFERROR(__xludf.DUMMYFUNCTION("GOOGLEFINANCE(B18, ""all"", EDATE(TODAY(), -LEFT(G15, FIND("" "", G15))), TODAY(), ""DAILY"")"),"Date") | E3: =IFERROR(__xludf.DUMMYFUNCTION("""COMPUTED_VALUE"""),"Close") | G3: =IFERROR(__xludf.DUMMYFUNCTION("GOOGLEFINANCE(B18, ""all"", EDATE(TODAY(), -LEFT(G15, FIND("" "", G15))), TODAY(), ""DAILY"")"),"Date") | H3: =IFERROR(__xludf.DUMMYFUNCTION("""COMPUTED_VALUE"""),"Close") | J3: =IFERROR(__xludf.DUMMYFUNCTION("GOOGLEFINANCE(B18, ""all"", EDATE(TODAY(), -LEFT(G15, FIND("" "", G15))), TODAY(), ""DAILY"")"),"Date") | K3: =IFERROR(__xludf.DUMMYFUNCTION("""COMPUTED_VALUE"""),"Close") | M3: =IFERROR(__xludf.DUMMYFUNCTION("GOOGLEFINANCE(B18, ""all"", EDATE(TODAY(), -LEFT(G15, FIND("" "", G15))), TODAY(), ""DAILY"")"),"Date") | N3: =IFERROR(__xludf.DUMMYFUNCTION("""COMPUTED_VALUE"""),"Close") | P3: =IFERROR(__xludf.DUMMYFUNCTION("GOOGLEFINANCE(B18, ""all"", EDATE(TODAY(), -LEFT(G15, FIND("" "", G15))), TODAY(), ""DAILY"")"),"Date") | Q3: =IFERROR(__xludf.DUMMYFUNCTION("""COMPUTED_VALUE"""),"Close") | S3: =IFERROR(__xludf.DUMMYFUNCTION("GOOGLEFINANCE(B18, ""all"", EDATE(TODAY(), -LEFT(G15, FIND("" "", G15))), TODAY(), ""DAILY"")"),"Date") | T3: =IFERROR(__xludf.DUMMYFUNCTION("""COMPUTED_VALUE"""),"Close") | V3: =IFERROR(__xludf.DUMMYFUNCTION("GOOGLEFINANCE(B18, ""all"", EDATE(TODAY(), -LEFT(G15, FIND("" "", G15))), TODAY(), ""DAILY"")"),"Date") | W3: =IFERROR(__xludf.DUMMYFUNCTION("""COMPUTED_VALUE"""),"Close") | Y3: =IFERROR(__xludf.DUMMYFUNCTION("GOOGLEFINANCE(B18, ""all"", EDATE(TODAY(), -LEFT(G15, FIND("" "", G15))), TODAY(), ""DAILY"")"),"Date") | Z3: =IFERROR(__xludf.DUMMYFUNCTION("""COMPUTED_VALUE"""),"Close") | AB3: =IFERROR(__xludf.DUMMYFUNCTION("GOOGLEFINANCE(B18, ""all"", EDATE(TODAY(), -LEFT(G15, FIND("" "", G15))), TODAY(), ""DAILY"")"),"Date") | AC3: =IFERROR(__xludf.DUMMYFUNCTION("""COMPUTED_VALUE"""),"Close") | AE3: =IFERROR(__xludf.DUMMYFUNCTION("GOOGLEFINANCE(B18, ""all"", EDATE(TODAY(), -LEFT(G15, FIND("" "", G15))), TODAY(), ""DAILY"")"),"Date") | AF3: =IFERROR(__xludf.DUMMYFUNCTION("""COMPUTED_VALUE"""),"Close") | AH3: =IFERROR(__xludf.DUMMYFUNCTION("GOOGLEFINANCE(B18, ""all"", EDATE(TODAY(), -LEFT(G15, FIND("" "", G15))), TODAY(), ""DAILY"")"),"Date") | AI3: =IFERROR(__xludf.DUMMYFUNCTION("""COMPUTED_VALUE"""),"Close") | AK3: =IFERROR(__xludf.DUMMYFUNCTION("GOOGLEFINANCE(B18, ""all"", EDATE(TODAY(), -LEFT(G15, FIND("" "", G15))), TODAY(), ""DAILY"")"),"Date") | AL3: =IFERROR(__xludf.DUMMYFUNCTION("""COMPUTED_VALUE"""),"Close") | AN3: =IFERROR(__xludf.DUMMYFUNCTION("GOOGLEFINANCE(B18, ""all"", EDATE(TODAY(), -LEFT(G15, FIND("" "", G15))), TODAY(), ""DAILY"")"),"Date") | AO3: =IFERROR(__xludf.DUMMYFUNCTION("""COMPUTED_VALUE"""),"Close") | AQ3: =IFERROR(__xludf.DUMMYFUNCTION("GOOGLEFINANCE(B18, ""all"", EDATE(TODAY(), -LEFT(G15, FIND("" "", G15))), TODAY(), ""DAILY"")"),"Date") | AR3: =IFERROR(__xludf.DUMMYFUNCTION("""COMPUTED_VALUE"""),"Close") | AT3: =IFERROR(__xludf.DUMMYFUNCTION("GOOGLEFINANCE(B18, ""all"", EDATE(TODAY(), -LEFT(G15, FIND("" "", G15))), TODAY(), ""DAILY"")"),"Date") | AU3: =IFERROR(__xludf.DUMMYFUNCTION("""COMPUTED_VALUE"""),"Close") | AW3: =IFERROR(__xludf.DUMMYFUNCTION("GOOGLEFINANCE(B18, ""all"", EDATE(TODAY(), -LEFT(G15, FIND("" "", G15))), TODAY(), ""DAILY"")"),"Date") | AX3: =IFERROR(__xludf.DUMMYFUNCTION("""COMPUTED_VALUE"""),"Close") | AZ3: =IFERROR(__xludf.DUMMYFUNCTION("GOOGLEFINANCE(B18, ""all"", EDATE(TODAY(), -LEFT(G15, FIND("" "", G15))), TODAY(), ""DAILY"")"),"Date") | BA3: =IFERROR(__xludf.DUMMYFUNCTION("""COMPUTED_VALUE"""),"Close") | BC3: =IFERROR(__xludf.DUMMYFUNCTION("GOOGLEFINANCE(B18, ""all"", EDATE(TODAY(), -LEFT(G15, FIND("" "", G15))), TODAY(), ""DAILY"")"),"Date") | BD3: =IFERROR(__xludf.DUMMYFUNCTION("""COMPUTED_VALUE"""),"Close") | BF3: =IFERROR(__xludf.DUMMYFUNCTION("GOOGLEFINANCE(B18, ""all"", EDATE(TODAY(), -LEFT(G15, FIND("" "", G15))), TODAY(), ""DAILY"")"),"Date") | BG3: =IFERROR(__xludf.DUMMYFUNCTION("""COMPUTED_VALUE"""),"Close") | BI3: =IFERROR(__xludf.DUMMYFUNCTION("GOOGLEFINANCE(B18, ""all"", EDATE(TODAY(), -LEFT(G15, FIND("" "", G15))), TODAY(), ""DAILY"")"),"Date") | BJ3: =IFERROR(__xludf.DUMMYFUNCTION("""COMPUTED_VALUE"""),"Close") | BL3: =IFERROR(__xludf.DUMMYFUNCTION("GOOGLEFINANCE(B18, ""all"", EDATE(TODAY(), -LEFT(G15, FIND("" "", G15))), TODAY(), ""DAILY"")"),"Date") | BM3: =IFERROR(__xludf.DUMMYFUNCTION("""COMPUTED_VALUE"""),"Close") | BO3: =IFERROR(__xludf.DUMMYFUNCTION("GOOGLEFINANCE(B18, ""all"", EDATE(TODAY(), -LEFT(G15, FIND("" "", G15))), TODAY(), ""DAILY"")"),"Date") | BP3: =IFERROR(__xludf.DUMMYFUNCTION("""COMPUTED_VALUE"""),"Close") | CB3: IWM
