Workbook

Sheet 뱅샐현황
B3: 1.고객정보
B4: 사용자의 기본 정보에 해당하는 항목입니다.
B5: 이름 | C5: 성별 | D5: 연령 (만 나이) | E5: 신용점수 (KCB) | F5: 이메일
B6: 김용 | C6: 남 | D6: 46 | E6: 1000 | F6: -
B9: 2.현금흐름현황
B10: 최근 1년 동안의 현금흐름을 분석합니다.
B11: 항목 | C11: 총계 | D11: 월평균 | E11: 2025-07 | F11: 2025-08 | G11: 2025-09 | H11: 2025-10 | I11: 2025-11 | J11: 2025-12 | K11: 2026-01 | L11: 2026-02 | M11: 2026-03 | N11: 2026-04 | O11: 2026-05 | P11: 2026-06 | Q11: 2026-07
B12: 금융수입 | C12: =SUM(E12:Q12) | D12: =C12/13 | E12: 0 | F12: 0 | G12: 80000 | H12: 1 | I12: 0 | J12: 20000 | K12: 0 | L12: 0 | M12: 4 | N12: 0 | O12: 1 | P12: 0 | Q12: 0
B13: 급여 | C13: =SUM(E13:Q13) | D13: =C13/13 | E13: 0 | F13: 5107809 | G13: 5863980 | H13: 10584640 | I13: 5897358 | J13: 9609713 | K13: 5869380 | L13: 12652275 | M13: 6055700 | N13: 6132550 | O13: 6052268 | P13: 6022650 | Q13: 6065877
B14: 기타수입 | C14: =SUM(E14:Q14) | D14: =C14/13 | E14: 0 | F14: 0 | G14: 0 | H14: 0 | I14: 0 | J14: 0 | K14: 0 | L14: 0 | M14: 0 | N14: 0 | O14: 0 | P14: 10430 | Q14: 0
B15: 사업수입 | C15: =SUM(E15:Q15) | D15: =C15/13 | E15: 0 | F15: 0 | G15: 0 | H15: 0 | I15: 0 | J15: 0 | K15: 0 | L15: 0 | M15: 0 | N15: 1064432 | O15: 0 | P15: 0 | Q15: 0
B16: 상여금 | C16: =SUM(E16:Q16) | D16: =C16/13 | E16: 0 | F16: 0 | G16: 0 | H16: 0 | I16: 0 | J16: 0 | K16: 0 | L16: 0 | M16: 0 | N16: 0 | O16: 0 | P16: 2378785 | Q16: 0
B17: 미분류 | C17: =SUM(E17:Q17) | D17: =C17/13 | E17: 0 | F17: 0 | G17: 0 | H17: 0 | I17: 0 | J17: 0 | K17: 0 | L17: 0 | M17: 0 | N17: 0 | O17: 0 | P17: 0 | Q17: 2279856
B18: 월수입 총계 | C18: =SUM(E18:Q18) | D18: =C18/13 | E18: =SUM(E12:E17) | F18: =SUM(F12:F17) | G18: =SUM(G12:G17) | H18: =SUM(H12:H17) | I18: =SUM(I12:I17) | J18: =SUM(J12:J17) | K18: =SUM(K12:K17) | L18: =SUM(L12:L17) | ... Q18: =SUM(Q12:Q17)
A19: 필수 | B19: 경조/선물 | C19: =SUM(E19:Q19) | D19: =C19/13 | E19: 700000 | F19: 730000 | G19: 700000 | H19: 930000 | I19: 750000 | J19: 750000 | K19: 750000 | L19: 760336 | M19: 721000 | N19: 750000 | O19: 750000 | P19: 750000 | Q19: 50000
A20: 선택 | B20: 교육/학습 | C20: =SUM(E20:Q20) | D20: =C20/13 | E20: 0 | F20: 0 | G20: 10200 | H20: 0 | I20: 0 | J20: 12000 | K20: 85700 | L20: 92190 | M20: 0 | N20: 6000 | O20: 0 | P20: 0 | Q20: 0
A21: 필수 | B21: 교통 | C21: =SUM(E21:Q21) | D21: =C21/13 | E21: 0 | F21: 2900 | G21: 30000 | H21: 30000 | I21: 60750 | J21: 50000 | K21: 63200 | L21: 75300 | M21: 60000 | N21: 53200 | O21: 60000 | P21: 63400 | Q21: 71500
A22: 필수 | B22: 금융 | C22: =SUM(E22:Q22) | D22: =C22/13 | E22: 60380 | F22: 1313802 | G22: 121577701 | H22: 1659562 | I22: 1384699 | J22: 1498194 | K22: 2075322 | L22: 1863655 | M22: 2015670 | N22: 1818208 | O22: 2053519 | P22: 2005859 | Q22: 1995597
A23: 선택 | B23: 문화/여가 | C23: =SUM(E23:Q23) | D23: =C23/13 | E23: 0 | F23: 21900 | G23: 9270 | H23: 0 | I23: 7000 | J23: 18000 | K23: 71490 | L23: 34900 | M23: 54490 | N23: 37900 | O23: 4000 | P23: 48700 | Q23: 11000
A24: 선택 | B24: 반려동물 | C24: =SUM(E24:Q24) | D24: =C24/13 | E24: 0 | F24: 0 | G24: 0 | H24: 0 | I24: 0 | J24: 0 | K24: 0 | L24: 0 | M24: 0 | N24: 0 | O24: 0 | P24: 32500 | Q24: 0
A25: 선택 | B25: 뷰티/미용 | C25: =SUM(E25:Q25) | D25: =C25/13 | E25: 0 | F25: 52400 | G25: 81670 | H25: 41200 | I25: 102433 | J25: 83333 | K25: 150833 | L25: 83333 | M25: 101933 | N25: 83333 | O25: 43610 | P25: 37660 | Q25: 88170
A26: 선택 | B26: 생활 | C26: =SUM(E26:Q26) | D26: =C26/13 | E26: 0 | F26: 517390 | G26: 562764 | H26: 384580 | I26: 657570 | J26: 562880 | K26: 406777 | L26: 664860 | M26: 238890 | N26: 248160 | O26: 611080 | P26: 180400 | Q26: 231160
A27: 선택 | B27: 술/유흥 | C27: =SUM(E27:Q27) | D27: =C27/13 | E27: 0 | F27: 0 | G27: 0 | H27: 0 | I27: 28500 | J27: 0 | K27: 0 | L27: 0 | M27: 0 | N27: 121400 | O27: 0 | P27: 0 | Q27: 0
A28: 선택 | B28: 식비 | C28: =SUM(E28:Q28) | D28: =C28/13 | E28: 198963 | F28: 1064704 | G28: 534182 | H28: 619454 | I28: 814865 | J28: 586715 | K28: 951826 | L28: 1051308 | M28: 1223049 | N28: 824610 | O28: 1109662 | P28: 717950 | Q28: 1162035
A29: 선택 | B29: 여행/숙박 | C29: =SUM(E29:Q29) | D29: =C29/13 | E29: 0 | F29: 0 | G29: 0 | H29: 42000 | I29: 0 | J29: 0 | K29: 28500 | L29: 126254 | M29: 3000 | N29: 61400 | O29: 10000 | P29: 220900 | Q29: 0
A30: 선택 | B30: 온라인쇼핑 | C30: =SUM(E30:Q30) | D30: =C30/13 | E30: 95160 | F30: 796617 | G30: 5908354 | H30: 478950 | I30: 1478034 | J30: 251792 | K30: 894758 | L30: 253822 | M30: 505824 | N30: 365333 | O30: 286309 | P30: 688755 | Q30: 188672
... A37: 선택 | B37: 미분류 | C37: =SUM(E37:Q37) | D37: =C37/13 | E37: 0 | F37: 0 | G37: 0 | H37: 0 | I37: 0 | J37: 0 | K37: 0 | L37: 0 | M37: 0 | N37: 0 | O37: 0 | P37: 0 | Q37: 0
B38: 월지출 총계 | C38: =SUM(E38:Q38) | D38: =C38/13 | E38: =SUM(E19:E37) | F38: =SUM(F19:F37) | G38: =SUM(G19:G37) | H38: =SUM(H19:H37) | I38: =SUM(I19:I37) | J38: =SUM(J19:J37) | K38: =SUM(K19:K37) | L38: =SUM(L19:L37) | ... Q38: =SUM(Q19:Q37)
B39: 순수입 총계 | C39: =SUM(E39:Q39) | D39: =C39/13 | E39: =E18-E38 | F39: =F18-F38 | G39: =G18-G38 | H39: =H18-H38 | I39: =I18-I38 | J39: =J18-J38 | K39: =K18-K38 | L39: =L18-L38 | ... Q39: =Q18-Q38
B42: 3.재무현황
B43: 데이터를 내보낸 시점의 자산과 부채 상태를 분석합니다.
B44: 자산 | F44: 부채
B45: 항목 | C45: 상품명 | E45: 금액 | F45: 항목 | G45: 상품명 | I45: 금액
B46: 자유입출금 자산 | C46: AMA+급여 MMDA | E46: 0 | F46: 장기대출 | G46: 하나은행 마이너스 통장 | I46: 121685737
C47: AMA+급여 저축예금 | E47: 0 | G47: 가계일반자금대출(분할상환)-하나 아파트론(혼합금리형) | I47: 207103001
C48: MY 입출금통장 | E48: 1 | G48: 하나은행 마이너스 통장 | I48: 1726305
C49: NH주거래우대통장(비대면실명확인) | E49: 0 | G49: 2020년 2학기 일반상환학자금_등록금 | I49: 5448520
C50: 넘버엔 통장 | E50: -121685737 | G50: 2021년 2학기 일반상환학자금_등록금 | I50: 5441312
C51: 달달 하나 통장 | E51: -1726305 | G51: 2020년 1학기 일반상환학자금_등록금 | I51: 5198750
C52: 샐러리맨리치예금(스페셜플러스예금) | E52: 86 | G52: 2021년 1학기 일반상환학자금_등록금 | I52: 5129730
...

Sheet 대시보드
B1: 전체 투자금 | C1: 16666666 | G1: 채권 | H1: =C3/3
B2: 한국 개별주 퀀트 | C2: =C1*60% | G2: 변형 듀얼모멘텀 | H2: =C3/3
B3: 동적자산배분 | C3: =C1*40% | G3: BAA | H3: =C3/3
B5: ㅣBAA | H5: ㅣ변형 듀얼모멘텀 | O5: ㅣ채권 동적자산배분
B6: Q. 카나리아 자산 중 "0"이하인 모멘텀 스코어가 있나요? | H6: Step1. 공격자산 수익률이 모두 "0"이상인 경우, 수익률이 높은 자산에 100%투자합니다
B7: ㅣBAA중도형_카나리아 자산
C8: =BD!Z28 | H8: ㅣ변형 듀얼모멘텀_공격자산
B9: SPY | C9: =BD!Z29 | H9: =BD!A36 | I9: =BD!B36
B10: EFA | C10: =BD!Z30 | H10: =BD!A37 | I10: =BD!B37
B11: EEM | C11: =BD!Z31 | H11: =BD!A38 | I11: =BD!B38
B12: AGG | C12: =BD!Z32
H13: Step2. SPY의 수익률이 "0"이하인 경우, 안전자산 중 수익률 높은 채권 3개를 매수합니다 But, 수익률이 "0" 이하인 자산은 현금보유
B14: A-1. 네, "0" 이하가 있어요
B15: 공격자산 투자중단! ↓아래있는 안전자산의 최근수익률이 높은 3개 자산에 투자합니다 But,(현재가격<12개월 이동평균)이면 현금으로 보유
H16: 종목당 투자금액 | I16: =H2/3
B17: 종목당 투자액 | C17: =H3/3 | H17: ㅣ변형 듀얼모멘텀_안전자산
B18: ㅣBAA 안전자산 | H18: =BD!A41 | I18: =BD!T41 | N18: 216 9002
C19: 현재/12개월이평 | D19: =BD!B18 | E19: =BD!P18 | H19: =BD!A42 | I19: =BD!T42
B20: =BD!A19 | C20: =BD!Q19 | D20: =BD!B19 | E20: =BD!P19 | H20: =BD!A43 | I20: =BD!T43
B21: =BD!A20 | C21: =BD!Q20 | D21: =BD!B20 | E21: =BD!P20 | H21: =BD!A44 | I21: =BD!T44
B22: =BD!A21 | C22: =BD!Q21 | D22: =BD!B21 | E22: =BD!P21 | H22: =BD!A45 | I22: =BD!T45
B23: =BD!A22 | C23: =BD!Q22 | D23: =BD!B22 | E23: =BD!P22 | H23: =BD!A46 | I23: =BD!T46
B24: =BD!A23 | C24: =BD!Q23 | D24: =BD!B23 | E24: =BD!P23 | H24: =BD!A47 | I24: =BD!T47
B25: =BD!A24 | C25: =BD!Q24 | D25: =BD!B24 | E25: =BD!P24 | H25: =BD!A48 | I25: =BD!T48
B26: =BD!A25 | C26: =BD!Q25 | D26: =BD!B25 | E26: =BD!P25 | H26: =BD!A49 | I26: =BD!T49
B28: A-2. 모두 "0" 보다 커요(BAA중도형) | E28: A-2. 모두 "0" 보다 커요(BAA공격형)
B29: ↓아래있는 [BAA중도형_공격자산 12종목] 또는 [BAA공격형]중 모멘텀 스코어가 높은 6개 자산에 투자합니다 | E29: BAA 공격형 투자는 최근수익률이 높은 1개 자산에 몰빵! 합니다
B31: 종목당 투자액 | C31: =H3/6 | E31: 종목당 투자액 | F31: =H3
B32: ㅣBAA 중도형_공격자산 12종목 | E32: ㅣBAA공격형(수익↑, MDD↑)
C33: =BD!Z4 | D33: 현재/12개월이평 | F33: 모멘텀 스코어 | G33: 현재/12개월이평
B34: =BD!A5 | C34: =BD!Z5 | D34: =BD!Q5 | E34: =관심종목!D26 | F34: =BD!Z33 | G34: =BD!Q29
B35: =BD!A6 | C35: =BD!Z6 | D35: =BD!Q6 | E35: =관심종목!D23 | F35: =BD!Z30 | G35: =BD!Q30
B36: =BD!A7 | C36: =BD!Z7 | D36: =BD!Q7 | E36: =관심종목!D24 | F36: =BD!Z31 | G36: =BD!Q31
B37: =BD!A8 | C37: =BD!Z8 | D37: =BD!Q8 | E37: =관심종목!D25 | F37: =BD!Z32 | G37: =BD!Q32
B38: =BD!A9 | C38: =BD!Z9 | D38: =BD!Q9
B39: =BD!A10 | C39: =BD!Z10 | D39: =BD!Q10
B40: =BD!A11 | C40: =BD!Z11 | D40: =BD!Q11
B41: =BD!A12 | C41: =BD!Z12 | D41: =BD!Q12
B42: =BD!A13 | C42: =BD!Z13 | D42: =BD!Q13
B43: =BD!A14 | C43: =BD!Z14 | D43: =BD!Q14
...

Sheet 관심종목
D1: 안내 B열에 추적할 주식의 종목코드를 입력합니다. H열에 평가금액을 추적할 주식의 수량을 입력합니다. | L1: 제공: | P1: 차트 보기 안내
L2: Google Finance | P2: D열 Ticker를 클릭하면 해당 종목 차트 시트로 이동합니다.
P3: 각 차트 시트의 B1 링크로 관심종목으로 돌아올 수 있습니다.
F4: 관심종목
F5: 평가금액 | P5: 이벤트 관리로 이동
F6: =SUM(N9:N55)
A8: 전략 명 | B8: 투자비율 | C8: 포트폴리오 명 | D8: 종목코드 | E8: 거래소 (선택사항) | F8: 종목명 | H8: 현재가 | I8: 전일대비 | J8: 등락률(%) | K8: 주식수 | L8: 평가금액 | M8: 종목 합계 | O8: 모멘텀스코어 | P8: 1개월수익률 | Q8: 3개월수익률 | R8: 6개월수익률 | S8: 12개월수익률 | T8: 12개월 이동평균 | U8: 현재가격/ 12개월이동평균
E9: NASDAQ | F9: =IFERROR(__xludf.DUMMYFUNCTION("IF(ISBLANK(D9), ""-"", GOOGLEFINANCE(IF(ISBLANK(E9), D9, E9&"":""&D9), ""name""))"),"-") | H9: =IFERROR(__xludf.DUMMYFUNCTION("IF(ISBLANK(D9), 0, GOOGLEFINANCE(IF(ISBLANK(E9), D9, E9&"":""&D9), ""price""))"),0) | I9: =IFERROR(__xludf.DUMMYFUNCTION("IF(ISBLANK(D9), 0, GOOGLEFINANCE(IF(ISBLANK(E9), D9, E9&"":""&D9), ""change""))"),0) | J9: =IFERROR(__xludf.DUMMYFUNCTION("IF(ISBLANK(D9), 0, GOOGLEFINANCE(IF(ISBLANK(E9), D9, E9&"":""&D9), ""changepct"")/100)"),0) | K9: 0 | L9: =K9 * H9 | O9: =(P9*12)+(Q9*4)+(R9*2)+(S9*1)
C10: BAA 공격자산 | D10: SPY | F10: =IFERROR(__xludf.DUMMYFUNCTION("IF(ISBLANK(D10), ""-"", GOOGLEFINANCE(IF(ISBLANK(E10), D10, E10&"":""&D10), ""name""))"),"State Street SPDR S&P 500 ETF Trust") | H10: =IFERROR(__xludf.DUMMYFUNCTION("IF(ISBLANK(D10), 0, GOOGLEFINANCE(IF(ISBLANK(E10), D10, E10&"":""&D10), ""price""))"),729.46) | I10: =IFERROR(__xludf.DUMMYFUNCTION("IF(ISBLANK(D10), 0, GOOGLEFINANCE(IF(ISBLANK(E10), D10, E10&"":""&D10), ""change""))"),-11.4) | J10: =IFERROR(__xludf.DUMMYFUNCTION("IF(ISBLANK(D10), 0, GOOGLEFINANCE(IF(ISBLANK(E10), D10, E10&"":""&D10), ""changepct"")/100)"),-0.0154) | K10: 1 | L10: =K10 * H10 | O10: =(P10*12)+(Q10*4)+(R10*2)+(S10*1) | P10: =(SPY!F278-SPY!F256)/SPY!F256 | Q10: =(SPY!F278-SPY!F214)/SPY!F214 | R10: =(SPY!F278-SPY!F151)/SPY!F151 | S10: =(SPY!F278-SPY!F28)/SPY!F28
D11: QQQ | F11: =IFERROR(__xludf.DUMMYFUNCTION("IF(ISBLANK(D11), ""-"", GOOGLEFINANCE(IF(ISBLANK(E11), D11, E11&"":""&D11), ""name""))"),"Invesco QQQ Trust, Series 1") | H11: =IFERROR(__xludf.DUMMYFUNCTION("IF(ISBLANK(D11), 0, GOOGLEFINANCE(IF(ISBLANK(E11), D11, E11&"":""&D11), ""price""))"),661.73) | I11: =IFERROR(__xludf.DUMMYFUNCTION("IF(ISBLANK(D11), 0, GOOGLEFINANCE(IF(ISBLANK(E11), D11, E11&"":""&D11), ""change""))"),-13.76) | J11: =IFERROR(__xludf.DUMMYFUNCTION("IF(ISBLANK(D11), 0, GOOGLEFINANCE(IF(ISBLANK(E11), D11, E11&"":""&D11), ""changepct"")/100)"),-0.0204) | K11: 1 | L11: =K11 * H11 | O11: =(P11*12)+(Q11*4)+(R11*2)+(S11*1) | P11: =(TLT!$F$278-TLT!$F$256)/TLT!$F$256 | Q11: =(TLT!$F$278-TLT!$F$214)/TLT!$F$214 | R11: =(TLT!$F$278-TLT!$F$151)/TLT!$F$151 | S11: =(TLT!$F$278-TLT!$F$28)/TLT!$F$28
D12: IWM | F12: =IFERROR(__xludf.DUMMYFUNCTION("IF(ISBLANK(D12), ""-"", GOOGLEFINANCE(IF(ISBLANK(E12), D12, E12&"":""&D12), ""name""))"),"iShares Russell 2000 ETF") | H12: =IFERROR(__xludf.DUMMYFUNCTION("IF(ISBLANK(D12), 0, GOOGLEFINANCE(IF(ISBLANK(E12), D12, E12&"":""&D12), ""price""))"),288.57) | I12: =IFERROR(__xludf.DUMMYFUNCTION("IF(ISBLANK(D12), 0, GOOGLEFINANCE(IF(ISBLANK(E12), D12, E12&"":""&D12), ""change""))"),-4.8) | J12: =IFERROR(__xludf.DUMMYFUNCTION("IF(ISBLANK(D12), 0, GOOGLEFINANCE(IF(ISBLANK(E12), D12, E12&"":""&D12), ""changepct"")/100)"),-0.0163999999999999) | K12: 1 | L12: =K12 * H12 | O12: =(P12*12)+(Q12*4)+(R12*2)+(S12*1) | P12: =(GLD!F278-GLD!F256)/GLD!F256 | Q12: =(GLD!F278-GLD!F214)/GLD!F214 | R12: =(GLD!F278-GLD!F151)/GLD!F151 | S12: =(GLD!F278-GLD!F28)/GLD!F28
D13: VGK | F13: =IFERROR(__xludf.DUMMYFUNCTION("IF(ISBLANK(D13), ""-"", GOOGLEFINANCE(IF(ISBLANK(E13), D13, E13&"":""&D13), ""name""))"),"Vanguard European Stock Index Fund ETF") | H13: =IFERROR(__xludf.DUMMYFUNCTION("IF(ISBLANK(D13), 0, GOOGLEFINANCE(IF(ISBLANK(E13), D13, E13&"":""&D13), ""price""))"),88.86) | I13: =IFERROR(__xludf.DUMMYFUNCTION("IF(ISBLANK(D13), 0, GOOGLEFINANCE(IF(ISBLANK(E13), D13, E13&"":""&D13), ""change""))"),-0.37) | J13: =IFERROR(__xludf.DUMMYFUNCTION("IF(ISBLANK(D13), 0, GOOGLEFINANCE(IF(ISBLANK(E13), D13, E13&"":""&D13), ""changepct"")/100)"),-0.00409999999999999) | K13: 1 | L13: =K13 * H13 | O13: =(P13*12)+(Q13*4)+(R13*2)+(S13*1) | P13: =(BIL!$F$278-BIL!$F$256)/BIL!$F$256 | Q13: =(BIL!$F$278-BIL!$F$214)/BIL!$F$214 | R13: =(BIL!$F$278-BIL!$F$151)/BIL!$F$151 | S13: =(BIL!$F$278-BIL!$F$28)/BIL!$F$28
D14: EWJ | F14: =IFERROR(__xludf.DUMMYFUNCTION("IF(ISBLANK(D14), ""-"", GOOGLEFINANCE(IF(ISBLANK(E14), D14, E14&"":""&D14), ""name""))"),"iShares MSCI Japan ETF") | H14: =IFERROR(__xludf.DUMMYFUNCTION("IF(ISBLANK(D14), 0, GOOGLEFINANCE(IF(ISBLANK(E14), D14, E14&"":""&D14), ""price""))"),89.35) | I14: =IFERROR(__xludf.DUMMYFUNCTION("IF(ISBLANK(D14), 0, GOOGLEFINANCE(IF(ISBLANK(E14), D14, E14&"":""&D14), ""change""))"),-0.48) | J14: =IFERROR(__xludf.DUMMYFUNCTION("IF(ISBLANK(D14), 0, GOOGLEFINANCE(IF(ISBLANK(E14), D14, E14&"":""&D14), ""changepct"")/100)"),-0.0053) | K14: 1 | L14: =K14 * H14
D15: VWO | F15: =IFERROR(__xludf.DUMMYFUNCTION("IF(ISBLANK(D15), ""-"", GOOGLEFINANCE(IF(ISBLANK(E15), D15, E15&"":""&D15), ""name""))"),"Vanguard Emerging Markets Stock Index Fund ETF") | H15: =IFERROR(__xludf.DUMMYFUNCTION("IF(ISBLANK(D15), 0, GOOGLEFINANCE(IF(ISBLANK(E15), D15, E15&"":""&D15), ""price""))"),56.92) | I15: =IFERROR(__xludf.DUMMYFUNCTION("IF(ISBLANK(D15), 0, GOOGLEFINANCE(IF(ISBLANK(E15), D15, E15&"":""&D15), ""change""))"),-0.82) | J15: =IFERROR(__xludf.DUMMYFUNCTION("IF(ISBLANK(D15), 0, GOOGLEFINANCE(IF(ISBLANK(E15), D15, E15&"":""&D15), ""changepct"")/100)"),-0.0141999999999999) | K15: 1 | L15: =K15 * H15
D16: VEA | F16: =IFERROR(__xludf.DUMMYFUNCTION("IF(ISBLANK(D16), ""-"", GOOGLEFINANCE(IF(ISBLANK(E16), D16, E16&"":""&D16), ""name""))"),"Vanguard Tax Managed Fund FTSE Developed Markets ETF") | H16: =IFERROR(__xludf.DUMMYFUNCTION("IF(ISBLANK(D16), 0, GOOGLEFINANCE(IF(ISBLANK(E16), D16, E16&"":""&D16), ""price""))"),68.95) | I16: =IFERROR(__xludf.DUMMYFUNCTION("IF(ISBLANK(D16), 0, GOOGLEFINANCE(IF(ISBLANK(E16), D16, E16&"":""&D16), ""change""))"),-0.65) | J16: =IFERROR(__xludf.DUMMYFUNCTION("IF(ISBLANK(D16), 0, GOOGLEFINANCE(IF(ISBLANK(E16), D16, E16&"":""&D16), ""changepct"")/100)"),-0.0093) | K16: 1 | L16: =K16 * H16
D17: VNQ | F17: =IFERROR(__xludf.DUMMYFUNCTION("IF(ISBLANK(D17), ""-"", GOOGLEFINANCE(IF(ISBLANK(E17), D17, E17&"":""&D17), ""name""))"),"Vanguard Real Estate Index Fund ETF") | H17: =IFERROR(__xludf.DUMMYFUNCTION("IF(ISBLANK(D17), 0, GOOGLEFINANCE(IF(ISBLANK(E17), D17, E17&"":""&D17), ""price""))"),100.66) | I17: =IFERROR(__xludf.DUMMYFUNCTION("IF(ISBLANK(D17), 0, GOOGLEFINANCE(IF(ISBLANK(E17), D17, E17&"":""&D17), ""change""))"),-0.29) | J17: =IFERROR(__xludf.DUMMYFUNCTION("IF(ISBLANK(D17), 0, GOOGLEFINANCE(IF(ISBLANK(E17), D17, E17&"":""&D17), ""changepct"")/100)"),-0.0029) | K17: 1 | L17: =K17 * H17
D18: DBC | F18: =IFERROR(__xludf.DUMMYFUNCTION("IF(ISBLANK(D18), ""-"", GOOGLEFINANCE(IF(ISBLANK(E18), D18, E18&"":""&D18), ""name""))"),"Invesco DB Commodity Index Tracking Fund") | H18: =IFERROR(__xludf.DUMMYFUNCTION("IF(ISBLANK(D18), 0, GOOGLEFINANCE(IF(ISBLANK(E18), D18, E18&"":""&D18), ""price""))"),29.42) | I18: =IFERROR(__xludf.DUMMYFUNCTION("IF(ISBLANK(D18), 0, GOOGLEFINANCE(IF(ISBLANK(E18), D18, E18&"":""&D18), ""change""))"),0.82) | J18: =IFERROR(__xludf.DUMMYFUNCTION("IF(ISBLANK(D18), 0, GOOGLEFINANCE(IF(ISBLANK(E18), D18, E18&"":""&D18), ""changepct"")/100)"),0.0287) | K18: 1 | L18: =K18 * H18
D19: GLD | F19: =IFERROR(__xludf.DUMMYFUNCTION("IF(ISBLANK(D19), ""-"", GOOGLEFINANCE(IF(ISBLANK(E19), D19, E19&"":""&D19), ""name""))"),"SPDR Gold Trust") | H19: =IFERROR(__xludf.DUMMYFUNCTION("IF(ISBLANK(D19), 0, GOOGLEFINANCE(IF(ISBLANK(E19), D19, E19&"":""&D19), ""price""))"),371.08) | I19: =IFERROR(__xludf.DUMMYFUNCTION("IF(ISBLANK(D19), 0, GOOGLEFINANCE(IF(ISBLANK(E19), D19, E19&"":""&D19), ""change""))"),1.71) | J19: =IFERROR(__xludf.DUMMYFUNCTION("IF(ISBLANK(D19), 0, GOOGLEFINANCE(IF(ISBLANK(E19), D19, E19&"":""&D19), ""changepct"")/100)"),0.0046) | K19: 1 | L19: =K19 * H19
D20: LQD | F20: =IFERROR(__xludf.DUMMYFUNCTION("IF(ISBLANK(D20), ""-"", GOOGLEFINANCE(IF(ISBLANK(E20), D20, E20&"":""&D20), ""name""))"),"iShares iBoxx $ Inv Grade Corporate Bond ETF") | H20: =IFERROR(__xludf.DUMMYFUNCTION("IF(ISBLANK(D20), 0, GOOGLEFINANCE(IF(ISBLANK(E20), D20, E20&"":""&D20), ""price""))"),106.22) | I20: =IFERROR(__xludf.DUMMYFUNCTION("IF(ISBLANK(D20), 0, GOOGLEFINANCE(IF(ISBLANK(E20), D20, E20&"":""&D20), ""change""))"),-0.61) | J20: =IFERROR(__xludf.DUMMYFUNCTION("IF(ISBLANK(D20), 0, GOOGLEFINANCE(IF(ISBLANK(E20), D20, E20&"":""&D20), ""changepct"")/100)"),-0.00569999999999999) | K20: 1 | L20: =K20 * H20
D21: HYG | F21: =IFERROR(__xludf.DUMMYFUNCTION("IF(ISBLANK(D21), ""-"", GOOGLEFINANCE(IF(ISBLANK(E21), D21, E21&"":""&D21), ""name""))"),"iShares iBoxx $ High Yield Corporate Bond ETF") | H21: =IFERROR(__xludf.DUMMYFUNCTION("IF(ISBLANK(D21), 0, GOOGLEFINANCE(IF(ISBLANK(E21), D21, E21&"":""&D21), ""price""))"),79.24) | I21: =IFERROR(__xludf.DUMMYFUNCTION("IF(ISBLANK(D21), 0, GOOGLEFINANCE(IF(ISBLANK(E21), D21, E21&"":""&D21), ""change""))"),-0.18) | J21: =IFERROR(__xludf.DUMMYFUNCTION("IF(ISBLANK(D21), 0, GOOGLEFINANCE(IF(ISBLANK(E21), D21, E21&"":""&D21), ""changepct"")/100)"),-0.0023) | K21: 1 | L21: =K21 * H21
C22: BAA 카나리아 | D22: SPY | F22: =IFERROR(__xludf.DUMMYFUNCTION("IF(ISBLANK(D22), ""-"", GOOGLEFINANCE(IF(ISBLANK(E22), D22, E22&"":""&D22), ""name""))"),"State Street SPDR S&P 500 ETF Trust") | G22: 미국 주식 | H22: =IFERROR(__xludf.DUMMYFUNCTION("IF(ISBLANK(D22), 0, GOOGLEFINANCE(IF(ISBLANK(E22), D22, E22&"":""&D22), ""price""))"),729.46) | I22: =IFERROR(__xludf.DUMMYFUNCTION("IF(ISBLANK(D22), 0, GOOGLEFINANCE(IF(ISBLANK(E22), D22, E22&"":""&D22), ""change""))"),-11.4) | J22: =IFERROR(__xludf.DUMMYFUNCTION("IF(ISBLANK(D22), 0, GOOGLEFINANCE(IF(ISBLANK(E22), D22, E22&"":""&D22), ""changepct"")/100)"),-0.0154) | K22: 1 | L22: =K22 * H22 | O22: =(P22*12)+(Q22*4)+(R22*2)+(S22*1) | P22: =(SPY!$F$278-SPY!$F$256)/SPY!$F$256 | Q22: =(SPY!$F$278-SPY!$F$214)/SPY!$F$214 | R22: =(SPY!$F$278-SPY!$F$151)/SPY!$F$151 | S22: =(SPY!$F$278-SPY!$F$28)/SPY!$F$28 | V22: 모멘텀 스코어가 0이하인 ETF가 하나라도 있으면 공격자산 투자중단->안전자산으로 이동
D23: EFA | F23: =IFERROR(__xludf.DUMMYFUNCTION("IF(ISBLANK(D23), ""-"", GOOGLEFINANCE(IF(ISBLANK(E23), D23, E23&"":""&D23), ""name""))"),"iShares MSCI EAFE ETF") | G23: 선진국 주식 | H23: =IFERROR(__xludf.DUMMYFUNCTION("IF(ISBLANK(D23), 0, GOOGLEFINANCE(IF(ISBLANK(E23), D23, E23&"":""&D23), ""price""))"),103.37) | I23: =IFERROR(__xludf.DUMMYFUNCTION("IF(ISBLANK(D23), 0, GOOGLEFINANCE(IF(ISBLANK(E23), D23, E23&"":""&D23), ""change""))"),-0.52) | J23: =IFERROR(__xludf.DUMMYFUNCTION("IF(ISBLANK(D23), 0, GOOGLEFINANCE(IF(ISBLANK(E23), D23, E23&"":""&D23), ""changepct"")/100)"),-0.005) | K23: 1 | L23: =K23 * H23 | O23: =(P23*12)+(Q23*4)+(R23*2)+(S23*1) | P23: =(EFA!$F$278-EFA!$F$256)/EFA!$F$256 | Q23: =(EFA!$F$278-EFA!$F$214)/EFA!$F$214 | R23: =(EFA!$F$278-EFA!$F$151)/EFA!$F$151 | S23: =(EFA!$F$278-EFA!$F$28)/EFA!$F$28
D24: EEM | F24: =IFERROR(__xludf.DUMMYFUNCTION("IF(ISBLANK(D24), ""-"", GOOGLEFINANCE(IF(ISBLANK(E24), D24, E24&"":""&D24), ""name""))"),"iShares MSCI Emerging Markets ETF") | G24: 개발도상국 | H24: =IFERROR(__xludf.DUMMYFUNCTION("IF(ISBLANK(D24), 0, GOOGLEFINANCE(IF(ISBLANK(E24), D24, E24&"":""&D24), ""price""))"),61.07) | I24: =IFERROR(__xludf.DUMMYFUNCTION("IF(ISBLANK(D24), 0, GOOGLEFINANCE(IF(ISBLANK(E24), D24, E24&"":""&D24), ""change""))"),-1.29) | J24: =IFERROR(__xludf.DUMMYFUNCTION("IF(ISBLANK(D24), 0, GOOGLEFINANCE(IF(ISBLANK(E24), D24, E24&"":""&D24), ""changepct"")/100)"),-0.0207) | K24: 1 | L24: =K24 * H24 | O24: =(P24*12)+(Q24*4)+(R24*2)+(S24*1) | P24: =(EEM!F278-EEM!F256)/EEM!F256 | Q24: =(EEM!F278-EEM!F214)/EEM!F214 | R24: =(EEM!F278-EEM!F151)/EEM!F151 | S24: =(EEM!F278-EEM!F28)/EEM!F28
D25: AGG | F25: =IFERROR(__xludf.DUMMYFUNCTION("IF(ISBLANK(D25), ""-"", GOOGLEFINANCE(IF(ISBLANK(E25), D25, E25&"":""&D25), ""name""))"),"iShares Core US Aggregate Bond ETF") | G25: 혼합채권 | H25: =IFERROR(__xludf.DUMMYFUNCTION("IF(ISBLANK(D25), 0, GOOGLEFINANCE(IF(ISBLANK(E25), D25, E25&"":""&D25), ""price""))"),97.55) | I25: =IFERROR(__xludf.DUMMYFUNCTION("IF(ISBLANK(D25), 0, GOOGLEFINANCE(IF(ISBLANK(E25), D25, E25&"":""&D25), ""change""))"),-0.37) | J25: =IFERROR(__xludf.DUMMYFUNCTION("IF(ISBLANK(D25), 0, GOOGLEFINANCE(IF(ISBLANK(E25), D25, E25&"":""&D25), ""changepct"")/100)"),-0.0038) | K25: 1 | L25: =K25 * H25 | O25: =(P25*12)+(Q25*4)+(R25*2)+(S25*1) | P25: =(AGG!F278-AGG!F256)/AGG!F256 | Q25: =(AGG!F278-AGG!F214)/AGG!F214 | R25: =(AGG!F278-AGG!F151)/AGG!F151 | S25: =(AGG!F278-AGG!F28)/AGG!F28
D26: QQQ | F26: =IFERROR(__xludf.DUMMYFUNCTION("IF(ISBLANK(D26), ""-"", GOOGLEFINANCE(IF(ISBLANK(E26), D26, E26&"":""&D26), ""name""))"),"Invesco QQQ Trust, Series 1") | G26: 미국 주식 | H26: =IFERROR(__xludf.DUMMYFUNCTION("IF(ISBLANK(D26), 0, GOOGLEFINANCE(IF(ISBLANK(E26), D26, E26&"":""&D26), ""price""))"),661.73) | I26: =IFERROR(__xludf.DUMMYFUNCTION("IF(ISBLANK(D26), 0, GOOGLEFINANCE(IF(ISBLANK(E26), D26, E26&"":""&D26), ""change""))"),-13.76) | J26: =IFERROR(__xludf.DUMMYFUNCTION("IF(ISBLANK(D26), 0, GOOGLEFINANCE(IF(ISBLANK(E26), D26, E26&"":""&D26), ""changepct"")/100)"),-0.0204) | K26: 1 | L26: =K26 * H26
C27: BAA 안전자산 | D27: LQD | F27: =IFERROR(__xludf.DUMMYFUNCTION("IF(ISBLANK(D27), ""-"", GOOGLEFINANCE(IF(ISBLANK(E27), D27, E27&"":""&D27), ""name""))"),"iShares iBoxx $ Inv Grade Corporate Bond ETF") | G27: 미국회사채 | H27: =IFERROR(__xludf.DUMMYFUNCTION("IF(ISBLANK(D27), 0, GOOGLEFINANCE(IF(ISBLANK(E27), D27, E27&"":""&D27), ""price""))"),106.22) | I27: =IFERROR(__xludf.DUMMYFUNCTION("IF(ISBLANK(D27), 0, GOOGLEFINANCE(IF(ISBLANK(E27), D27, E27&"":""&D27), ""change""))"),-0.61) | J27: =IFERROR(__xludf.DUMMYFUNCTION("IF(ISBLANK(D27), 0, GOOGLEFINANCE(IF(ISBLANK(E27), D27, E27&"":""&D27), ""changepct"")/100)"),-0.00569999999999999) | K27: 1 | L27: =K27 * H27 | O27: =(P27*12)+(Q27*4)+(R27*2)+(S27*1) | P27: =(LQD!F278-LQD!F256)/LQD!F256 | Q27: =(LQD!F278-LQD!F214)/LQD!F214 | R27: =(LQD!F278-LQD!F151)/LQD!F151 | S27: =(LQD!F278-LQD!F28)/LQD!F28 | V27: 현재가격/12개월 이동평균이 높은 3개에 투자 But,현재가격이 이동평균보다 낮으면 현금으로 보유
D28: IEF | F28: =IFERROR(__xludf.DUMMYFUNCTION("IF(ISBLANK(D28), ""-"", GOOGLEFINANCE(IF(ISBLANK(E28), D28, E28&"":""&D28), ""name""))"),"iShares 7-10 Year Treasury Bond ETF") | G28: 미국중기국채 | H28: =IFERROR(__xludf.DUMMYFUNCTION("IF(ISBLANK(D28), 0, GOOGLEFINANCE(IF(ISBLANK(E28), D28, E28&"":""&D28), ""price""))"),93.17) | I28: =IFERROR(__xludf.DUMMYFUNCTION("IF(ISBLANK(D28), 0, GOOGLEFINANCE(IF(ISBLANK(E28), D28, E28&"":""&D28), ""change""))"),-0.39) | J28: =IFERROR(__xludf.DUMMYFUNCTION("IF(ISBLANK(D28), 0, GOOGLEFINANCE(IF(ISBLANK(E28), D28, E28&"":""&D28), ""changepct"")/100)"),-0.0042) | K28: 1 | L28: =K28 * H28 | O28: =(P28*12)+(Q28*4)+(R28*2)+(S28*1) | P28: =(IEF!F278-IEF!F256)/IEF!F256 | Q28: =(IEF!F278-IEF!F214)/IEF!F214 | R28: =(IEF!F278-IEF!F151)/IEF!F151 | S28: =(IEF!F278-IEF!F28)/IEF!F28
D29: BIL | F29: =IFERROR(__xludf.DUMMYFUNCTION("IF(ISBLANK(D29), ""-"", GOOGLEFINANCE(IF(ISBLANK(E29), D29, E29&"":""&D29), ""name""))"),"State Street SPDR Bloomberg 1-3 Month T-Bill ETF") | G29: 미국초단기채권 | H29: =IFERROR(__xludf.DUMMYFUNCTION("IF(ISBLANK(D29), 0, GOOGLEFINANCE(IF(ISBLANK(E29), D29, E29&"":""&D29), ""price""))"),91.64) | I29: =IFERROR(__xludf.DUMMYFUNCTION("IF(ISBLANK(D29), 0, GOOGLEFINANCE(IF(ISBLANK(E29), D29, E29&"":""&D29), ""change""))"),0.01) | J29: =IFERROR(__xludf.DUMMYFUNCTION("IF(ISBLANK(D29), 0, GOOGLEFINANCE(IF(ISBLANK(E29), D29, E29&"":""&D29), ""changepct"")/100)"),0.0001) | K29: 1 | L29: =K29 * H29 | O29: =(P29*12)+(Q29*4)+(R29*2)+(S29*1) | P29: =(BIL!$F$278-BIL!$F$256)/BIL!$F$256 | Q29: =(BIL!$F$278-BIL!$F$214)/BIL!$F$214 | R29: =(BIL!$F$278-BIL!$F$151)/BIL!$F$151 | S29: =(BIL!$F$278-BIL!$F$28)/BIL!$F$28
D30: TLT | F30: =IFERROR(__xludf.DUMMYFUNCTION("IF(ISBLANK(D30), ""-"", GOOGLEFINANCE(IF(ISBLANK(E30), D30, E30&"":""&D30), ""name""))"),"iShares 20+ Year Treasury Bond ETF") | G30: 미국장기국채 | H30: =IFERROR(__xludf.DUMMYFUNCTION("IF(ISBLANK(D30), 0, GOOGLEFINANCE(IF(ISBLANK(E30), D30, E30&"":""&D30), ""price""))"),82.85) | I30: =IFERROR(__xludf.DUMMYFUNCTION("IF(ISBLANK(D30), 0, GOOGLEFINANCE(IF(ISBLANK(E30), D30, E30&"":""&D30), ""change""))"),-1.39) | J30: =IFERROR(__xludf.DUMMYFUNCTION("IF(ISBLANK(D30), 0, GOOGLEFINANCE(IF(ISBLANK(E30), D30, E30&"":""&D30), ""changepct"")/100)"),-0.0165) | K30: 1 | L30: =K30 * H30 | O30: =(P30*12)+(Q30*4)+(R30*2)+(S30*1) | P30: =(TLT!$F$278-TLT!$F$256)/TLT!$F$256 | Q30: =(TLT!$F$278-TLT!$F$214)/TLT!$F$214 | R30: =(TLT!$F$278-TLT!$F$151)/TLT!$F$151 | S30: =(TLT!$F$278-TLT!$F$28)/TLT!$F$28
D31: TIP | F31: =IFERROR(__xludf.DUMMYFUNCTION("IF(ISBLANK(D31), ""-"", GOOGLEFINANCE(IF(ISBLANK(E31), D31, E31&"":""&D31), ""name""))"),"iShares TIPS Bond ETF") | G31: 미국물가연동채 | H31: =IFERROR(__xludf.DUMMYFUNCTION("IF(ISBLANK(D31), 0, GOOGLEFINANCE(IF(ISBLANK(E31), D31, E31&"":""&D31), ""price""))"),107.77) | I31: =IFERROR(__xludf.DUMMYFUNCTION("IF(ISBLANK(D31), 0, GOOGLEFINANCE(IF(ISBLANK(E31), D31, E31&"":""&D31), ""change""))"),0.11) | J31: =IFERROR(__xludf.DUMMYFUNCTION("IF(ISBLANK(D31), 0, GOOGLEFINANCE(IF(ISBLANK(E31), D31, E31&"":""&D31), ""changepct"")/100)"),0.001) | K31: 1 | L31: =K31 * H31 | O31: =(P31*12)+(Q31*4)+(R31*2)+(S31*1) | P31: =(TIP!$F$278-TIP!$F$256)/TIP!$F$256 | Q31: =(TIP!$F$278-TIP!$F$214)/TIP!$F$214 | R31: =(TIP!$F$278-TIP!$F$151)/TIP!$F$151 | S31: =(TIP!$F$278-TIP!$F$28)/TIP!$F$28
D32: BND | F32: =IFERROR(__xludf.DUMMYFUNCTION("IF(ISBLANK(D32), ""-"", GOOGLEFINANCE(IF(ISBLANK(E32), D32, E32&"":""&D32), ""name""))"),"Vanguard Total Bond Market Index Fund ETF") | G32: 미국잡채권 | H32: =IFERROR(__xludf.DUMMYFUNCTION("IF(ISBLANK(D32), 0, GOOGLEFINANCE(IF(ISBLANK(E32), D32, E32&"":""&D32), ""price""))"),72.38) | I32: =IFERROR(__xludf.DUMMYFUNCTION("IF(ISBLANK(D32), 0, GOOGLEFINANCE(IF(ISBLANK(E32), D32, E32&"":""&D32), ""change""))"),-0.26) | J32: =IFERROR(__xludf.DUMMYFUNCTION("IF(ISBLANK(D32), 0, GOOGLEFINANCE(IF(ISBLANK(E32), D32, E32&"":""&D32), ""changepct"")/100)"),-0.0036) | K32: 1 | L32: =K32 * H32 | O32: =(P32*12)+(Q32*4)+(R32*2)+(S32*1) | P32: =(BND!$F$278-BND!$F$256)/BND!$F$256 | Q32: =(BND!$F$278-BND!$F$214)/BND!$F$214 | R32: =(BND!$F$278-BND!$F$151)/BND!$F$151 | S32: =(BND!$F$278-BND!$F$28)/BND!$F$28
D33: DBC | F33: =IFERROR(__xludf.DUMMYFUNCTION("IF(ISBLANK(D33), ""-"", GOOGLEFINANCE(IF(ISBLANK(E33), D33, E33&"":""&D33), ""name""))"),"Invesco DB Commodity Index Tracking Fund") | G33: 원자재 | H33: =IFERROR(__xludf.DUMMYFUNCTION("IF(ISBLANK(D33), 0, GOOGLEFINANCE(IF(ISBLANK(E33), D33, E33&"":""&D33), ""price""))"),29.42) | I33: =IFERROR(__xludf.DUMMYFUNCTION("IF(ISBLANK(D33), 0, GOOGLEFINANCE(IF(ISBLANK(E33), D33, E33&"":""&D33), ""change""))"),0.82) | J33: =IFERROR(__xludf.DUMMYFUNCTION("IF(ISBLANK(D33), 0, GOOGLEFINANCE(IF(ISBLANK(E33), D33, E33&"":""&D33), ""changepct"")/100)"),0.0287) | K33: 1 | L33: =K33 * H33 | O33: =(P33*12)+(Q33*4)+(R33*2)+(S33*1) | P33: =(DBC!$F$278-DBC!$F$256)/DBC!$F$256 | Q33: =(DBC!$F$278-DBC!$F$214)/DBC!$F$214 | R33: =(DBC!$F$278-DBC!$F$151)/DBC!$F$151 | S33: =(DBC!$F$278-DBC!$F$28)/DBC!$F$28
A36: 변형듀얼모멘텀 | C36: 공격자산 | D36: SPY | F36: =IFERROR(__xludf.DUMMYFUNCTION("IF(ISBLANK(D36), ""-"", GOOGLEFINANCE(IF(ISBLANK(E36), D36, E36&"":""&D36), ""name""))"),"State Street SPDR S&P 500 ETF Trust") | G36: 미국 주식 | H36: =IFERROR(__xludf.DUMMYFUNCTION("IF(ISBLANK(D36), 0, GOOGLEFINANCE(IF(ISBLANK(E36), D36, E36&"":""&D36), ""price""))"),729.46) | I36: =IFERROR(__xludf.DUMMYFUNCTION("IF(ISBLANK(D36), 0, GOOGLEFINANCE(IF(ISBLANK(E36), D36, E36&"":""&D36), ""change""))"),-11.4) | J36: =IFERROR(__xludf.DUMMYFUNCTION("IF(ISBLANK(D36), 0, GOOGLEFINANCE(IF(ISBLANK(E36), D36, E36&"":""&D36), ""changepct"")/100)"),-0.0154) | K36: 1 | L36: =K36 * H36 | O36: =(P36*12)+(Q36*4)+(R36*2)+(S36*1) | P36: =(SPY!$F$278-SPY!$F$256)/SPY!$F$256 | Q36: =(SPY!$F$278-SPY!$F$214)/SPY!$F$214 | R36: =(SPY!$F$278-SPY!$F$151)/SPY!$F$151 | S36: =(SPY!$F$278-SPY!$F$28)/SPY!$F$28 | V36: 둘중 높은자산에 투자 But, 1년 수익이 0 이하면
D37: EFA | F37: =IFERROR(__xludf.DUMMYFUNCTION("IF(ISBLANK(D37), ""-"", GOOGLEFINANCE(IF(ISBLANK(E37), D37, E37&"":""&D37), ""name""))"),"iShares MSCI EAFE ETF") | H37: =IFERROR(__xludf.DUMMYFUNCTION("IF(ISBLANK(D37), 0, GOOGLEFINANCE(IF(ISBLANK(E37), D37, E37&"":""&D37), ""price""))"),103.37) | I37: =IFERROR(__xludf.DUMMYFUNCTION("IF(ISBLANK(D37), 0, GOOGLEFINANCE(IF(ISBLANK(E37), D37, E37&"":""&D37), ""change""))"),-0.52) | J37: =IFERROR(__xludf.DUMMYFUNCTION("IF(ISBLANK(D37), 0, GOOGLEFINANCE(IF(ISBLANK(E37), D37, E37&"":""&D37), ""changepct"")/100)"),-0.005) | K37: 1 | L37: =K37 * H37 | O37: =(P37*12)+(Q37*4)+(R37*2)+(S37*1) | P37: =(EFA!$F$278-EFA!$F$256)/EFA!$F$256 | Q37: =(EFA!$F$278-EFA!$F$214)/EFA!$F$214 | R37: =(EFA!$F$278-EFA!$F$151)/EFA!$F$151 | S37: =(EFA!$F$278-EFA!$F$28)/EFA!$F$28
F38: =IFERROR(__xludf.DUMMYFUNCTION("IF(ISBLANK(D38), ""-"", GOOGLEFINANCE(IF(ISBLANK(E38), D38, E38&"":""&D38), ""name""))"),"-") | H38: =IFERROR(__xludf.DUMMYFUNCTION("IF(ISBLANK(D38), 0, GOOGLEFINANCE(IF(ISBLANK(E38), D38, E38&"":""&D38), ""price""))"),0) | I38: =IFERROR(__xludf.DUMMYFUNCTION("IF(ISBLANK(D38), 0, GOOGLEFINANCE(IF(ISBLANK(E38), D38, E38&"":""&D38), ""change""))"),0) | J38: =IFERROR(__xludf.DUMMYFUNCTION("IF(ISBLANK(D38), 0, GOOGLEFINANCE(IF(ISBLANK(E38), D38, E38&"":""&D38), ""changepct"")/100)"),0) | L38: =K38 * H38 | O38: =(P38*12)+(Q38*4)+(R38*2)+(S38*1) | P38: =(BIL!$F$278-BIL!$F$256)/BIL!$F$256 | Q38: =(BIL!$F$278-BIL!$F$214)/BIL!$F$214 | R38: =(BIL!$F$278-BIL!$F$151)/BIL!$F$151 | S38: =(BIL!$F$278-BIL!$F$28)/BIL!$F$28
C39: 안전자산 8개 채권 | D39: SHY | F39: =IFERROR(__xludf.DUMMYFUNCTION("IF(ISBLANK(D39), ""-"", GOOGLEFINANCE(IF(ISBLANK(E39), D39, E39&"":""&D39), ""name""))"),"iShares 1-3 Year Treasury Bond ETF") | G39: 미국단기국채 | H39: =IFERROR(__xludf.DUMMYFUNCTION("IF(ISBLANK(D39), 0, GOOGLEFINANCE(IF(ISBLANK(E39), D39, E39&"":""&D39), ""price""))"),81.99) | I39: =IFERROR(__xludf.DUMMYFUNCTION("IF(ISBLANK(D39), 0, GOOGLEFINANCE(IF(ISBLANK(E39), D39, E39&"":""&D39), ""change""))"),0.05) | J39: =IFERROR(__xludf.DUMMYFUNCTION("IF(ISBLANK(D39), 0, GOOGLEFINANCE(IF(ISBLANK(E39), D39, E39&"":""&D39), ""changepct"")/100)"),0.0006) | K39: 1 | L39: =K39 * H39 | O39: =(P39*12)+(Q39*4)+(R39*2)+(S39*1) | P39: =(SHY!F$278-SHY!F$256)/SHY!F$256 | Q39: =(SHY!F$278-SHY!F$214)/SHY!F$214 | R39: =(SHY!F$278-SHY!F$151)/SHY!F$151 | S39: =(SHY!F$278-SHY!F$28)/SHY!F$28 | V39: 6개월 최고수익 3개 채권매수 But, 3개 채권중 0이하인 자산은 현금으로 보유
D40: IEF | F40: =IFERROR(__xludf.DUMMYFUNCTION("IF(ISBLANK(D40), ""-"", GOOGLEFINANCE(IF(ISBLANK(E40), D40, E40&"":""&D40), ""name""))"),"iShares 7-10 Year Treasury Bond ETF") | G40: 미국중기국채 | H40: =IFERROR(__xludf.DUMMYFUNCTION("IF(ISBLANK(D40), 0, GOOGLEFINANCE(IF(ISBLANK(E40), D40, E40&"":""&D40), ""price""))"),93.17) | I40: =IFERROR(__xludf.DUMMYFUNCTION("IF(ISBLANK(D40), 0, GOOGLEFINANCE(IF(ISBLANK(E40), D40, E40&"":""&D40), ""change""))"),-0.39) | J40: =IFERROR(__xludf.DUMMYFUNCTION("IF(ISBLANK(D40), 0, GOOGLEFINANCE(IF(ISBLANK(E40), D40, E40&"":""&D40), ""changepct"")/100)"),-0.0042) | K40: 1 | L40: =K40 * H40 | O40: =(P40*12)+(Q40*4)+(R40*2)+(S40*1) | P40: =(IEF!F$278-IEF!F$256)/IEF!F$256 | Q40: =(IEF!F$278-IEF!F$214)/IEF!F$214 | R40: =(IEF!F$278-IEF!F$151)/IEF!F$151 | S40: =(IEF!F$278-IEF!F$28)/IEF!F$28
D41: TLT | F41: =IFERROR(__xludf.DUMMYFUNCTION("IF(ISBLANK(D41), ""-"", GOOGLEFINANCE(IF(ISBLANK(E41), D41, E41&"":""&D41), ""name""))"),"iShares 20+ Year Treasury Bond ETF") | G41: 미국장기국채 | H41: =IFERROR(__xludf.DUMMYFUNCTION("IF(ISBLANK(D41), 0, GOOGLEFINANCE(IF(ISBLANK(E41), D41, E41&"":""&D41), ""price""))"),82.85) | I41: =IFERROR(__xludf.DUMMYFUNCTION("IF(ISBLANK(D41), 0, GOOGLEFINANCE(IF(ISBLANK(E41), D41, E41&"":""&D41), ""change""))"),-1.39) | J41: =IFERROR(__xludf.DUMMYFUNCTION("IF(ISBLANK(D41), 0, GOOGLEFINANCE(IF(ISBLANK(E41), D41, E41&"":""&D41), ""changepct"")/100)"),-0.0165) | K41: 1 | L41: =K41 * H41 | O41: =(P41*12)+(Q41*4)+(R41*2)+(S41*1) | P41: =(TLT!F$278-TLT!F$256)/TLT!F$256 | Q41: =(TLT!F$278-TLT!F$214)/TLT!F$214 | R41: =(TLT!F$278-TLT!F$151)/TLT!F$151 | S41: =(TLT!F$278-TLT!F$28)/TLT!F$28
D42: TIP | F42: =IFERROR(__xludf.DUMMYFUNCTION("IF(ISBLANK(D42), ""-"", GOOGLEFINANCE(IF(ISBLANK(E42), D42, E42&"":""&D42), ""name""))"),"iShares TIPS Bond ETF") | G42: 미국물가연동채 | H42: =IFERROR(__xludf.DUMMYFUNCTION("IF(ISBLANK(D42), 0, GOOGLEFINANCE(IF(ISBLANK(E42), D42, E42&"":""&D42), ""price""))"),107.77) | I42: =IFERROR(__xludf.DUMMYFUNCTION("IF(ISBLANK(D42), 0, GOOGLEFINANCE(IF(ISBLANK(E42), D42, E42&"":""&D42), ""change""))"),0.11) | J42: =IFERROR(__xludf.DUMMYFUNCTION("IF(ISBLANK(D42), 0, GOOGLEFINANCE(IF(ISBLANK(E42), D42, E42&"":""&D42), ""changepct"")/100)"),0.001) | K42: 1 | L42: =K42 * H42 | O42: =(P42*12)+(Q42*4)+(R42*2)+(S42*1) | P42: =(TIP!$F$278-TIP!$F$256)/TIP!$F$256 | Q42: =(TIP!$F$278-TIP!$F$214)/TIP!$F$214 | R42: =(TIP!$F$278-TIP!$F$151)/TIP!$F$151 | S42: =(TIP!$F$278-TIP!$F$28)/TIP!$F$28
D43: LQD | F43: =IFERROR(__xludf.DUMMYFUNCTION("IF(ISBLANK(D43), ""-"", GOOGLEFINANCE(IF(ISBLANK(E43), D43, E43&"":""&D43), ""name""))"),"iShares iBoxx $ Inv Grade Corporate Bond ETF") | G43: 미국회사채 | H43: =IFERROR(__xludf.DUMMYFUNCTION("IF(ISBLANK(D43), 0, GOOGLEFINANCE(IF(ISBLANK(E43), D43, E43&"":""&D43), ""price""))"),106.22) | I43: =IFERROR(__xludf.DUMMYFUNCTION("IF(ISBLANK(D43), 0, GOOGLEFINANCE(IF(ISBLANK(E43), D43, E43&"":""&D43), ""change""))"),-0.61) | J43: =IFERROR(__xludf.DUMMYFUNCTION("IF(ISBLANK(D43), 0, GOOGLEFINANCE(IF(ISBLANK(E43), D43, E43&"":""&D43), ""changepct"")/100)"),-0.00569999999999999) | K43: 1 | L43: =K43 * H43 | O43: =(P43*12)+(Q43*4)+(R43*2)+(S43*1) | P43: =(LQD!F278-LQD!F256)/LQD!F256 | Q43: =(LQD!F$278-LQD!F$214)/LQD!F$214 | R43: =(LQD!F$278-LQD!F$151)/LQD!F$151 | S43: =(LQD!F$278-LQD!F$28)/LQD!F$28
...

Sheet 이벤트 관리
A1: 구분 | B1: 주기 | C1: 날짜 | D1: 시간 | E1: 시장/국가 | F1: 관련 Ticker | G1: 이벤트명 | H1: 중요도 | I1: 상태 | J1: 메모 | K1: 자료 링크 | M1: 사용 방법
A2: 시장 | B2: Weekly | C2: =TODAY()-WEEKDAY(TODAY(),2)+1 | D2: 09:00 | E2: US | F2: SPY | G2: 주간 시장 점검 | H2: 중간 | I2: 예정 | J2: 주요 지수/금리/환율 확인 | M2: 주기: Weekly 또는 Monthly로 입력
A3: 실적 | B3: Weekly | C3: =TODAY()-WEEKDAY(TODAY(),2)+4 | E3: US | F3: QQQ | G3: 주요 기술주 실적 체크 | H3: 높음 | I3: 예정 | J3: 보유/관심 종목 중심 | M3: 관련 Ticker: 관심종목 D열 코드와 맞추면 추적이 쉽습니다.
A4: 매크로 | B4: Monthly | C4: =EOMONTH(TODAY(),-1)+1 | E4: US | G4: 월간 경제지표 캘린더 업데이트 | H4: 높음 | I4: 예정 | J4: CPI/FOMC/고용/PMI 일정 관리 | M4: 상태: 예정/완료/보류 등으로 관리
A5: 포트폴리오 | B5: Monthly | C5: =EOMONTH(TODAY(),0) | E5: Global | G5: 월말 리밸런싱 검토 | H5: 높음 | I5: 예정 | J5: 목표비중/모멘텀/현금비중 확인

Sheet BD
B1: 현재가 | C1: =TODAY()-1 | D1: =EDATE($C$1,-1) | E1: =EDATE($C$1,-2) | F1: =EDATE($C$1,-3) | G1: =EDATE($C$1,-4) | H1: =EDATE($C$1,-5) | I1: =EDATE($C$1,-6) | J1: =EDATE($C$1,-7) | K1: =EDATE($C$1,-8) | L1: =EDATE($C$1,-9) | M1: =EDATE($C$1,-10) | N1: =EDATE($C$1,-11) | O1: =TODAY()-362
A3: ㅣBAA중도형_공격자산 12종목
A4: 구간 | B4: 현재 | C4: 전 날 | D4: 1개월 전 | E4: 2개월 전 | F4: 3개월 전 | G4: 4개월 전 | H4: 5개월 전 | I4: 6개월 전 | J4: 7개월 전 | K4: 8개월 전 | L4: 9개월 전 | M4: 10개월 전 | N4: 11개월 전 | O4: 12개월 전 | P4: 12개월 이동평균 | Q4: 현재가격/12개월 이동평균 | R4: 1개월 수익률 | S4: 3개월 수익률 | T4: 6개월 수익률 | U4: 최근 1년 수익률 | V4: 1개월 수익률*12 | W4: 3개월 수익률*4 | X4: 6개월 수익률*2 | Y4: 12개월 수익률*1 | Z4: 모멘텀 스코어
A5: =관심종목!D10 | B5: =관심종목!H10 | C5: =VLOOKUP(C1,SPY!$B$27:$G$278,5,1) | D5: =VLOOKUP(D1,SPY!$B$27:$G$278,5,1) | E5: =VLOOKUP(E1,SPY!$B$27:$G$278,5,1) | F5: =VLOOKUP(F1,SPY!$B$27:$G$278,5,1) | G5: =VLOOKUP(G1,SPY!$B$27:$G$278,5,1) | H5: =VLOOKUP(H1,SPY!$B$27:$G$278,5,1) | I5: =VLOOKUP(I1,SPY!$B$27:$G$278,5,1) | J5: =VLOOKUP(J1,SPY!$B$27:$G$278,5,1) | ... O5: =VLOOKUP(O1,SPY!$B$27:$G$278,5,1) | P5: =AVERAGE(D5:O5) | Q5: =B5/P5 | R5: =(B5/D5)-1 | S5: =(B5/F5)-1 | T5: =(B5/I5)-1 | U5: =(B5/O5)-1 | V5: =R5*12 | W5: =S5*4 | X5: =T5*2 | Y5: =U5*1 | Z5: =SUM(V5:Y5)
A6: =관심종목!D11 | B6: =관심종목!H11 | C6: =VLOOKUP(C1,QQQ!$B$27:$G$278,5,1) | D6: =VLOOKUP(D1,QQQ!$B$27:$G$278,5,1) | E6: =VLOOKUP(E1,QQQ!$B$27:$G$278,5,1) | F6: =VLOOKUP(F1,QQQ!$B$27:$G$278,5,1) | G6: =VLOOKUP(G1,QQQ!$B$27:$G$278,5,1) | H6: =VLOOKUP(H1,QQQ!$B$27:$G$278,5,1) | I6: =VLOOKUP(I1,QQQ!$B$27:$G$278,5,1) | J6: =VLOOKUP(J1,QQQ!$B$27:$G$278,5,1) | ... O6: =VLOOKUP(O1,QQQ!$B$27:$G$278,5,1) | P6: =AVERAGE(D6:O6) | Q6: =B6/P6 | R6: =(B6/D6)-1 | S6: =(B6/F6)-1 | T6: =(B6/I6)-1 | U6: =(B6/O6)-1 | V6: =R6*12 | W6: =S6*4 | X6: =T6*2 | Y6: =U6*1 | Z6: =SUM(V6:Y6)
A7: =관심종목!D12 | B7: =관심종목!H12 | C7: =VLOOKUP(C1,IWM!$B$27:$G$278,5,1) | D7: =VLOOKUP(D1,IWM!$B$27:$G$278,5,1) | E7: =VLOOKUP(E1,IWM!$B$27:$G$278,5,1) | F7: =VLOOKUP(F1,IWM!$B$27:$G$278,5,1) | G7: =VLOOKUP(G1,IWM!$B$27:$G$278,5,1) | H7: =VLOOKUP(H1,IWM!$B$27:$G$278,5,1) | I7: =VLOOKUP(I1,IWM!$B$27:$G$278,5,1) | J7: =VLOOKUP(J1,IWM!$B$27:$G$278,5,1) | ... O7: =VLOOKUP(O1,IWM!$B$27:$G$278,5,1) | P7: =AVERAGE(D7:O7) | Q7: =B7/P7 | R7: =(B7/D7)-1 | S7: =(B7/F7)-1 | T7: =(B7/I7)-1 | U7: =(B7/O7)-1 | V7: =R7*12 | W7: =S7*4 | X7: =T7*2 | Y7: =U7*1 | Z7: =SUM(V7:Y7)
A8: =관심종목!D13 | B8: =관심종목!H13 | C8: =VLOOKUP(C1,VGK!$B$27:$G$278,5,1) | D8: =VLOOKUP(D1,VGK!$B$27:$G$278,5,1) | E8: =VLOOKUP(E1,VGK!$B$27:$G$278,5,1) | F8: =VLOOKUP(F1,VGK!$B$27:$G$278,5,1) | G8: =VLOOKUP(G1,VGK!$B$27:$G$278,5,1) | H8: =VLOOKUP(H1,VGK!$B$27:$G$278,5,1) | I8: =VLOOKUP(I1,VGK!$B$27:$G$278,5,1) | J8: =VLOOKUP(J1,VGK!$B$27:$G$278,5,1) | ... O8: =VLOOKUP(O1,VGK!$B$27:$G$278,5,1) | P8: =AVERAGE(D8:O8) | Q8: =B8/P8 | R8: =(B8/D8)-1 | S8: =(B8/F8)-1 | T8: =(B8/I8)-1 | U8: =(B8/O8)-1 | V8: =R8*12 | W8: =S8*4 | X8: =T8*2 | Y8: =U8*1 | Z8: =SUM(V8:Y8)
A9: =관심종목!D14 | B9: =관심종목!H14 | C9: =VLOOKUP(C1,EWJ!$B$27:$G$278,5,1) | D9: =VLOOKUP(D1,EWJ!$B$27:$G$278,5,1) | E9: =VLOOKUP(E1,EWJ!$B$27:$G$278,5,1) | F9: =VLOOKUP(F1,EWJ!$B$27:$G$278,5,1) | G9: =VLOOKUP(G1,EWJ!$B$27:$G$278,5,1) | H9: =VLOOKUP(H1,EWJ!$B$27:$G$278,5,1) | I9: =VLOOKUP(I1,EWJ!$B$27:$G$278,5,1) | J9: =VLOOKUP(J1,EWJ!$B$27:$G$278,5,1) | ... O9: =VLOOKUP(O1,EWJ!$B$27:$G$278,5,1) | P9: =AVERAGE(D9:O9) | Q9: =B9/P9 | R9: =(B9/D9)-1 | S9: =(B9/F9)-1 | T9: =(B9/I9)-1 | U9: =(B9/O9)-1 | V9: =R9*12 | W9: =S9*4 | X9: =T9*2 | Y9: =U9*1 | Z9: =SUM(V9:Y9)
A10: =관심종목!D15 | B10: =관심종목!H15 | C10: =VLOOKUP(C1,VWO!$B$27:$G$278,5,1) | D10: =VLOOKUP(D1,VWO!$B$27:$G$278,5,1) | E10: =VLOOKUP(E1,VWO!$B$27:$G$278,5,1) | F10: =VLOOKUP(F1,VWO!$B$27:$G$278,5,1) | G10: =VLOOKUP(G1,VWO!$B$27:$G$278,5,1) | H10: =VLOOKUP(H1,VWO!$B$27:$G$278,5,1) | I10: =VLOOKUP(I1,VWO!$B$27:$G$278,5,1) | J10: =VLOOKUP(J1,VWO!$B$27:$G$278,5,1) | ... O10: =VLOOKUP(O1,VWO!$B$27:$G$278,5,1) | P10: =AVERAGE(D10:O10) | Q10: =B10/P10 | R10: =(B10/D10)-1 | S10: =(B10/F10)-1 | T10: =(B10/I10)-1 | U10: =(B10/O10)-1 | V10: =R10*12 | W10: =S10*4 | X10: =T10*2 | Y10: =U10*1 | Z10: =SUM(V10:Y10)
A11: =관심종목!D16 | B11: =관심종목!H16 | C11: =VLOOKUP(C1,VEA!$B$27:$G$278,5,1) | D11: =VLOOKUP(D1,VEA!$B$27:$G$278,5,1) | E11: =VLOOKUP(E1,VEA!$B$27:$G$278,5,1) | F11: =VLOOKUP(F1,VEA!$B$27:$G$278,5,1) | G11: =VLOOKUP(G1,VEA!$B$27:$G$278,5,1) | H11: =VLOOKUP(H1,VEA!$B$27:$G$278,5,1) | I11: =VLOOKUP(I1,VEA!$B$27:$G$278,5,1) | J11: =VLOOKUP(J1,VEA!$B$27:$G$278,5,1) | ... O11: =VLOOKUP(O1,VEA!$B$27:$G$278,5,1) | P11: =AVERAGE(D11:O11) | Q11: =B11/P11 | R11: =(B11/D11)-1 | S11: =(B11/F11)-1 | T11: =(B11/I11)-1 | U11: =(B11/O11)-1 | V11: =R11*12 | W11: =S11*4 | X11: =T11*2 | Y11: =U11*1 | Z11: =SUM(V11:Y11)
A12: =관심종목!D17 | B12: =관심종목!H17 | C12: =VLOOKUP(C1,VNQ!$B$27:$G$278,5,1) | D12: =VLOOKUP(D1,VNQ!$B$27:$G$278,5,1) | E12: =VLOOKUP(E1,VNQ!$B$27:$G$278,5,1) | F12: =VLOOKUP(F1,VNQ!$B$27:$G$278,5,1) | G12: =VLOOKUP(G1,VNQ!$B$27:$G$278,5,1) | H12: =VLOOKUP(H1,VNQ!$B$27:$G$278,5,1) | I12: =VLOOKUP(I1,VNQ!$B$27:$G$278,5,1) | J12: =VLOOKUP(J1,VNQ!$B$27:$G$278,5,1) | ... O12: =VLOOKUP(O1,VNQ!$B$27:$G$278,5,1) | P12: =AVERAGE(D12:O12) | Q12: =B12/P12 | R12: =(B12/D12)-1 | S12: =(B12/F12)-1 | T12: =(B12/I12)-1 | U12: =(B12/O12)-1 | V12: =R12*12 | W12: =S12*4 | X12: =T12*2 | Y12: =U12*1 | Z12: =SUM(V12:Y12)
A13: =관심종목!D18 | B13: =관심종목!H18 | C13: =VLOOKUP(C1,DBC!$B$27:$G$278,5,1) | D13: =VLOOKUP(D1,DBC!$B$27:$G$278,5,1) | E13: =VLOOKUP(E1,DBC!$B$27:$G$278,5,1) | F13: =VLOOKUP(F1,DBC!$B$27:$G$278,5,1) | G13: =VLOOKUP(G1,DBC!$B$27:$G$278,5,1) | H13: =VLOOKUP(H1,DBC!$B$27:$G$278,5,1) | I13: =VLOOKUP(I1,DBC!$B$27:$G$278,5,1) | J13: =VLOOKUP(J1,DBC!$B$27:$G$278,5,1) | ... O13: =VLOOKUP(O1,DBC!$B$27:$G$278,5,1) | P13: =AVERAGE(D13:O13) | Q13: =B13/P13 | R13: =(B13/D13)-1 | S13: =(B13/F13)-1 | T13: =(B13/I13)-1 | U13: =(B13/O13)-1 | V13: =R13*12 | W13: =S13*4 | X13: =T13*2 | Y13: =U13*1 | Z13: =SUM(V13:Y13)
A14: =관심종목!D19 | B14: =관심종목!H19 | C14: =VLOOKUP(C1,GLD!$B$27:$G$278,5,1) | D14: =VLOOKUP(D1,GLD!$B$27:$G$278,5,1) | E14: =VLOOKUP(E1,GLD!$B$27:$G$278,5,1) | F14: =VLOOKUP(F1,GLD!$B$27:$G$278,5,1) | G14: =VLOOKUP(G1,GLD!$B$27:$G$278,5,1) | H14: =VLOOKUP(H1,GLD!$B$27:$G$278,5,1) | I14: =VLOOKUP(I1,GLD!$B$27:$G$278,5,1) | J14: =VLOOKUP(J1,GLD!$B$27:$G$278,5,1) | ... O14: =VLOOKUP(O1,GLD!$B$27:$G$278,5,1) | P14: =AVERAGE(D14:O14) | Q14: =B14/P14 | R14: =(B14/D14)-1 | S14: =(B14/F14)-1 | T14: =(B14/I14)-1 | U14: =(B14/O14)-1 | V14: =R14*12 | W14: =S14*4 | X14: =T14*2 | Y14: =U14*1 | Z14: =SUM(V14:Y14)
A15: =관심종목!D20 | B15: =관심종목!H20 | C15: =VLOOKUP(C1,LQD!$B$27:$G$278,5,1) | D15: =VLOOKUP(D1,LQD!$B$27:$G$278,5,1) | E15: =VLOOKUP(E1,LQD!$B$27:$G$278,5,1) | F15: =VLOOKUP(F1,LQD!$B$27:$G$278,5,1) | G15: =VLOOKUP(G1,LQD!$B$27:$G$278,5,1) | H15: =VLOOKUP(H1,LQD!$B$27:$G$278,5,1) | I15: =VLOOKUP(I1,LQD!$B$27:$G$278,5,1) | J15: =VLOOKUP(J1,LQD!$B$27:$G$278,5,1) | ... O15: =VLOOKUP(O1,LQD!$B$27:$G$278,5,1) | P15: =AVERAGE(D15:O15) | Q15: =B15/P15 | R15: =(B15/D15)-1 | S15: =(B15/F15)-1 | T15: =(B15/I15)-1 | U15: =(B15/O15)-1 | V15: =R15*12 | W15: =S15*4 | X15: =T15*2 | Y15: =U15*1 | Z15: =SUM(V15:Y15)
A16: =관심종목!D21 | B16: =관심종목!H21 | C16: =VLOOKUP(C1,HYG!$B$27:$G$278,5,1) | D16: =VLOOKUP(D1,HYG!$B$27:$G$278,5,1) | E16: =VLOOKUP(E1,HYG!$B$27:$G$278,5,1) | F16: =VLOOKUP(F1,HYG!$B$27:$G$278,5,1) | G16: =VLOOKUP(G1,HYG!$B$27:$G$278,5,1) | H16: =VLOOKUP(H1,HYG!$B$27:$G$278,5,1) | I16: =VLOOKUP(I1,HYG!$B$27:$G$278,5,1) | J16: =VLOOKUP(J1,HYG!$B$27:$G$278,5,1) | ... O16: =VLOOKUP(O1,HYG!$B$27:$G$278,5,1) | P16: =AVERAGE(D16:O16) | Q16: =B16/P16 | R16: =(B16/D16)-1 | S16: =(B16/F16)-1 | T16: =(B16/I16)-1 | U16: =(B16/O16)-1 | V16: =R16*12 | W16: =S16*4 | X16: =T16*2 | Y16: =U16*1 | Z16: =SUM(V16:Y16)
A17: ㅣBAA중도형_안전자산
A18: 구간 | B18: 현재 | C18: 전 날 | D18: 1개월 전 | E18: 2개월 전 | F18: 3개월 전 | G18: 4개월 전 | H18: 5개월 전 | I18: 6개월 전 | J18: 7개월 전 | K18: 8개월 전 | L18: 9개월 전 | M18: 10개월 전 | N18: 11개월 전 | O18: 12개월 전 | P18: 12개월 이동평균 | Q18: 현재가격/12개월 이동평균 | R18: 1개월 수익률 | S18: 3개월 수익률 | T18: 6개월 수익률 | U18: 최근 1년 수익률 | V18: 1개월 수익률*12 | W18: 3개월 수익률*4 | X18: 6개월 수익률*2 | Y18: 12개월 수익률*1 | Z18: 모멘텀 스코어
A19: =관심종목!D27 | B19: =관심종목!H27 | C19: =VLOOKUP(C1,LQD!$B$27:$G$278,5,1) | D19: =VLOOKUP($D$1,LQD!$B$27:$G$278,5,1) | E19: =VLOOKUP(E1,LQD!$B$27:$G$278,5,1) | F19: =VLOOKUP(F1,LQD!$B$27:$G$278,5,1) | G19: =VLOOKUP(G1,LQD!$B$27:$G$278,5,1) | H19: =VLOOKUP(H1,LQD!$B$27:$G$278,5,1) | I19: =VLOOKUP(I1,LQD!$B$27:$G$278,5,1) | J19: =VLOOKUP(J1,LQD!$B$27:$G$278,5,1) | K19: =VLOOKUP(K1,LQD!$B$27:$G$278,5,1) | L19: =VLOOKUP(L1,LQD!$B$27:$G$278,5,1) | ... O19: =VLOOKUP(O1,LQD!$B$27:$G$278,5,1) | P19: =AVERAGE(D19:O19) | Q19: =B19/P19 | R19: =(B19/D19)-1 | S19: =(B19/F19)-1 | T19: =(B19/I19)-1 | U19: =(B19/O19)-1 | V19: =R19*12 | W19: =S19*12 | X19: =T19*2 | Y19: =U19*1 | Z19: =SUM(V19:Y19)
A20: =관심종목!D28 | B20: =관심종목!H28 | C20: =VLOOKUP(C1,IEF!$B$27:$G$278,5,1) | D20: =VLOOKUP(D1,IEF!$B$27:$G$278,5,1) | E20: =VLOOKUP(E1,IEF!$B$27:$G$278,5,1) | F20: =VLOOKUP(F1,IEF!$B$27:$G$278,5,1) | G20: =VLOOKUP(G1,IEF!$B$27:$G$278,5,1) | H20: =VLOOKUP(H1,IEF!$B$27:$G$278,5,1) | I20: =VLOOKUP(I1,IEF!$B$27:$G$278,5,1) | J20: =VLOOKUP(J1,IEF!$B$27:$G$278,5,1) | ... O20: =VLOOKUP(O1,IEF!$B$27:$G$278,5,1) | P20: =AVERAGE(A20:N20) | Q20: =B20/P20 | R20: =(B20/D20)-1 | S20: =(B20/F20)-1 | T20: =(B20/I20)-1 | U20: =(B20/O20)-1 | V20: =R20*12 | W20: =S20*4 | X20: =T20*2 | Y20: =U20*1 | Z20: =SUM(V20:Y20)
A21: =관심종목!D29 | B21: =관심종목!H29 | C21: =VLOOKUP(C1,BIL!$B$27:$G$278,5,1) | D21: =VLOOKUP(D1,BIL!$B$27:$G$278,5,1) | E21: =VLOOKUP(E1,BIL!$B$27:$G$278,5,1) | F21: =VLOOKUP(F1,BIL!$B$27:$G$278,5,1) | G21: =VLOOKUP(G1,BIL!$B$27:$G$278,5,1) | H21: =VLOOKUP(H1,BIL!$B$27:$G$278,5,1) | I21: =VLOOKUP(I1,BIL!$B$27:$G$278,5,1) | J21: =VLOOKUP(J1,BIL!$B$27:$G$278,5,1) | ... O21: =VLOOKUP(O1,BIL!$B$27:$G$278,5,1) | P21: =AVERAGE(A21:N21) | Q21: =B21/P21 | R21: =(B21/D21)-1 | S21: =(B21/F21)-1 | T21: =(B21/I21)-1 | U21: =(B21/O21)-1 | V21: =R21*12 | W21: =S21*4 | X21: =T21*2 | Y21: =U21*1 | Z21: =SUM(V21:Y21)
A22: =관심종목!D30 | B22: =관심종목!H30 | C22: =VLOOKUP(C1,TLT!$B$27:$G$278,5,1) | D22: =VLOOKUP(D1,TLT!$B$27:$G$278,5,1) | E22: =VLOOKUP(E1,TLT!$B$27:$G$278,5,1) | F22: =VLOOKUP(F1,TLT!$B$27:$G$278,5,1) | G22: =VLOOKUP(G1,TLT!$B$27:$G$278,5,1) | H22: =VLOOKUP(H1,TLT!$B$27:$G$278,5,1) | I22: =VLOOKUP(I1,TLT!$B$27:$G$278,5,1) | J22: =VLOOKUP(J1,TLT!$B$27:$G$278,5,1) | ... O22: =VLOOKUP(O1,TLT!$B$27:$G$278,5,1) | P22: =AVERAGE(A22:N22) | Q22: =B22/P22 | R22: =(B22/D22)-1 | S22: =(B22/F22)-1 | T22: =(B22/I22)-1 | U22: =(B22/O22)-1 | V22: =R22*12 | W22: =S22*4 | X22: =T22*2 | Y22: =U22*1 | Z22: =SUM(V22:Y22)
A23: =관심종목!D31 | B23: =관심종목!H31 | C23: =VLOOKUP(C1,TIP!$B$27:$G$278,5,1) | D23: =VLOOKUP(D1,TIP!$B$27:$G$278,5,1) | E23: =VLOOKUP(E1,TIP!$B$27:$G$278,5,1) | F23: =VLOOKUP(F1,TIP!$B$27:$G$278,5,1) | G23: =VLOOKUP(G1,TIP!$B$27:$G$278,5,1) | H23: =VLOOKUP(H1,TIP!$B$27:$G$278,5,1) | I23: =VLOOKUP(I1,TIP!$B$27:$G$278,5,1) | J23: =VLOOKUP(J1,TIP!$B$27:$G$278,5,1) | ... O23: =VLOOKUP(O1,TIP!$B$27:$G$278,5,1) | P23: =AVERAGE(A23:N23) | Q23: =B23/P23 | R23: =(B23/D23)-1 | S23: =(B23/F23)-1 | T23: =(B23/I23)-1 | U23: =(B23/O23)-1 | V23: =R23*12 | W23: =S23*4 | X23: =T23*2 | Y23: =U23*1 | Z23: =SUM(V23:Y23)
A24: =관심종목!D32 | B24: =관심종목!H32 | C24: =VLOOKUP(C1,BND!$B$27:$G$278,5,1) | D24: =VLOOKUP(D1,BND!$B$27:$G$278,5,1) | E24: =VLOOKUP(E1,BND!$B$27:$G$278,5,1) | F24: =VLOOKUP(F1,BND!$B$27:$G$278,5,1) | G24: =VLOOKUP(G1,BND!$B$27:$G$278,5,1) | H24: =VLOOKUP(H1,BND!$B$27:$G$278,5,1) | I24: =VLOOKUP(I1,BND!$B$27:$G$278,5,1) | J24: =VLOOKUP(J1,BND!$B$27:$G$278,5,1) | ... O24: =VLOOKUP(O1,BND!$B$27:$G$278,5,1) | P24: =AVERAGE(A24:N24) | Q24: =B24/P24 | R24: =(B24/D24)-1 | S24: =(B24/F24)-1 | T24: =(B24/I24)-1 | U24: =(B24/O24)-1 | V24: =R24*12 | W24: =S24*4 | X24: =T24*2 | Y24: =U24*1 | Z24: =SUM(V24:Y24)
A25: =관심종목!D33 | B25: =관심종목!H33 | C25: =VLOOKUP(C1,DBC!$B$27:$G$278,5,1) | D25: =VLOOKUP(D1,DBC!$B$27:$G$278,5,1) | E25: =VLOOKUP(E1,DBC!$B$27:$G$278,5,1) | F25: =VLOOKUP(F1,DBC!$B$27:$G$278,5,1) | G25: =VLOOKUP(G1,DBC!$B$27:$G$278,5,1) | H25: =VLOOKUP(H1,DBC!$B$27:$G$278,5,1) | I25: =VLOOKUP(I1,DBC!$B$27:$G$278,5,1) | J25: =VLOOKUP(J1,DBC!$B$27:$G$278,5,1) | ... O25: =VLOOKUP(O1,DBC!$B$27:$G$278,5,1) | P25: =AVERAGE(A25:N25) | Q25: =B25/P25 | R25: =(B25/D25)-1 | S25: =(B25/F25)-1 | T25: =(B25/I25)-1 | U25: =(B25/O25)-1 | V25: =R25*12 | W25: =S25*4 | X25: =T25*2 | Y25: =U25*1 | Z25: =SUM(V25:Y25)
A27: ㅣ카나리아 자산군
B28: 현재 | C28: 전 날 | D28: 1개월 전 | E28: 2개월 전 | F28: 3개월 전 | G28: 4개월 전 | H28: 5개월 전 | I28: 6개월 전 | J28: 7개월 전 | K28: 8개월 전 | L28: 9개월 전 | M28: 10개월 전 | N28: 11개월 전 | O28: 12개월 전 | P28: 12개월 이동평균 | Q28: 현재가격/12개월 이동평균 | R28: 1개월 수익률 | S28: 3개월 수익률 | T28: 6개월 수익률 | U28: 최근 1년 수익률 | V28: 1개월 수익률*12 | W28: 3개월 수익률*4 | X28: 6개월 수익률*2 | Y28: 12개월 수익률*1 | Z28: 모멘텀 스코어
A29: SPY | B29: =관심종목!H22 | C29: =VLOOKUP(C1,SPY!$B$27:$G$278,5,1) | D29: =VLOOKUP(D1,SPY!$B$27:$G$278,5,1) | E29: =VLOOKUP(E1,SPY!$B$27:$G$278,5,1) | F29: =VLOOKUP(F1,SPY!$B$27:$G$278,5,1) | G29: =VLOOKUP(G1,SPY!$B$27:$G$278,5,1) | H29: =VLOOKUP(H1,SPY!$B$27:$G$278,5,1) | I29: =VLOOKUP(I1,SPY!$B$27:$G$278,5,1) | J29: =VLOOKUP(J1,SPY!$B$27:$G$278,5,1) | ... O29: =VLOOKUP(O1,SPY!$B$27:$G$278,5,1) | P29: =AVERAGE(D29:O29) | Q29: =B29/P29 | R29: =(B29/D29)-1 | S29: =(B29/F29)-1 | T29: =(B29/I29)-1 | U29: =(B29/O29)-1 | V29: =R29*12 | W29: =S29*12 | X29: =T29*2 | Y29: =U29*1 | Z29: =SUM(V29:Y29)
A30: EFA | B30: =관심종목!H23 | C30: =VLOOKUP(C1,EFA!$B$27:$G$278,5,1) | D30: =VLOOKUP(D1,EFA!$B$27:$G$278,5,1) | E30: =VLOOKUP(E1,EFA!$B$27:$G$278,5,1) | F30: =VLOOKUP(F1,EFA!$B$27:$G$278,5,1) | G30: =VLOOKUP(G1,EFA!$B$27:$G$278,5,1) | H30: =VLOOKUP(H1,EFA!$B$27:$G$278,5,1) | I30: =VLOOKUP(I1,EFA!$B$27:$G$278,5,1) | J30: =VLOOKUP(J1,EFA!$B$27:$G$278,5,1) | ... O30: =VLOOKUP(O1,EFA!$B$27:$G$278,5,1) | P30: =AVERAGE(D30:O30) | Q30: =B30/P30 | R30: =(B30/D30)-1 | S30: =(B30/F30)-1 | T30: =(B30/I30)-1 | U30: =(B30/O30)-1 | V30: =R30*12 | W30: =S30*12 | X30: =T30*2 | Y30: =U30*1 | Z30: =SUM(V30:Y30)
A31: EEM | B31: =관심종목!H24 | C31: =VLOOKUP(C1,EEM!$B$27:$G$278,5,1) | D31: =VLOOKUP(D1,EEM!$B$27:$G$278,5,1) | E31: =VLOOKUP(E1,EEM!$B$27:$G$278,5,1) | F31: =VLOOKUP(F1,EEM!$B$27:$G$278,5,1) | G31: =VLOOKUP(G1,EEM!$B$27:$G$278,5,1) | H31: =VLOOKUP(H1,EEM!$B$27:$G$278,5,1) | I31: =VLOOKUP(I1,EEM!$B$27:$G$278,5,1) | J31: =VLOOKUP(J1,EEM!$B$27:$G$278,5,1) | ... O31: =VLOOKUP(O1,EEM!$B$27:$G$278,5,1) | P31: =AVERAGE(D31:O31) | Q31: =B31/P31 | R31: =(B31/D31)-1 | S31: =(B31/F31)-1 | T31: =(B31/I31)-1 | U31: =(B31/O31)-1 | V31: =R31*12 | W31: =S31*12 | X31: =T31*2 | Y31: =U31*1 | Z31: =SUM(V31:Y31)
A32: AGG | B32: =관심종목!H25 | C32: =VLOOKUP(C1,AGG!$B$27:$G$278,5,1) | D32: =VLOOKUP(D1,AGG!$B$27:$G$278,5,1) | E32: =VLOOKUP(E1,AGG!$B$27:$G$278,5,1) | F32: =VLOOKUP(F1,AGG!$B$27:$G$278,5,1) | G32: =VLOOKUP(G1,AGG!$B$27:$G$278,5,1) | H32: =VLOOKUP(H1,AGG!$B$27:$G$278,5,1) | I32: =VLOOKUP(I1,AGG!$B$27:$G$278,5,1) | J32: =VLOOKUP(J1,AGG!$B$27:$G$278,5,1) | ... O32: =VLOOKUP(O1,AGG!$B$27:$G$278,5,1) | P32: =AVERAGE(D32:O32) | Q32: =B32/P32 | R32: =(B32/D32)-1 | S32: =(B32/F32)-1 | T32: =(B32/I32)-1 | U32: =(B32/O32)-1 | V32: =R32*12 | W32: =S32*12 | X32: =T32*2 | Y32: =U32*1 | Z32: =SUM(V32:Y32)
A33: QQQ | B33: =관심종목!H26 | C33: =VLOOKUP(C1,QQQ!$B$27:$G$278,5,1) | D33: =VLOOKUP(D1,QQQ!$B$27:$G$278,5,1) | E33: =VLOOKUP(E1,QQQ!$B$27:$G$278,5,1) | F33: =VLOOKUP(F1,QQQ!$B$27:$G$278,5,1) | G33: =VLOOKUP(G1,QQQ!$B$27:$G$278,5,1) | H33: =VLOOKUP(H1,QQQ!$B$27:$G$278,5,1) | I33: =VLOOKUP(I1,QQQ!$B$27:$G$278,5,1) | J33: =VLOOKUP(J1,QQQ!$B$27:$G$278,5,1) | ... O33: =VLOOKUP(O1,QQQ!$B$27:$G$278,5,1) | P33: =AVERAGE(D33:O33) | Q33: =B33/P33 | R33: =(B33/D33)-1 | S33: =(B33/F33)-1 | T33: =(B33/I33)-1 | U33: =(B33/O33)-1 | V33: =R33*12 | W33: =S33*4 | X33: =T33*2 | Y33: =U33*1 | Z33: =SUM(V33:Y33)
A35: ㅣ변형듀얼모멘텀_공격자산
B36: =U28
A37: SPY | B37: =U29
A38: EFA | B38: =U30
A40: ㅣ변형듀얼모멘텀_안전자산
B41: 현재 | C41: 전 날 | D41: 1개월 전 | E41: 2개월 전 | F41: 3개월 전 | G41: 4개월 전 | H41: 5개월 전 | I41: 6개월 전 | J41: 7개월 전 | K41: 8개월 전 | L41: 9개월 전 | M41: 10개월 전 | N41: 11개월 전 | O41: 12개월 전 | P41: 12개월 이동평균 | Q41: 현재가격/12개월 이동평균 | R41: 1개월 수익률 | S41: 3개월 수익률 | T41: 6개월 수익률 | U41: 최근 1년 수익률 | V41: 1개월 수익률*12 | W41: 3개월 수익률*4 | X41: 6개월 수익률*2 | Y41: 12개월 수익률*1 | Z41: 모멘텀 스코어
A42: =관심종목!D39 | B42: =관심종목!H39 | C42: =VLOOKUP(C1,SHY!$B$27:$G$278,5,1) | D42: =VLOOKUP(D1,SHY!$B$27:$G$278,5,1) | E42: =VLOOKUP(E1,SHY!$B$27:$G$278,5,1) | F42: =VLOOKUP(F1,SHY!$B$27:$G$278,5,1) | G42: =VLOOKUP(G1,SHY!$B$27:$G$278,5,1) | H42: =VLOOKUP(H1,SHY!$B$27:$G$278,5,1) | I42: =VLOOKUP(I1,SHY!$B$27:$G$278,5,1) | J42: =VLOOKUP(J1,SHY!$B$27:$G$278,5,1) | ... O42: =VLOOKUP(O1,SHY!$B$27:$G$278,5,1) | P42: =AVERAGE(D42:O42) | Q42: =B42/P42 | R42: =(B42/D42)-1 | S42: =(B42/F42)-1 | T42: =(B42/I42)-1 | U42: =(B42/O42)-1 | V42: =R42*12 | W42: =S42*4 | X42: =T42*2 | Y42: =U42*1 | Z42: =SUM(V42:Y42)
A43: =관심종목!D40 | B43: =관심종목!H40 | C43: =VLOOKUP(C1,IEF!$B$27:$G$278,5,1) | D43: =VLOOKUP(D1,IEF!$B$27:$G$278,5,1) | E43: =VLOOKUP(E1,IEF!$B$27:$G$278,5,1) | F43: =VLOOKUP(F1,IEF!$B$27:$G$278,5,1) | G43: =VLOOKUP(G1,IEF!$B$27:$G$278,5,1) | H43: =VLOOKUP(H1,IEF!$B$27:$G$278,5,1) | I43: =VLOOKUP(I1,IEF!$B$27:$G$278,5,1) | J43: =VLOOKUP(J1,IEF!$B$27:$G$278,5,1) | ... O43: =VLOOKUP(O1,IEF!$B$27:$G$278,5,1) | P43: =AVERAGE(D43:O43) | Q43: =B43/P43 | R43: =(B43/D43)-1 | S43: =(C43/F43)-1 | T43: =(B43/I43)-1 | U43: =(B43/O43)-1 | V43: =R43*12 | W43: =S43*4 | X43: =T43*2 | Y43: =U43*1 | Z43: =SUM(V43:Y43)
A44: =관심종목!D41 | B44: =관심종목!H41 | C44: =VLOOKUP(C1,TLT!$B$27:$G$278,5,1) | D44: =VLOOKUP(D1,TLT!$B$27:$G$278,5,1) | E44: =VLOOKUP(E1,TLT!$B$27:$G$278,5,1) | F44: =VLOOKUP(F1,TLT!$B$27:$G$278,5,1) | G44: =VLOOKUP(G1,TLT!$B$27:$G$278,5,1) | H44: =VLOOKUP(H1,TLT!$B$27:$G$278,5,1) | I44: =VLOOKUP(I1,TLT!$B$27:$G$278,5,1) | J44: =VLOOKUP(J1,TLT!$B$27:$G$278,5,1) | ... O44: =VLOOKUP(O1,TLT!$B$27:$G$278,5,1) | P44: =AVERAGE(D44:O44) | Q44: =B44/P44 | R44: =(B44/D44)-1 | S44: =(C44/F44)-1 | T44: =(B44/I44)-1 | U44: =(B44/O44)-1 | V44: =R44*12 | W44: =S44*4 | X44: =T44*2 | Y44: =U44*1 | Z44: =SUM(V44:Y44)
...

Sheet SPY
B1: ← 관심종목으로 돌아가기 | G1: 제공:
G2: Google Finance
B4: spy | C4: << 종목코드 입력
C5: << 필요한 경우 거래소 입력(예: NASDAQ, NYSE)
B7: =IFERROR(__xludf.DUMMYFUNCTION("GOOGLEFINANCE(B18,""name"")"),"State Street SPDR S&P 500 ETF Trust")
B9: 현재가 | D9: 전일대비 | E9: 등락률(%)
B10: =IFERROR(__xludf.DUMMYFUNCTION("GOOGLEFINANCE(B18,""price"")"),729.46) | D10: =IFERROR(__xludf.DUMMYFUNCTION("IFERROR(GOOGLEFINANCE(B18,""change""),""-"")"),-11.4) | E10: =IFERROR(__xludf.DUMMYFUNCTION("IFERROR(GOOGLEFINANCE(B18,""changepct"")/100,""-"")"),-0.0154)
B13: 시가총액 | C13: PER | D13: 베타계수
B14: =IFERROR(__xludf.DUMMYFUNCTION("IFERROR(GOOGLEFINANCE(B18,""marketcap""),""-"")"),658411272346) | C14: =IFERROR(__xludf.DUMMYFUNCTION("IFERROR(GOOGLEFINANCE(B18,""pe""),""-"")"),"-") | D14: =IFERROR(__xludf.DUMMYFUNCTION("IFERROR(GOOGLEFINANCE(B18,""beta""),""-"")"),"-")
G15: 12 Months
B18: =IF(ISBLANK(B5),"",B5&":")&B4
B27: =IFERROR(__xludf.DUMMYFUNCTION("GOOGLEFINANCE(B18, ""all"", EDATE(TODAY(), -LEFT(G15, FIND("" "", G15))), TODAY(), ""DAILY"")"),"Date") | C27: =IFERROR(__xludf.DUMMYFUNCTION("""COMPUTED_VALUE"""),"Open") | D27: =IFERROR(__xludf.DUMMYFUNCTION("""COMPUTED_VALUE"""),"High") | E27: =IFERROR(__xludf.DUMMYFUNCTION("""COMPUTED_VALUE"""),"Low") | F27: =IFERROR(__xludf.DUMMYFUNCTION("""COMPUTED_VALUE"""),"Close") | G27: =IFERROR(__xludf.DUMMYFUNCTION("""COMPUTED_VALUE"""),"Volume")
B28: =IFERROR(__xludf.DUMMYFUNCTION("""COMPUTED_VALUE"""),45868.6666666666) | C28: =IFERROR(__xludf.DUMMYFUNCTION("""COMPUTED_VALUE"""),635.92) | D28: =IFERROR(__xludf.DUMMYFUNCTION("""COMPUTED_VALUE"""),637.68) | E28: =IFERROR(__xludf.DUMMYFUNCTION("""COMPUTED_VALUE"""),631.54) | F28: =IFERROR(__xludf.DUMMYFUNCTION("""COMPUTED_VALUE"""),634.46) | G28: =IFERROR(__xludf.DUMMYFUNCTION("""COMPUTED_VALUE"""),80418851)
B29: =IFERROR(__xludf.DUMMYFUNCTION("""COMPUTED_VALUE"""),45869.6666666666) | C29: =IFERROR(__xludf.DUMMYFUNCTION("""COMPUTED_VALUE"""),639.46) | D29: =IFERROR(__xludf.DUMMYFUNCTION("""COMPUTED_VALUE"""),639.85) | E29: =IFERROR(__xludf.DUMMYFUNCTION("""COMPUTED_VALUE"""),630.77) | F29: =IFERROR(__xludf.DUMMYFUNCTION("""COMPUTED_VALUE"""),632.08) | G29: =IFERROR(__xludf.DUMMYFUNCTION("""COMPUTED_VALUE"""),103385246)
B30: =IFERROR(__xludf.DUMMYFUNCTION("""COMPUTED_VALUE"""),45870.6666666666) | C30: =IFERROR(__xludf.DUMMYFUNCTION("""COMPUTED_VALUE"""),626.3) | D30: =IFERROR(__xludf.DUMMYFUNCTION("""COMPUTED_VALUE"""),626.34) | E30: =IFERROR(__xludf.DUMMYFUNCTION("""COMPUTED_VALUE"""),619.29) | F30: =IFERROR(__xludf.DUMMYFUNCTION("""COMPUTED_VALUE"""),621.72) | G30: =IFERROR(__xludf.DUMMYFUNCTION("""COMPUTED_VALUE"""),140103572)
B31: =IFERROR(__xludf.DUMMYFUNCTION("""COMPUTED_VALUE"""),45873.6666666666) | C31: =IFERROR(__xludf.DUMMYFUNCTION("""COMPUTED_VALUE"""),625.67) | D31: =IFERROR(__xludf.DUMMYFUNCTION("""COMPUTED_VALUE"""),631.22) | E31: =IFERROR(__xludf.DUMMYFUNCTION("""COMPUTED_VALUE"""),625.58) | F31: =IFERROR(__xludf.DUMMYFUNCTION("""COMPUTED_VALUE"""),631.17) | G31: =IFERROR(__xludf.DUMMYFUNCTION("""COMPUTED_VALUE"""),73218015)
B32: =IFERROR(__xludf.DUMMYFUNCTION("""COMPUTED_VALUE"""),45874.6666666666) | C32: =IFERROR(__xludf.DUMMYFUNCTION("""COMPUTED_VALUE"""),631.79) | D32: =IFERROR(__xludf.DUMMYFUNCTION("""COMPUTED_VALUE"""),632.61) | E32: =IFERROR(__xludf.DUMMYFUNCTION("""COMPUTED_VALUE"""),627.04) | F32: =IFERROR(__xludf.DUMMYFUNCTION("""COMPUTED_VALUE"""),627.97) | G32: =IFERROR(__xludf.DUMMYFUNCTION("""COMPUTED_VALUE"""),68051401)
B33: =IFERROR(__xludf.DUMMYFUNCTION("""COMPUTED_VALUE"""),45875.6666666666) | C33: =IFERROR(__xludf.DUMMYFUNCTION("""COMPUTED_VALUE"""),629.05) | D33: =IFERROR(__xludf.DUMMYFUNCTION("""COMPUTED_VALUE"""),633.44) | E33: =IFERROR(__xludf.DUMMYFUNCTION("""COMPUTED_VALUE"""),628.13) | F33: =IFERROR(__xludf.DUMMYFUNCTION("""COMPUTED_VALUE"""),632.78) | G33: =IFERROR(__xludf.DUMMYFUNCTION("""COMPUTED_VALUE"""),64357525)
B34: =IFERROR(__xludf.DUMMYFUNCTION("""COMPUTED_VALUE"""),45876.6666666666) | C34: =IFERROR(__xludf.DUMMYFUNCTION("""COMPUTED_VALUE"""),636.24) | D34: =IFERROR(__xludf.DUMMYFUNCTION("""COMPUTED_VALUE"""),636.98) | E34: =IFERROR(__xludf.DUMMYFUNCTION("""COMPUTED_VALUE"""),629.11) | F34: =IFERROR(__xludf.DUMMYFUNCTION("""COMPUTED_VALUE"""),632.25) | G34: =IFERROR(__xludf.DUMMYFUNCTION("""COMPUTED_VALUE"""),74205791)
B35: =IFERROR(__xludf.DUMMYFUNCTION("""COMPUTED_VALUE"""),45877.6666666666) | C35: =IFERROR(__xludf.DUMMYFUNCTION("""COMPUTED_VALUE"""),634.06) | D35: =IFERROR(__xludf.DUMMYFUNCTION("""COMPUTED_VALUE"""),637.65) | E35: =IFERROR(__xludf.DUMMYFUNCTION("""COMPUTED_VALUE"""),633.74) | F35: =IFERROR(__xludf.DUMMYFUNCTION("""COMPUTED_VALUE"""),637.18) | G35: =IFERROR(__xludf.DUMMYFUNCTION("""COMPUTED_VALUE"""),64051626)
B36: =IFERROR(__xludf.DUMMYFUNCTION("""COMPUTED_VALUE"""),45880.6666666666) | C36: =IFERROR(__xludf.DUMMYFUNCTION("""COMPUTED_VALUE"""),637.46) | D36: =IFERROR(__xludf.DUMMYFUNCTION("""COMPUTED_VALUE"""),638.95) | E36: =IFERROR(__xludf.DUMMYFUNCTION("""COMPUTED_VALUE"""),634.66) | F36: =IFERROR(__xludf.DUMMYFUNCTION("""COMPUTED_VALUE"""),635.92) | G36: =IFERROR(__xludf.DUMMYFUNCTION("""COMPUTED_VALUE"""),58742300)
B37: =IFERROR(__xludf.DUMMYFUNCTION("""COMPUTED_VALUE"""),45881.6666666666) | C37: =IFERROR(__xludf.DUMMYFUNCTION("""COMPUTED_VALUE"""),638.29) | D37: =IFERROR(__xludf.DUMMYFUNCTION("""COMPUTED_VALUE"""),642.85) | E37: =IFERROR(__xludf.DUMMYFUNCTION("""COMPUTED_VALUE"""),636.79) | F37: =IFERROR(__xludf.DUMMYFUNCTION("""COMPUTED_VALUE"""),642.69) | G37: =IFERROR(__xludf.DUMMYFUNCTION("""COMPUTED_VALUE"""),64821798)
B38: =IFERROR(__xludf.DUMMYFUNCTION("""COMPUTED_VALUE"""),45882.6666666666) | C38: =IFERROR(__xludf.DUMMYFUNCTION("""COMPUTED_VALUE"""),644.91) | D38: =IFERROR(__xludf.DUMMYFUNCTION("""COMPUTED_VALUE"""),646.19) | E38: =IFERROR(__xludf.DUMMYFUNCTION("""COMPUTED_VALUE"""),642.68) | F38: =IFERROR(__xludf.DUMMYFUNCTION("""COMPUTED_VALUE"""),644.89) | G38: =IFERROR(__xludf.DUMMYFUNCTION("""COMPUTED_VALUE"""),60092790)
B39: =IFERROR(__xludf.DUMMYFUNCTION("""COMPUTED_VALUE"""),45883.6666666666) | C39: =IFERROR(__xludf.DUMMYFUNCTION("""COMPUTED_VALUE"""),642.79) | D39: =IFERROR(__xludf.DUMMYFUNCTION("""COMPUTED_VALUE"""),645.62) | E39: =IFERROR(__xludf.DUMMYFUNCTION("""COMPUTED_VALUE"""),642.34) | F39: =IFERROR(__xludf.DUMMYFUNCTION("""COMPUTED_VALUE"""),644.95) | G39: =IFERROR(__xludf.DUMMYFUNCTION("""COMPUTED_VALUE"""),59327466)
B40: =IFERROR(__xludf.DUMMYFUNCTION("""COMPUTED_VALUE"""),45884.6666666666) | C40: =IFERROR(__xludf.DUMMYFUNCTION("""COMPUTED_VALUE"""),645.99) | D40: =IFERROR(__xludf.DUMMYFUNCTION("""COMPUTED_VALUE"""),646.09) | E40: =IFERROR(__xludf.DUMMYFUNCTION("""COMPUTED_VALUE"""),642.52) | F40: =IFERROR(__xludf.DUMMYFUNCTION("""COMPUTED_VALUE"""),643.44) | G40: =IFERROR(__xludf.DUMMYFUNCTION("""COMPUTED_VALUE"""),68592507)
B41: =IFERROR(__xludf.DUMMYFUNCTION("""COMPUTED_VALUE"""),45887.6666666666) | C41: =IFERROR(__xludf.DUMMYFUNCTION("""COMPUTED_VALUE"""),642.86) | D41: =IFERROR(__xludf.DUMMYFUNCTION("""COMPUTED_VALUE"""),644) | E41: =IFERROR(__xludf.DUMMYFUNCTION("""COMPUTED_VALUE"""),642.18) | F41: =IFERROR(__xludf.DUMMYFUNCTION("""COMPUTED_VALUE"""),643.3) | G41: =IFERROR(__xludf.DUMMYFUNCTION("""COMPUTED_VALUE"""),43804914)
