Workbook

Sheet 뱅샐현황
B3: 1.고객정보
B4: 사용자의 기본 정보에 해당하는 항목입니다.
B5: 이름 | C5: 성별 | D5: 연령 (만 나이) | E5: 신용점수 (KCB) | F5: 이메일
B6: 김용 | C6: 남 | D6: 46 | E6: 1000 | F6: -
B9: 2.현금흐름현황
B10: 최근 1년 동안의 현금흐름을 분석합니다.
B11: 항목 | C11: 총계 | D11: 월평균 | E11: 2025-07 | F11: 2025-08 | G11: 2025-09 | H11: 2025-10 | I11: 2025-11 | J11: 2025-12 | K11: 2026-01 | L11: 2026-02 | M11: 2026-03 | N11: 2026-04 | O11: 2026-05 | P11: 2026-06 | Q11: 2026-07
B12: 금융수입 | C12: =SUM(E12:Q12) -> 100006 | D12: =C12/13 -> 7692.7692 | E12: 0 | F12: 0 | G12: 80000 | H12: 1 | I12: 0 | J12: 20000 | K12: 0 | L12: 0 | M12: 4 | N12: 0 | O12: 1 | P12: 0 | Q12: 0
B13: 급여 | C13: =SUM(E13:Q13) -> 85914200 | D13: =C13/13 -> 6608784.6 | E13: 0 | F13: 5107809 | G13: 5863980 | H13: 10584640 | I13: 5897358 | J13: 9609713 | K13: 5869380 | L13: 12652275 | M13: 6055700 | N13: 6132550 | O13: 6052268 | P13: 6022650 | Q13: 6065877
B14: 기타수입 | C14: =SUM(E14:Q14) -> 10430 | D14: =C14/13 -> 802.30769 | E14: 0 | F14: 0 | G14: 0 | H14: 0 | I14: 0 | J14: 0 | K14: 0 | L14: 0 | M14: 0 | N14: 0 | O14: 0 | P14: 10430 | Q14: 0
B15: 사업수입 | C15: =SUM(E15:Q15) -> 1064432 | D15: =C15/13 -> 81879.385 | E15: 0 | F15: 0 | G15: 0 | H15: 0 | I15: 0 | J15: 0 | K15: 0 | L15: 0 | M15: 0 | N15: 1064432 | O15: 0 | P15: 0 | Q15: 0
B16: 상여금 | C16: =SUM(E16:Q16) -> 2378785 | D16: =C16/13 -> 182983.46 | E16: 0 | F16: 0 | G16: 0 | H16: 0 | I16: 0 | J16: 0 | K16: 0 | L16: 0 | M16: 0 | N16: 0 | O16: 0 | P16: 2378785 | Q16: 0
B17: 미분류 | C17: =SUM(E17:Q17) -> 2279856 | D17: =C17/13 -> 175373.54 | E17: 0 | F17: 0 | G17: 0 | H17: 0 | I17: 0 | J17: 0 | K17: 0 | L17: 0 | M17: 0 | N17: 0 | O17: 0 | P17: 0 | Q17: 2279856
B18: 월수입 총계 | C18: =SUM(E18:Q18) -> 91747709 | D18: =C18/13 -> 7057516.1 | E18: =SUM(E12:E17) -> 0 | F18: =SUM(F12:F17) -> 5107809 | G18: =SUM(G12:G17) -> 5943980 | H18: =SUM(H12:H17) -> 10584641 | I18: =SUM(I12:I17) -> 5897358 | J18: =SUM(J12:J17) -> 9629713 | K18: =SUM(K12:K17) -> 5869380 | L18: =SUM(L12:L17) -> 12652275 | ... Q18: =SUM(Q12:Q17) -> 8345733
A19: 필수 | B19: 경조/선물 | C19: =SUM(E19:Q19) -> 9091336 | D19: =C19/13 -> 699333.54 | E19: 700000 | F19: 730000 | G19: 700000 | H19: 930000 | I19: 750000 | J19: 750000 | K19: 750000 | L19: 760336 | M19: 721000 | N19: 750000 | O19: 750000 | P19: 750000 | Q19: 50000
A20: 선택 | B20: 교육/학습 | C20: =SUM(E20:Q20) -> 206090 | D20: =C20/13 -> 15853.077 | E20: 0 | F20: 0 | G20: 10200 | H20: 0 | I20: 0 | J20: 12000 | K20: 85700 | L20: 92190 | M20: 0 | N20: 6000 | O20: 0 | P20: 0 | Q20: 0
A21: 필수 | B21: 교통 | C21: =SUM(E21:Q21) -> 620250 | D21: =C21/13 -> 47711.538 | E21: 0 | F21: 2900 | G21: 30000 | H21: 30000 | I21: 60750 | J21: 50000 | K21: 63200 | L21: 75300 | M21: 60000 | N21: 53200 | O21: 60000 | P21: 63400 | Q21: 71500
A22: 필수 | B22: 금융 | C22: =SUM(E22:Q22) -> 141322168 | D22: =C22/13 -> 10870936 | E22: 60380 | F22: 1313802 | G22: 121577701 | H22: 1659562 | I22: 1384699 | J22: 1498194 | K22: 2075322 | L22: 1863655 | M22: 2015670 | N22: 1818208 | O22: 2053519 | P22: 2005859 | Q22: 1995597
A23: 선택 | B23: 문화/여가 | C23: =SUM(E23:Q23) -> 318650 | D23: =C23/13 -> 24511.538 | E23: 0 | F23: 21900 | G23: 9270 | H23: 0 | I23: 7000 | J23: 18000 | K23: 71490 | L23: 34900 | M23: 54490 | N23: 37900 | O23: 4000 | P23: 48700 | Q23: 11000
A24: 선택 | B24: 반려동물 | C24: =SUM(E24:Q24) -> 32500 | D24: =C24/13 -> 2500 | E24: 0 | F24: 0 | G24: 0 | H24: 0 | I24: 0 | J24: 0 | K24: 0 | L24: 0 | M24: 0 | N24: 0 | O24: 0 | P24: 32500 | Q24: 0
A25: 선택 | B25: 뷰티/미용 | C25: =SUM(E25:Q25) -> 949908 | D25: =C25/13 -> 73069.846 | E25: 0 | F25: 52400 | G25: 81670 | H25: 41200 | I25: 102433 | J25: 83333 | K25: 150833 | L25: 83333 | M25: 101933 | N25: 83333 | O25: 43610 | P25: 37660 | Q25: 88170
A26: 선택 | B26: 생활 | C26: =SUM(E26:Q26) -> 5266511 | D26: =C26/13 -> 405116.23 | E26: 0 | F26: 517390 | G26: 562764 | H26: 384580 | I26: 657570 | J26: 562880 | K26: 406777 | L26: 664860 | M26: 238890 | N26: 248160 | O26: 611080 | P26: 180400 | Q26: 231160
A27: 선택 | B27: 술/유흥 | C27: =SUM(E27:Q27) -> 149900 | D27: =C27/13 -> 11530.769 | E27: 0 | F27: 0 | G27: 0 | H27: 0 | I27: 28500 | J27: 0 | K27: 0 | L27: 0 | M27: 0 | N27: 121400 | O27: 0 | P27: 0 | Q27: 0
A28: 선택 | B28: 식비 | C28: =SUM(E28:Q28) -> 10859323 | D28: =C28/13 -> 835332.54 | E28: 198963 | F28: 1064704 | G28: 534182 | H28: 619454 | I28: 814865 | J28: 586715 | K28: 951826 | L28: 1051308 | M28: 1223049 | N28: 824610 | O28: 1109662 | P28: 717950 | Q28: 1162035
A29: 선택 | B29: 여행/숙박 | C29: =SUM(E29:Q29) -> 492054 | D29: =C29/13 -> 37850.308 | E29: 0 | F29: 0 | G29: 0 | H29: 42000 | I29: 0 | J29: 0 | K29: 28500 | L29: 126254 | M29: 3000 | N29: 61400 | O29: 10000 | P29: 220900 | Q29: 0
A30: 선택 | B30: 온라인쇼핑 | C30: =SUM(E30:Q30) -> 12192380 | D30: =C30/13 -> 937875.38 | E30: 95160 | F30: 796617 | G30: 5908354 | H30: 478950 | I30: 1478034 | J30: 251792 | K30: 894758 | L30: 253822 | M30: 505824 | N30: 365333 | O30: 286309 | P30: 688755 | Q30: 188672
... A37: 선택 | B37: 미분류 | C37: =SUM(E37:Q37) -> 0 | D37: =C37/13 -> 0 | E37: 0 | F37: 0 | G37: 0 | H37: 0 | I37: 0 | J37: 0 | K37: 0 | L37: 0 | M37: 0 | N37: 0 | O37: 0 | P37: 0 | Q37: 0
B38: 월지출 총계 | C38: =SUM(E38:Q38) -> 194620682 | D38: =C38/13 -> 14970822 | E38: =SUM(E19:E37) -> 1084003 | F38: =SUM(F19:F37) -> 5102523 | G38: =SUM(G19:G37) -> 130315436 | H38: =SUM(H19:H37) -> 5937755 | I38: =SUM(I19:I37) -> 6397071 | J38: =SUM(J19:J37) -> 4881721 | K38: =SUM(K19:K37) -> 6696012 | L38: =SUM(L19:L37) -> 6337284 | ... Q38: =SUM(Q19:Q37) -> 4644167
B39: 순수입 총계 | C39: =SUM(E39:Q39) -> -102872973 | D39: =C39/13 -> -7913305.6 | E39: =E18-E38 -> -1084003 | F39: =F18-F38 -> 5286 | G39: =G18-G38 -> -124371456 | H39: =H18-H38 -> 4646886 | I39: =I18-I38 -> -499713 | J39: =J18-J38 -> 4747992 | K39: =K18-K38 -> -826632 | L39: =L18-L38 -> 6314991 | ... Q39: =Q18-Q38 -> 3701566
B42: 3.재무현황
B43: 데이터를 내보낸 시점의 자산과 부채 상태를 분석합니다.
B44: 자산 | F44: 부채
B45: 항목 | C45: 상품명 | E45: 금액 | F45: 항목 | G45: 상품명 | I45: 금액
B46: 자유입출금 자산 | C46: AMA+급여 MMDA | E46: 0 | F46: 장기대출 | G46: 하나은행 마이너스 통장 | I46: 121685737
C47: AMA+급여 저축예금 | E47: 0 | G47: 가계일반자금대출(분할상환)-하나 아파트론(혼합금리형) | I47: 207103001
C48: MY 입출금통장 | E48: 1 | G48: 하나은행 마이너스 통장 | I48: 1726305
C49: NH주거래우대통장(비대면실명확인) | E49: 0 | G49: 2020년 2학기 일반상환학자금_등록금 | I49: 5448520
C50: 넘버엔 통장 | E50: -121685737 | G50: 2021년 2학기 일반상환학자금_등록금 | I50: 5441312
C51: 달달 하나 통장 | E51: -1726305 | G51: 2020년 1학기 일반상환학자금_등록금 | I51: 5198750
C52: 샐러리맨리치예금(스페셜플러스예금) | E52: 86 | G52: 2021년 1학기 일반상환학자금_등록금 | I52: 5129730
...

Sheet 대시보드
B1: 전체 투자금 | C1: 16666666 | G1: 채권 | H1: =C3/3 -> 2222222.1
B2: 한국 개별주 퀀트 | C2: =C1*60% -> 9999999.6 | G2: 변형 듀얼모멘텀 | H2: =C3/3 -> 2222222.1
B3: 동적자산배분 | C3: =C1*40% -> 6666666.4 | G3: BAA | H3: =C3/3 -> 2222222.1
B5: ㅣBAA | H5: ㅣ변형 듀얼모멘텀 | O5: ㅣ채권 동적자산배분
B6: Q. 카나리아 자산 중 "0"이하인 모멘텀 스코어가 있나요? | H6: Step1. 공격자산 수익률이 모두 "0"이상인 경우, 수익률이 높은 자산에 100%투자합니다
B7: ㅣBAA중도형_카나리아 자산
C8: =BD!Z28 -> 모멘텀 스코어 | H8: ㅣ변형 듀얼모멘텀_공격자산
B9: SPY | C9: =BD!Z29 -> 0.57855269 | H9: =BD!A36 -> 0 | I9: =BD!B36 -> 최근 1년 수익률
B10: EFA | C10: =BD!Z30 -> 0.61452449 | H10: =BD!A37 -> SPY | I10: =BD!B37 -> 0.17329344
B11: EEM | C11: =BD!Z31 -> -1.1812447 | H11: =BD!A38 -> EFA | I11: =BD!B38 -> 0.18421354
B12: AGG | C12: =BD!Z32 -> -0.50752718
H13: Step2. SPY의 수익률이 "0"이하인 경우, 안전자산 중 수익률 높은 채권 3개를 매수합니다 But, 수익률이 "0" 이하인 자산은 현금보유
B14: A-1. 네, "0" 이하가 있어요
B15: 공격자산 투자중단! ↓아래있는 안전자산의 최근수익률이 높은 3개 자산에 투자합니다 But,(현재가격<12개월 이동평균)이면 현금으로 보유
H16: 종목당 투자금액 | I16: =H2/3 -> 740740.71
B17: 종목당 투자액 | C17: =H3/3 -> 740740.71 | H17: ㅣ변형 듀얼모멘텀_안전자산
B18: ㅣBAA 안전자산 | H18: =BD!A41 -> 0 | I18: =BD!T41 -> 6개월 수익률 | N18: 216 9002
C19: 현재/12개월이평 | D19: =BD!B18 -> 현재 | E19: =BD!P18 -> 12개월 이동평균 | H19: =BD!A42 -> SHY | I19: =BD!T42 -> -0.010857763
B20: =BD!A19 -> LQD | C20: =BD!Q19 -> 0.96234834 | D20: =BD!B19 -> 106.22 | E20: =BD!P19 -> 110.37583 | H20: =BD!A43 -> IEF | I20: =BD!T43 -> -0.028467153
B21: =BD!A20 -> IEF | C21: =BD!Q20 -> 0.97363365 | D21: =BD!B20 -> 93.17 | E21: =BD!P20 -> 95.693077 | H21: =BD!A44 -> TLT | I21: =BD!T44 -> -0.054223744
B22: =BD!A21 -> BIL | C22: =BD!Q21 -> 1.0000336 | D22: =BD!B21 -> 91.64 | E22: =BD!P21 -> 91.636923 | H22: =BD!A45 -> TIP | I22: =BD!T45 -> -0.024176023
B23: =BD!A22 -> TLT | C23: =BD!Q22 -> 0.9475152 | D23: =BD!B22 -> 82.85 | E23: =BD!P22 -> 87.439231 | H23: =BD!A46 -> LQD | I23: =BD!T46 -> -0.04003615
B24: =BD!A23 -> TIP | C24: =BD!Q23 -> 0.97578999 | D24: =BD!B23 -> 107.77 | E24: =BD!P23 -> 110.44385 | H24: =BD!A47 -> HYG | I24: =BD!T47 -> -0.022211254
B25: =BD!A24 -> BND | C25: =BD!Q24 -> 0.97960501 | D25: =BD!B24 -> 72.38 | E25: =BD!P24 -> 73.886923 | H25: =BD!A48 -> BWX | I25: =BD!T48 -> -0.064810787
B26: =BD!A25 -> DBC | C26: =BD!Q25 -> 1.1344585 | D26: =BD!B25 -> 29.42 | E26: =BD!P25 -> 25.933077 | H26: =BD!A49 -> EMB | I26: =BD!T49 -> -0.021725636
B28: A-2. 모두 "0" 보다 커요(BAA중도형) | E28: A-2. 모두 "0" 보다 커요(BAA공격형)
B29: ↓아래있는 [BAA중도형_공격자산 12종목] 또는 [BAA공격형]중 모멘텀 스코어가 높은 6개 자산에 투자합니다 | E29: BAA 공격형 투자는 최근수익률이 높은 1개 자산에 몰빵! 합니다
B31: 종목당 투자액 | C31: =H3/6 -> 370370.36 | E31: 종목당 투자액 | F31: =H3 -> 2222222.1
B32: ㅣBAA 중도형_공격자산 12종목 | E32: ㅣBAA공격형(수익↑, MDD↑)
C33: =BD!Z4 -> 모멘텀 스코어 | D33: 현재/12개월이평 | F33: 모멘텀 스코어 | G33: 현재/12개월이평
B34: =BD!A5 -> SPY | C34: =BD!Z5 -> 0.37880279 | D34: =BD!Q5 -> 1.066982 | E34: =관심종목!D26 -> QQQ | F34: =BD!Z33 -> 38.610291 | G34: =BD!Q29 -> 1.066982
B35: =BD!A6 -> QQQ | C35: =BD!Z6 -> 38.610291 | D35: =BD!Q6 -> 3.0321206 | E35: =관심종목!D23 -> EFA | F35: =BD!Z30 -> 0.61452449 | G35: =BD!Q30 -> 1.062257
B36: =BD!A7 -> IWM | C36: =BD!Z7 -> 0.29806355 | D36: =BD!Q7 -> 1.1260573 | E36: =관심종목!D24 -> EEM | F36: =BD!Z31 -> -1.1812447 | G36: =BD!Q31 -> 1.0572756
B37: =BD!A8 -> VGK | C37: =BD!Z8 -> 0.56731347 | D37: =BD!Q8 -> 1.0664906 | E37: =관심종목!D25 -> AGG | F37: =BD!Z32 -> -0.50752718 | G37: =BD!Q32 -> 0.97650906
B38: =BD!A9 -> EWJ | C38: =BD!Z9 -> -0.060885151 | D38: =BD!Q9 -> 1.0576259
B39: =BD!A10 -> VWO | C39: =BD!Z10 -> -0.31959144 | D39: =BD!Q10 -> 1.0287522
B40: =BD!A11 -> VEA | C40: =BD!Z11 -> #N/A | D40: =BD!Q11 -> #N/A
B41: =BD!A12 -> VNQ | C41: =BD!Z12 -> 0.83395273 | D41: =BD!Q12 -> 1.0923791
B42: =BD!A13 -> DBC | C42: =BD!Z13 -> 1.8569605 | D42: =BD!Q13 -> 1.1721116
B43: =BD!A14 -> GLD | C43: =BD!Z14 -> -0.86267709 | D43: =BD!Q14 -> 0.93920526
...

Sheet 관심종목
D1: 안내 B열에 추적할 주식의 종목코드를 입력합니다. H열에 평가금액을 추적할 주식의 수량을 입력합니다. | L1: 제공:
L2: Google Finance
F4: 관심종목
F5: 평가금액
F6: =SUM(N9:N55) -> 0
A8: 전략 명 | B8: 투자비율 | C8: 포트폴리오 명 | D8: 종목코드 | E8: 거래소 (선택사항) | F8: 종목명 | H8: 현재가 | I8: 전일대비 | J8: 등락률(%) | K8: 주식수 | L8: 평가금액 | M8: 종목 합계 | O8: 모멘텀스코어 | P8: 1개월수익률 | Q8: 3개월수익률 | R8: 6개월수익률 | S8: 12개월수익률 | T8: 12개월 이동평균 | U8: 현재가격/ 12개월이동평균
E9: NASDAQ | F9: =IFERROR(__xludf.DUMMYFUNCTION("IF(ISBLANK(D9), ""-"", GOOGLEFINANCE(IF(ISBLANK(E9), D9, E9&"":""&D9), ""name""))"),"-") -> - | H9: =IFERROR(__xludf.DUMMYFUNCTION("IF(ISBLANK(D9), 0, GOOGLEFINANCE(IF(ISBLANK(E9), D9, E9&"":""&D9), ""price""))"),0) -> 0 | I9: =IFERROR(__xludf.DUMMYFUNCTION("IF(ISBLANK(D9), 0, GOOGLEFINANCE(IF(ISBLANK(E9), D9, E9&"":""&D9), ""change""))"),0) -> 0 | J9: =IFERROR(__xludf.DUMMYFUNCTION("IF(ISBLANK(D9), 0, GOOGLEFINANCE(IF(ISBLANK(E9), D9, E9&"":""&D9), ""changepct"")/100)"),0) -> 0 | K9: 0 | L9: =K9 * H9 -> 0 | O9: =(P9*12)+(Q9*4)+(R9*2)+(S9*1) -> 0
C10: BAA 공격자산 | D10: SPY | F10: =IFERROR(__xludf.DUMMYFUNCTION("IF(ISBLANK(D10), ""-"", GOOGLEFINANCE(IF(ISBLANK(E10), D10, E10&"":""&D10), ""name""))"),"State Street SPDR S&P 500 ETF Trust") -> State Street SPDR S&P 500 ETF Trust | H10: =IFERROR(__xludf.DUMMYFUNCTION("IF(ISBLANK(D10), 0, GOOGLEFINANCE(IF(ISBLANK(E10), D10, E10&"":""&D10), ""price""))"),729.46) -> 729.46 | I10: =IFERROR(__xludf.DUMMYFUNCTION("IF(ISBLANK(D10), 0, GOOGLEFINANCE(IF(ISBLANK(E10), D10, E10&"":""&D10), ""change""))"),-11.4) -> -11.4 | J10: =IFERROR(__xludf.DUMMYFUNCTION("IF(ISBLANK(D10), 0, GOOGLEFINANCE(IF(ISBLANK(E10), D10, E10&"":""&D10), ""changepct"")/100)"),-0.0154) -> -0.0154 | K10: 1 | L10: =K10 * H10 -> 729.46 | O10: =(P10*12)+(Q10*4)+(R10*2)+(S10*1) -> 0.34343962 | P10: =(SPY!F278-SPY!F256)/SPY!F256 -> 0.00064472764 | Q10: =(SPY!F278-SPY!F214)/SPY!F214 -> 0.019981263 | R10: =(SPY!F278-SPY!F151)/SPY!F151 -> 0.053022101 | S10: =(SPY!F278-SPY!F28)/SPY!F28 -> 0.14973363
D11: QQQ | F11: =IFERROR(__xludf.DUMMYFUNCTION("IF(ISBLANK(D11), ""-"", GOOGLEFINANCE(IF(ISBLANK(E11), D11, E11&"":""&D11), ""name""))"),"Invesco QQQ Trust, Series 1") -> Invesco QQQ Trust, Series 1 | H11: =IFERROR(__xludf.DUMMYFUNCTION("IF(ISBLANK(D11), 0, GOOGLEFINANCE(IF(ISBLANK(E11), D11, E11&"":""&D11), ""price""))"),661.73) -> 661.73 | I11: =IFERROR(__xludf.DUMMYFUNCTION("IF(ISBLANK(D11), 0, GOOGLEFINANCE(IF(ISBLANK(E11), D11, E11&"":""&D11), ""change""))"),-13.76) -> -13.76 | J11: =IFERROR(__xludf.DUMMYFUNCTION("IF(ISBLANK(D11), 0, GOOGLEFINANCE(IF(ISBLANK(E11), D11, E11&"":""&D11), ""changepct"")/100)"),-0.0204) -> -0.0204 | K11: 1 | L11: =K11 * H11 -> 661.73 | O11: =(P11*12)+(Q11*4)+(R11*2)+(S11*1) -> -0.9493035 | P11: =(TLT!$F$278-TLT!$F$256)/TLT!$F$256 -> -0.051625458 | Q11: =(TLT!$F$278-TLT!$F$214)/TLT!$F$214 -> -0.039754288 | R11: =(TLT!$F$278-TLT!$F$151)/TLT!$F$151 -> -0.062252405 | S11: =(TLT!$F$278-TLT!$F$28)/TLT!$F$28 -> -0.046276045
D12: IWM | F12: =IFERROR(__xludf.DUMMYFUNCTION("IF(ISBLANK(D12), ""-"", GOOGLEFINANCE(IF(ISBLANK(E12), D12, E12&"":""&D12), ""name""))"),"iShares Russell 2000 ETF") -> iShares Russell 2000 ETF | H12: =IFERROR(__xludf.DUMMYFUNCTION("IF(ISBLANK(D12), 0, GOOGLEFINANCE(IF(ISBLANK(E12), D12, E12&"":""&D12), ""price""))"),288.57) -> 288.57 | I12: =IFERROR(__xludf.DUMMYFUNCTION("IF(ISBLANK(D12), 0, GOOGLEFINANCE(IF(ISBLANK(E12), D12, E12&"":""&D12), ""change""))"),-4.8) -> -4.8 | J12: =IFERROR(__xludf.DUMMYFUNCTION("IF(ISBLANK(D12), 0, GOOGLEFINANCE(IF(ISBLANK(E12), D12, E12&"":""&D12), ""changepct"")/100)"),-0.0163999999999999) -> -0.0164 | K12: 1 | L12: =K12 * H12 -> 288.57 | O12: =(P12*12)+(Q12*4)+(R12*2)+(S12*1) -> -0.7990478 | P12: =(GLD!F278-GLD!F256)/GLD!F256 -> -0.0068249338 | Q12: =(GLD!F278-GLD!F214)/GLD!F214 -> -0.13680244 | R12: =(GLD!F278-GLD!F151)/GLD!F151 -> -0.20146331 | S12: =(GLD!F278-GLD!F28)/GLD!F28 -> 0.23298777
D13: VGK | F13: =IFERROR(__xludf.DUMMYFUNCTION("IF(ISBLANK(D13), ""-"", GOOGLEFINANCE(IF(ISBLANK(E13), D13, E13&"":""&D13), ""name""))"),"Vanguard European Stock Index Fund ETF") -> Vanguard European Stock Index Fund ETF | H13: =IFERROR(__xludf.DUMMYFUNCTION("IF(ISBLANK(D13), 0, GOOGLEFINANCE(IF(ISBLANK(E13), D13, E13&"":""&D13), ""price""))"),88.86) -> 88.86 | I13: =IFERROR(__xludf.DUMMYFUNCTION("IF(ISBLANK(D13), 0, GOOGLEFINANCE(IF(ISBLANK(E13), D13, E13&"":""&D13), ""change""))"),-0.37) -> -0.37 | J13: =IFERROR(__xludf.DUMMYFUNCTION("IF(ISBLANK(D13), 0, GOOGLEFINANCE(IF(ISBLANK(E13), D13, E13&"":""&D13), ""changepct"")/100)"),-0.00409999999999999) -> -0.0041 | K13: 1 | L13: =K13 * H13 -> 88.86 | O13: =(P13*12)+(Q13*4)+(R13*2)+(S13*1) -> 0.0021845717 | P13: =(BIL!$F$278-BIL!$F$256)/BIL!$F$256 -> 0.00010913456 | Q13: =(BIL!$F$278-BIL!$F$214)/BIL!$F$214 -> 0.00021829295 | R13: =(BIL!$F$278-BIL!$F$151)/BIL!$F$151 -> 0.00054591113 | S13: =(BIL!$F$278-BIL!$F$28)/BIL!$F$28 -> -0.0010900371
D14: EWJ | F14: =IFERROR(__xludf.DUMMYFUNCTION("IF(ISBLANK(D14), ""-"", GOOGLEFINANCE(IF(ISBLANK(E14), D14, E14&"":""&D14), ""name""))"),"iShares MSCI Japan ETF") -> iShares MSCI Japan ETF | H14: =IFERROR(__xludf.DUMMYFUNCTION("IF(ISBLANK(D14), 0, GOOGLEFINANCE(IF(ISBLANK(E14), D14, E14&"":""&D14), ""price""))"),89.35) -> 89.35 | I14: =IFERROR(__xludf.DUMMYFUNCTION("IF(ISBLANK(D14), 0, GOOGLEFINANCE(IF(ISBLANK(E14), D14, E14&"":""&D14), ""change""))"),-0.48) -> -0.48 | J14: =IFERROR(__xludf.DUMMYFUNCTION("IF(ISBLANK(D14), 0, GOOGLEFINANCE(IF(ISBLANK(E14), D14, E14&"":""&D14), ""changepct"")/100)"),-0.0053) -> -0.0053 | K14: 1 | L14: =K14 * H14 -> 89.35
D15: VWO | F15: =IFERROR(__xludf.DUMMYFUNCTION("IF(ISBLANK(D15), ""-"", GOOGLEFINANCE(IF(ISBLANK(E15), D15, E15&"":""&D15), ""name""))"),"Vanguard Emerging Markets Stock Index Fund ETF") -> Vanguard Emerging Markets Stock Index Fund ETF | H15: =IFERROR(__xludf.DUMMYFUNCTION("IF(ISBLANK(D15), 0, GOOGLEFINANCE(IF(ISBLANK(E15), D15, E15&"":""&D15), ""price""))"),56.92) -> 56.92 | I15: =IFERROR(__xludf.DUMMYFUNCTION("IF(ISBLANK(D15), 0, GOOGLEFINANCE(IF(ISBLANK(E15), D15, E15&"":""&D15), ""change""))"),-0.82) -> -0.82 | J15: =IFERROR(__xludf.DUMMYFUNCTION("IF(ISBLANK(D15), 0, GOOGLEFINANCE(IF(ISBLANK(E15), D15, E15&"":""&D15), ""changepct"")/100)"),-0.0141999999999999) -> -0.0142 | K15: 1 | L15: =K15 * H15 -> 56.92
D16: VEA | F16: =IFERROR(__xludf.DUMMYFUNCTION("IF(ISBLANK(D16), ""-"", GOOGLEFINANCE(IF(ISBLANK(E16), D16, E16&"":""&D16), ""name""))"),"Vanguard Tax Managed Fund FTSE Developed Markets ETF") -> Vanguard Tax Managed Fund FTSE Developed Markets ETF | H16: =IFERROR(__xludf.DUMMYFUNCTION("IF(ISBLANK(D16), 0, GOOGLEFINANCE(IF(ISBLANK(E16), D16, E16&"":""&D16), ""price""))"),68.95) -> 68.95 | I16: =IFERROR(__xludf.DUMMYFUNCTION("IF(ISBLANK(D16), 0, GOOGLEFINANCE(IF(ISBLANK(E16), D16, E16&"":""&D16), ""change""))"),-0.65) -> -0.65 | J16: =IFERROR(__xludf.DUMMYFUNCTION("IF(ISBLANK(D16), 0, GOOGLEFINANCE(IF(ISBLANK(E16), D16, E16&"":""&D16), ""changepct"")/100)"),-0.0093) -> -0.0093 | K16: 1 | L16: =K16 * H16 -> 68.95
D17: VNQ | F17: =IFERROR(__xludf.DUMMYFUNCTION("IF(ISBLANK(D17), ""-"", GOOGLEFINANCE(IF(ISBLANK(E17), D17, E17&"":""&D17), ""name""))"),"Vanguard Real Estate Index Fund ETF") -> Vanguard Real Estate Index Fund ETF | H17: =IFERROR(__xludf.DUMMYFUNCTION("IF(ISBLANK(D17), 0, GOOGLEFINANCE(IF(ISBLANK(E17), D17, E17&"":""&D17), ""price""))"),100.66) -> 100.66 | I17: =IFERROR(__xludf.DUMMYFUNCTION("IF(ISBLANK(D17), 0, GOOGLEFINANCE(IF(ISBLANK(E17), D17, E17&"":""&D17), ""change""))"),-0.29) -> -0.29 | J17: =IFERROR(__xludf.DUMMYFUNCTION("IF(ISBLANK(D17), 0, GOOGLEFINANCE(IF(ISBLANK(E17), D17, E17&"":""&D17), ""changepct"")/100)"),-0.0029) -> -0.0029 | K17: 1 | L17: =K17 * H17 -> 100.66
D18: DBC | F18: =IFERROR(__xludf.DUMMYFUNCTION("IF(ISBLANK(D18), ""-"", GOOGLEFINANCE(IF(ISBLANK(E18), D18, E18&"":""&D18), ""name""))"),"Invesco DB Commodity Index Tracking Fund") -> Invesco DB Commodity Index Tracking Fund | H18: =IFERROR(__xludf.DUMMYFUNCTION("IF(ISBLANK(D18), 0, GOOGLEFINANCE(IF(ISBLANK(E18), D18, E18&"":""&D18), ""price""))"),29.42) -> 29.42 | I18: =IFERROR(__xludf.DUMMYFUNCTION("IF(ISBLANK(D18), 0, GOOGLEFINANCE(IF(ISBLANK(E18), D18, E18&"":""&D18), ""change""))"),0.82) -> 0.82 | J18: =IFERROR(__xludf.DUMMYFUNCTION("IF(ISBLANK(D18), 0, GOOGLEFINANCE(IF(ISBLANK(E18), D18, E18&"":""&D18), ""changepct"")/100)"),0.0287) -> 0.0287 | K18: 1 | L18: =K18 * H18 -> 29.42
D19: GLD | F19: =IFERROR(__xludf.DUMMYFUNCTION("IF(ISBLANK(D19), ""-"", GOOGLEFINANCE(IF(ISBLANK(E19), D19, E19&"":""&D19), ""name""))"),"SPDR Gold Trust") -> SPDR Gold Trust | H19: =IFERROR(__xludf.DUMMYFUNCTION("IF(ISBLANK(D19), 0, GOOGLEFINANCE(IF(ISBLANK(E19), D19, E19&"":""&D19), ""price""))"),371.08) -> 371.08 | I19: =IFERROR(__xludf.DUMMYFUNCTION("IF(ISBLANK(D19), 0, GOOGLEFINANCE(IF(ISBLANK(E19), D19, E19&"":""&D19), ""change""))"),1.71) -> 1.71 | J19: =IFERROR(__xludf.DUMMYFUNCTION("IF(ISBLANK(D19), 0, GOOGLEFINANCE(IF(ISBLANK(E19), D19, E19&"":""&D19), ""changepct"")/100)"),0.0046) -> 0.0046 | K19: 1 | L19: =K19 * H19 -> 371.08
D20: LQD | F20: =IFERROR(__xludf.DUMMYFUNCTION("IF(ISBLANK(D20), ""-"", GOOGLEFINANCE(IF(ISBLANK(E20), D20, E20&"":""&D20), ""name""))"),"iShares iBoxx $ Inv Grade Corporate Bond ETF") -> iShares iBoxx $ Inv Grade Corporate Bond ETF | H20: =IFERROR(__xludf.DUMMYFUNCTION("IF(ISBLANK(D20), 0, GOOGLEFINANCE(IF(ISBLANK(E20), D20, E20&"":""&D20), ""price""))"),106.22) -> 106.22 | I20: =IFERROR(__xludf.DUMMYFUNCTION("IF(ISBLANK(D20), 0, GOOGLEFINANCE(IF(ISBLANK(E20), D20, E20&"":""&D20), ""change""))"),-0.61) -> -0.61 | J20: =IFERROR(__xludf.DUMMYFUNCTION("IF(ISBLANK(D20), 0, GOOGLEFINANCE(IF(ISBLANK(E20), D20, E20&"":""&D20), ""changepct"")/100)"),-0.00569999999999999) -> -0.0057 | K20: 1 | L20: =K20 * H20 -> 106.22
D21: HYG | F21: =IFERROR(__xludf.DUMMYFUNCTION("IF(ISBLANK(D21), ""-"", GOOGLEFINANCE(IF(ISBLANK(E21), D21, E21&"":""&D21), ""name""))"),"iShares iBoxx $ High Yield Corporate Bond ETF") -> iShares iBoxx $ High Yield Corporate Bond ETF | H21: =IFERROR(__xludf.DUMMYFUNCTION("IF(ISBLANK(D21), 0, GOOGLEFINANCE(IF(ISBLANK(E21), D21, E21&"":""&D21), ""price""))"),79.24) -> 79.24 | I21: =IFERROR(__xludf.DUMMYFUNCTION("IF(ISBLANK(D21), 0, GOOGLEFINANCE(IF(ISBLANK(E21), D21, E21&"":""&D21), ""change""))"),-0.18) -> -0.18 | J21: =IFERROR(__xludf.DUMMYFUNCTION("IF(ISBLANK(D21), 0, GOOGLEFINANCE(IF(ISBLANK(E21), D21, E21&"":""&D21), ""changepct"")/100)"),-0.0023) -> -0.0023 | K21: 1 | L21: =K21 * H21 -> 79.24
C22: BAA 카나리아 | D22: SPY | F22: =IFERROR(__xludf.DUMMYFUNCTION("IF(ISBLANK(D22), ""-"", GOOGLEFINANCE(IF(ISBLANK(E22), D22, E22&"":""&D22), ""name""))"),"State Street SPDR S&P 500 ETF Trust") -> State Street SPDR S&P 500 ETF Trust | G22: 미국 주식 | H22: =IFERROR(__xludf.DUMMYFUNCTION("IF(ISBLANK(D22), 0, GOOGLEFINANCE(IF(ISBLANK(E22), D22, E22&"":""&D22), ""price""))"),729.46) -> 729.46 | I22: =IFERROR(__xludf.DUMMYFUNCTION("IF(ISBLANK(D22), 0, GOOGLEFINANCE(IF(ISBLANK(E22), D22, E22&"":""&D22), ""change""))"),-11.4) -> -11.4 | J22: =IFERROR(__xludf.DUMMYFUNCTION("IF(ISBLANK(D22), 0, GOOGLEFINANCE(IF(ISBLANK(E22), D22, E22&"":""&D22), ""changepct"")/100)"),-0.0154) -> -0.0154 | K22: 1 | L22: =K22 * H22 -> 729.46 | O22: =(P22*12)+(Q22*4)+(R22*2)+(S22*1) -> 0.34343962 | P22: =(SPY!$F$278-SPY!$F$256)/SPY!$F$256 -> 0.00064472764 | Q22: =(SPY!$F$278-SPY!$F$214)/SPY!$F$214 -> 0.019981263 | R22: =(SPY!$F$278-SPY!$F$151)/SPY!$F$151 -> 0.053022101 | S22: =(SPY!$F$278-SPY!$F$28)/SPY!$F$28 -> 0.14973363 | V22: 모멘텀 스코어가 0이하인 ETF가 하나라도 있으면 공격자산 투자중단->안전자산으로 이동
D23: EFA | F23: =IFERROR(__xludf.DUMMYFUNCTION("IF(ISBLANK(D23), ""-"", GOOGLEFINANCE(IF(ISBLANK(E23), D23, E23&"":""&D23), ""name""))"),"iShares MSCI EAFE ETF") -> iShares MSCI EAFE ETF | G23: 선진국 주식 | H23: =IFERROR(__xludf.DUMMYFUNCTION("IF(ISBLANK(D23), 0, GOOGLEFINANCE(IF(ISBLANK(E23), D23, E23&"":""&D23), ""price""))"),103.37) -> 103.37 | I23: =IFERROR(__xludf.DUMMYFUNCTION("IF(ISBLANK(D23), 0, GOOGLEFINANCE(IF(ISBLANK(E23), D23, E23&"":""&D23), ""change""))"),-0.52) -> -0.52 | J23: =IFERROR(__xludf.DUMMYFUNCTION("IF(ISBLANK(D23), 0, GOOGLEFINANCE(IF(ISBLANK(E23), D23, E23&"":""&D23), ""changepct"")/100)"),-0.005) -> -0.005 | K23: 1 | L23: =K23 * H23 -> 103.37 | O23: =(P23*12)+(Q23*4)+(R23*2)+(S23*1) -> 0.40179665 | P23: =(EFA!$F$278-EFA!$F$256)/EFA!$F$256 -> 0.0080944022 | Q23: =(EFA!$F$278-EFA!$F$214)/EFA!$F$214 -> 0.019629118 | R23: =(EFA!$F$278-EFA!$F$151)/EFA!$F$151 -> 0.028864338 | S23: =(EFA!$F$278-EFA!$F$28)/EFA!$F$28 -> 0.16841867
D24: EEM | F24: =IFERROR(__xludf.DUMMYFUNCTION("IF(ISBLANK(D24), ""-"", GOOGLEFINANCE(IF(ISBLANK(E24), D24, E24&"":""&D24), ""name""))"),"iShares MSCI Emerging Markets ETF") -> iShares MSCI Emerging Markets ETF | G24: 개발도상국 | H24: =IFERROR(__xludf.DUMMYFUNCTION("IF(ISBLANK(D24), 0, GOOGLEFINANCE(IF(ISBLANK(E24), D24, E24&"":""&D24), ""price""))"),61.07) -> 61.07 | I24: =IFERROR(__xludf.DUMMYFUNCTION("IF(ISBLANK(D24), 0, GOOGLEFINANCE(IF(ISBLANK(E24), D24, E24&"":""&D24), ""change""))"),-1.29) -> -1.29 | J24: =IFERROR(__xludf.DUMMYFUNCTION("IF(ISBLANK(D24), 0, GOOGLEFINANCE(IF(ISBLANK(E24), D24, E24&"":""&D24), ""changepct"")/100)"),-0.0207) -> -0.0207 | K24: 1 | L24: =K24 * H24 -> 61.07 | O24: =(P24*12)+(Q24*4)+(R24*2)+(S24*1) -> -0.93992219 | P24: =(EEM!F278-EEM!F256)/EEM!F256 -> -0.091084983 | Q24: =(EEM!F278-EEM!F214)/EEM!F214 -> -0.040383407 | R24: =(EEM!F278-EEM!F151)/EEM!F151 -> 0.032110867 | S24: =(EEM!F278-EEM!F28)/EEM!F28 -> 0.2504095
D25: AGG | F25: =IFERROR(__xludf.DUMMYFUNCTION("IF(ISBLANK(D25), ""-"", GOOGLEFINANCE(IF(ISBLANK(E25), D25, E25&"":""&D25), ""name""))"),"iShares Core US Aggregate Bond ETF") -> iShares Core US Aggregate Bond ETF | G25: 혼합채권 | H25: =IFERROR(__xludf.DUMMYFUNCTION("IF(ISBLANK(D25), 0, GOOGLEFINANCE(IF(ISBLANK(E25), D25, E25&"":""&D25), ""price""))"),97.55) -> 97.55 | I25: =IFERROR(__xludf.DUMMYFUNCTION("IF(ISBLANK(D25), 0, GOOGLEFINANCE(IF(ISBLANK(E25), D25, E25&"":""&D25), ""change""))"),-0.37) -> -0.37 | J25: =IFERROR(__xludf.DUMMYFUNCTION("IF(ISBLANK(D25), 0, GOOGLEFINANCE(IF(ISBLANK(E25), D25, E25&"":""&D25), ""changepct"")/100)"),-0.0038) -> -0.0038 | K25: 1 | L25: =K25 * H25 -> 97.55 | O25: =(P25*12)+(Q25*4)+(R25*2)+(S25*1) -> -0.35666026 | P25: =(AGG!F278-AGG!F256)/AGG!F256 -> -0.018018925 | Q25: =(AGG!F278-AGG!F214)/AGG!F214 -> -0.019006436 | R25: =(AGG!F278-AGG!F151)/AGG!F151 -> -0.027029723 | S25: =(AGG!F278-AGG!F28)/AGG!F28 -> -0.010347976
D26: QQQ | F26: =IFERROR(__xludf.DUMMYFUNCTION("IF(ISBLANK(D26), ""-"", GOOGLEFINANCE(IF(ISBLANK(E26), D26, E26&"":""&D26), ""name""))"),"Invesco QQQ Trust, Series 1") -> Invesco QQQ Trust, Series 1 | G26: 미국 주식 | H26: =IFERROR(__xludf.DUMMYFUNCTION("IF(ISBLANK(D26), 0, GOOGLEFINANCE(IF(ISBLANK(E26), D26, E26&"":""&D26), ""price""))"),661.73) -> 661.73 | I26: =IFERROR(__xludf.DUMMYFUNCTION("IF(ISBLANK(D26), 0, GOOGLEFINANCE(IF(ISBLANK(E26), D26, E26&"":""&D26), ""change""))"),-13.76) -> -13.76 | J26: =IFERROR(__xludf.DUMMYFUNCTION("IF(ISBLANK(D26), 0, GOOGLEFINANCE(IF(ISBLANK(E26), D26, E26&"":""&D26), ""changepct"")/100)"),-0.0204) -> -0.0204 | K26: 1 | L26: =K26 * H26 -> 661.73
C27: BAA 안전자산 | D27: LQD | F27: =IFERROR(__xludf.DUMMYFUNCTION("IF(ISBLANK(D27), ""-"", GOOGLEFINANCE(IF(ISBLANK(E27), D27, E27&"":""&D27), ""name""))"),"iShares iBoxx $ Inv Grade Corporate Bond ETF") -> iShares iBoxx $ Inv Grade Corporate Bond ETF | G27: 미국회사채 | H27: =IFERROR(__xludf.DUMMYFUNCTION("IF(ISBLANK(D27), 0, GOOGLEFINANCE(IF(ISBLANK(E27), D27, E27&"":""&D27), ""price""))"),106.22) -> 106.22 | I27: =IFERROR(__xludf.DUMMYFUNCTION("IF(ISBLANK(D27), 0, GOOGLEFINANCE(IF(ISBLANK(E27), D27, E27&"":""&D27), ""change""))"),-0.61) -> -0.61 | J27: =IFERROR(__xludf.DUMMYFUNCTION("IF(ISBLANK(D27), 0, GOOGLEFINANCE(IF(ISBLANK(E27), D27, E27&"":""&D27), ""changepct"")/100)"),-0.00569999999999999) -> -0.0057 | K27: 1 | L27: =K27 * H27 -> 106.22 | O27: =(P27*12)+(Q27*4)+(R27*2)+(S27*1) -> -0.58295137 | P27: =(LQD!F278-LQD!F256)/LQD!F256 -> -0.029954338 | Q27: =(LQD!F278-LQD!F214)/LQD!F214 -> -0.028090402 | R27: =(LQD!F278-LQD!F151)/LQD!F151 -> -0.042459209 | S27: =(LQD!F278-LQD!F28)/LQD!F28 -> -0.026219289 | V27: 현재가격/12개월 이동평균이 높은 3개에 투자 But,현재가격이 이동평균보다 낮으면 현금으로 보유
D28: IEF | F28: =IFERROR(__xludf.DUMMYFUNCTION("IF(ISBLANK(D28), ""-"", GOOGLEFINANCE(IF(ISBLANK(E28), D28, E28&"":""&D28), ""name""))"),"iShares 7-10 Year Treasury Bond ETF") -> iShares 7-10 Year Treasury Bond ETF | G28: 미국중기국채 | H28: =IFERROR(__xludf.DUMMYFUNCTION("IF(ISBLANK(D28), 0, GOOGLEFINANCE(IF(ISBLANK(E28), D28, E28&"":""&D28), ""price""))"),93.17) -> 93.17 | I28: =IFERROR(__xludf.DUMMYFUNCTION("IF(ISBLANK(D28), 0, GOOGLEFINANCE(IF(ISBLANK(E28), D28, E28&"":""&D28), ""change""))"),-0.39) -> -0.39 | J28: =IFERROR(__xludf.DUMMYFUNCTION("IF(ISBLANK(D28), 0, GOOGLEFINANCE(IF(ISBLANK(E28), D28, E28&"":""&D28), ""changepct"")/100)"),-0.0042) -> -0.0042 | K28: 1 | L28: =K28 * H28 -> 93.17 | O28: =(P28*12)+(Q28*4)+(R28*2)+(S28*1) -> -0.40409353 | P28: =(IEF!F278-IEF!F256)/IEF!F256 -> -0.019572766 | Q28: =(IEF!F278-IEF!F214)/IEF!F214 -> -0.022760646 | R28: =(IEF!F278-IEF!F151)/IEF!F151 -> -0.030388178 | S28: =(IEF!F278-IEF!F28)/IEF!F28 -> -0.017401392
D29: BIL | F29: =IFERROR(__xludf.DUMMYFUNCTION("IF(ISBLANK(D29), ""-"", GOOGLEFINANCE(IF(ISBLANK(E29), D29, E29&"":""&D29), ""name""))"),"State Street SPDR Bloomberg 1-3 Month T-Bill ETF") -> State Street SPDR Bloomberg 1-3 Month T-Bill ETF | G29: 미국초단기채권 | H29: =IFERROR(__xludf.DUMMYFUNCTION("IF(ISBLANK(D29), 0, GOOGLEFINANCE(IF(ISBLANK(E29), D29, E29&"":""&D29), ""price""))"),91.64) -> 91.64 | I29: =IFERROR(__xludf.DUMMYFUNCTION("IF(ISBLANK(D29), 0, GOOGLEFINANCE(IF(ISBLANK(E29), D29, E29&"":""&D29), ""change""))"),0.01) -> 0.01 | J29: =IFERROR(__xludf.DUMMYFUNCTION("IF(ISBLANK(D29), 0, GOOGLEFINANCE(IF(ISBLANK(E29), D29, E29&"":""&D29), ""changepct"")/100)"),0.0001) -> 0.0001 | K29: 1 | L29: =K29 * H29 -> 91.64 | O29: =(P29*12)+(Q29*4)+(R29*2)+(S29*1) -> 0.0021845717 | P29: =(BIL!$F$278-BIL!$F$256)/BIL!$F$256 -> 0.00010913456 | Q29: =(BIL!$F$278-BIL!$F$214)/BIL!$F$214 -> 0.00021829295 | R29: =(BIL!$F$278-BIL!$F$151)/BIL!$F$151 -> 0.00054591113 | S29: =(BIL!$F$278-BIL!$F$28)/BIL!$F$28 -> -0.0010900371
D30: TLT | F30: =IFERROR(__xludf.DUMMYFUNCTION("IF(ISBLANK(D30), ""-"", GOOGLEFINANCE(IF(ISBLANK(E30), D30, E30&"":""&D30), ""name""))"),"iShares 20+ Year Treasury Bond ETF") -> iShares 20+ Year Treasury Bond ETF | G30: 미국장기국채 | H30: =IFERROR(__xludf.DUMMYFUNCTION("IF(ISBLANK(D30), 0, GOOGLEFINANCE(IF(ISBLANK(E30), D30, E30&"":""&D30), ""price""))"),82.85) -> 82.85 | I30: =IFERROR(__xludf.DUMMYFUNCTION("IF(ISBLANK(D30), 0, GOOGLEFINANCE(IF(ISBLANK(E30), D30, E30&"":""&D30), ""change""))"),-1.39) -> -1.39 | J30: =IFERROR(__xludf.DUMMYFUNCTION("IF(ISBLANK(D30), 0, GOOGLEFINANCE(IF(ISBLANK(E30), D30, E30&"":""&D30), ""changepct"")/100)"),-0.0165) -> -0.0165 | K30: 1 | L30: =K30 * H30 -> 82.85 | O30: =(P30*12)+(Q30*4)+(R30*2)+(S30*1) -> -0.9493035 | P30: =(TLT!$F$278-TLT!$F$256)/TLT!$F$256 -> -0.051625458 | Q30: =(TLT!$F$278-TLT!$F$214)/TLT!$F$214 -> -0.039754288 | R30: =(TLT!$F$278-TLT!$F$151)/TLT!$F$151 -> -0.062252405 | S30: =(TLT!$F$278-TLT!$F$28)/TLT!$F$28 -> -0.046276045
D31: TIP | F31: =IFERROR(__xludf.DUMMYFUNCTION("IF(ISBLANK(D31), ""-"", GOOGLEFINANCE(IF(ISBLANK(E31), D31, E31&"":""&D31), ""name""))"),"iShares TIPS Bond ETF") -> iShares TIPS Bond ETF | G31: 미국물가연동채 | H31: =IFERROR(__xludf.DUMMYFUNCTION("IF(ISBLANK(D31), 0, GOOGLEFINANCE(IF(ISBLANK(E31), D31, E31&"":""&D31), ""price""))"),107.77) -> 107.77 | I31: =IFERROR(__xludf.DUMMYFUNCTION("IF(ISBLANK(D31), 0, GOOGLEFINANCE(IF(ISBLANK(E31), D31, E31&"":""&D31), ""change""))"),0.11) -> 0.11 | J31: =IFERROR(__xludf.DUMMYFUNCTION("IF(ISBLANK(D31), 0, GOOGLEFINANCE(IF(ISBLANK(E31), D31, E31&"":""&D31), ""changepct"")/100)"),0.001) -> 0.001 | K31: 1 | L31: =K31 * H31 -> 107.77 | O31: =(P31*12)+(Q31*4)+(R31*2)+(S31*1) -> -0.42049844 | P31: =(TIP!$F$278-TIP!$F$256)/TIP!$F$256 -> -0.017593437 | Q31: =(TIP!$F$278-TIP!$F$214)/TIP!$F$214 -> -0.035787778 | R31: =(TIP!$F$278-TIP!$F$151)/TIP!$F$151 -> -0.023645588 | S31: =(TIP!$F$278-TIP!$F$28)/TIP!$F$28 -> -0.018934911
D32: BND | F32: =IFERROR(__xludf.DUMMYFUNCTION("IF(ISBLANK(D32), ""-"", GOOGLEFINANCE(IF(ISBLANK(E32), D32, E32&"":""&D32), ""name""))"),"Vanguard Total Bond Market Index Fund ETF") -> Vanguard Total Bond Market Index Fund ETF | G32: 미국잡채권 | H32: =IFERROR(__xludf.DUMMYFUNCTION("IF(ISBLANK(D32), 0, GOOGLEFINANCE(IF(ISBLANK(E32), D32, E32&"":""&D32), ""price""))"),72.38) -> 72.38 | I32: =IFERROR(__xludf.DUMMYFUNCTION("IF(ISBLANK(D32), 0, GOOGLEFINANCE(IF(ISBLANK(E32), D32, E32&"":""&D32), ""change""))"),-0.26) -> -0.26 | J32: =IFERROR(__xludf.DUMMYFUNCTION("IF(ISBLANK(D32), 0, GOOGLEFINANCE(IF(ISBLANK(E32), D32, E32&"":""&D32), ""changepct"")/100)"),-0.0036) -> -0.0036 | K32: 1 | L32: =K32 * H32 -> 72.38 | O32: =(P32*12)+(Q32*4)+(R32*2)+(S32*1) -> -0.34769674 | P32: =(BND!$F$278-BND!$F$256)/BND!$F$256 -> -0.01751052 | Q32: =(BND!$F$278-BND!$F$214)/BND!$F$214 -> -0.018443179 | R32: =(BND!$F$278-BND!$F$151)/BND!$F$151 -> -0.026365348 | S32: =(BND!$F$278-BND!$F$28)/BND!$F$28 -> -0.011067086
D33: DBC | F33: =IFERROR(__xludf.DUMMYFUNCTION("IF(ISBLANK(D33), ""-"", GOOGLEFINANCE(IF(ISBLANK(E33), D33, E33&"":""&D33), ""name""))"),"Invesco DB Commodity Index Tracking Fund") -> Invesco DB Commodity Index Tracking Fund | G33: 원자재 | H33: =IFERROR(__xludf.DUMMYFUNCTION("IF(ISBLANK(D33), 0, GOOGLEFINANCE(IF(ISBLANK(E33), D33, E33&"":""&D33), ""price""))"),29.42) -> 29.42 | I33: =IFERROR(__xludf.DUMMYFUNCTION("IF(ISBLANK(D33), 0, GOOGLEFINANCE(IF(ISBLANK(E33), D33, E33&"":""&D33), ""change""))"),0.82) -> 0.82 | J33: =IFERROR(__xludf.DUMMYFUNCTION("IF(ISBLANK(D33), 0, GOOGLEFINANCE(IF(ISBLANK(E33), D33, E33&"":""&D33), ""changepct"")/100)"),0.0287) -> 0.0287 | K33: 1 | L33: =K33 * H33 -> 29.42 | O33: =(P33*12)+(Q33*4)+(R33*2)+(S33*1) -> 1.9199659 | P33: =(DBC!$F$278-DBC!$F$256)/DBC!$F$256 -> 0.10726383 | Q33: =(DBC!$F$278-DBC!$F$214)/DBC!$F$214 -> -0.022266534 | R33: =(DBC!$F$278-DBC!$F$151)/DBC!$F$151 -> 0.21119802 | S33: =(DBC!$F$278-DBC!$F$28)/DBC!$F$28 -> 0.29946996
A36: 변형듀얼모멘텀 | C36: 공격자산 | D36: SPY | F36: =IFERROR(__xludf.DUMMYFUNCTION("IF(ISBLANK(D36), ""-"", GOOGLEFINANCE(IF(ISBLANK(E36), D36, E36&"":""&D36), ""name""))"),"State Street SPDR S&P 500 ETF Trust") -> State Street SPDR S&P 500 ETF Trust | G36: 미국 주식 | H36: =IFERROR(__xludf.DUMMYFUNCTION("IF(ISBLANK(D36), 0, GOOGLEFINANCE(IF(ISBLANK(E36), D36, E36&"":""&D36), ""price""))"),729.46) -> 729.46 | I36: =IFERROR(__xludf.DUMMYFUNCTION("IF(ISBLANK(D36), 0, GOOGLEFINANCE(IF(ISBLANK(E36), D36, E36&"":""&D36), ""change""))"),-11.4) -> -11.4 | J36: =IFERROR(__xludf.DUMMYFUNCTION("IF(ISBLANK(D36), 0, GOOGLEFINANCE(IF(ISBLANK(E36), D36, E36&"":""&D36), ""changepct"")/100)"),-0.0154) -> -0.0154 | K36: 1 | L36: =K36 * H36 -> 729.46 | O36: =(P36*12)+(Q36*4)+(R36*2)+(S36*1) -> 0.34343962 | P36: =(SPY!$F$278-SPY!$F$256)/SPY!$F$256 -> 0.00064472764 | Q36: =(SPY!$F$278-SPY!$F$214)/SPY!$F$214 -> 0.019981263 | R36: =(SPY!$F$278-SPY!$F$151)/SPY!$F$151 -> 0.053022101 | S36: =(SPY!$F$278-SPY!$F$28)/SPY!$F$28 -> 0.14973363 | V36: 둘중 높은자산에 투자 But, 1년 수익이 0 이하면
D37: EFA | F37: =IFERROR(__xludf.DUMMYFUNCTION("IF(ISBLANK(D37), ""-"", GOOGLEFINANCE(IF(ISBLANK(E37), D37, E37&"":""&D37), ""name""))"),"iShares MSCI EAFE ETF") -> iShares MSCI EAFE ETF | H37: =IFERROR(__xludf.DUMMYFUNCTION("IF(ISBLANK(D37), 0, GOOGLEFINANCE(IF(ISBLANK(E37), D37, E37&"":""&D37), ""price""))"),103.37) -> 103.37 | I37: =IFERROR(__xludf.DUMMYFUNCTION("IF(ISBLANK(D37), 0, GOOGLEFINANCE(IF(ISBLANK(E37), D37, E37&"":""&D37), ""change""))"),-0.52) -> -0.52 | J37: =IFERROR(__xludf.DUMMYFUNCTION("IF(ISBLANK(D37), 0, GOOGLEFINANCE(IF(ISBLANK(E37), D37, E37&"":""&D37), ""changepct"")/100)"),-0.005) -> -0.005 | K37: 1 | L37: =K37 * H37 -> 103.37 | O37: =(P37*12)+(Q37*4)+(R37*2)+(S37*1) -> 0.40179665 | P37: =(EFA!$F$278-EFA!$F$256)/EFA!$F$256 -> 0.0080944022 | Q37: =(EFA!$F$278-EFA!$F$214)/EFA!$F$214 -> 0.019629118 | R37: =(EFA!$F$278-EFA!$F$151)/EFA!$F$151 -> 0.028864338 | S37: =(EFA!$F$278-EFA!$F$28)/EFA!$F$28 -> 0.16841867
F38: =IFERROR(__xludf.DUMMYFUNCTION("IF(ISBLANK(D38), ""-"", GOOGLEFINANCE(IF(ISBLANK(E38), D38, E38&"":""&D38), ""name""))"),"-") -> - | H38: =IFERROR(__xludf.DUMMYFUNCTION("IF(ISBLANK(D38), 0, GOOGLEFINANCE(IF(ISBLANK(E38), D38, E38&"":""&D38), ""price""))"),0) -> 0 | I38: =IFERROR(__xludf.DUMMYFUNCTION("IF(ISBLANK(D38), 0, GOOGLEFINANCE(IF(ISBLANK(E38), D38, E38&"":""&D38), ""change""))"),0) -> 0 | J38: =IFERROR(__xludf.DUMMYFUNCTION("IF(ISBLANK(D38), 0, GOOGLEFINANCE(IF(ISBLANK(E38), D38, E38&"":""&D38), ""changepct"")/100)"),0) -> 0 | L38: =K38 * H38 -> 0 | O38: =(P38*12)+(Q38*4)+(R38*2)+(S38*1) -> 0.0021845717 | P38: =(BIL!$F$278-BIL!$F$256)/BIL!$F$256 -> 0.00010913456 | Q38: =(BIL!$F$278-BIL!$F$214)/BIL!$F$214 -> 0.00021829295 | R38: =(BIL!$F$278-BIL!$F$151)/BIL!$F$151 -> 0.00054591113 | S38: =(BIL!$F$278-BIL!$F$28)/BIL!$F$28 -> -0.0010900371
C39: 안전자산 8개 채권 | D39: SHY | F39: =IFERROR(__xludf.DUMMYFUNCTION("IF(ISBLANK(D39), ""-"", GOOGLEFINANCE(IF(ISBLANK(E39), D39, E39&"":""&D39), ""name""))"),"iShares 1-3 Year Treasury Bond ETF") -> iShares 1-3 Year Treasury Bond ETF | G39: 미국단기국채 | H39: =IFERROR(__xludf.DUMMYFUNCTION("IF(ISBLANK(D39), 0, GOOGLEFINANCE(IF(ISBLANK(E39), D39, E39&"":""&D39), ""price""))"),81.99) -> 81.99 | I39: =IFERROR(__xludf.DUMMYFUNCTION("IF(ISBLANK(D39), 0, GOOGLEFINANCE(IF(ISBLANK(E39), D39, E39&"":""&D39), ""change""))"),0.05) -> 0.05 | J39: =IFERROR(__xludf.DUMMYFUNCTION("IF(ISBLANK(D39), 0, GOOGLEFINANCE(IF(ISBLANK(E39), D39, E39&"":""&D39), ""changepct"")/100)"),0.0006) -> 0.0006 | K39: 1 | L39: =K39 * H39 -> 81.99 | O39: =(P39*12)+(Q39*4)+(R39*2)+(S39*1) -> -0.083996471 | P39: =(SHY!F$278-SHY!F$256)/SHY!F$256 -> -0.0024333861 | Q39: =(SHY!F$278-SHY!F$214)/SHY!F$214 -> -0.0067837674 | R39: =(SHY!F$278-SHY!F$151)/SHY!F$151 -> -0.010619042 | S39: =(SHY!F$278-SHY!F$28)/SHY!F$28 -> -0.0064226854 | V39: 6개월 최고수익 3개 채권매수 But, 3개 채권중 0이하인 자산은 현금으로 보유
D40: IEF | F40: =IFERROR(__xludf.DUMMYFUNCTION("IF(ISBLANK(D40), ""-"", GOOGLEFINANCE(IF(ISBLANK(E40), D40, E40&"":""&D40), ""name""))"),"iShares 7-10 Year Treasury Bond ETF") -> iShares 7-10 Year Treasury Bond ETF | G40: 미국중기국채 | H40: =IFERROR(__xludf.DUMMYFUNCTION("IF(ISBLANK(D40), 0, GOOGLEFINANCE(IF(ISBLANK(E40), D40, E40&"":""&D40), ""price""))"),93.17) -> 93.17 | I40: =IFERROR(__xludf.DUMMYFUNCTION("IF(ISBLANK(D40), 0, GOOGLEFINANCE(IF(ISBLANK(E40), D40, E40&"":""&D40), ""change""))"),-0.39) -> -0.39 | J40: =IFERROR(__xludf.DUMMYFUNCTION("IF(ISBLANK(D40), 0, GOOGLEFINANCE(IF(ISBLANK(E40), D40, E40&"":""&D40), ""changepct"")/100)"),-0.0042) -> -0.0042 | K40: 1 | L40: =K40 * H40 -> 93.17 | O40: =(P40*12)+(Q40*4)+(R40*2)+(S40*1) -> -0.40409353 | P40: =(IEF!F$278-IEF!F$256)/IEF!F$256 -> -0.019572766 | Q40: =(IEF!F$278-IEF!F$214)/IEF!F$214 -> -0.022760646 | R40: =(IEF!F$278-IEF!F$151)/IEF!F$151 -> -0.030388178 | S40: =(IEF!F$278-IEF!F$28)/IEF!F$28 -> -0.017401392
D41: TLT | F41: =IFERROR(__xludf.DUMMYFUNCTION("IF(ISBLANK(D41), ""-"", GOOGLEFINANCE(IF(ISBLANK(E41), D41, E41&"":""&D41), ""name""))"),"iShares 20+ Year Treasury Bond ETF") -> iShares 20+ Year Treasury Bond ETF | G41: 미국장기국채 | H41: =IFERROR(__xludf.DUMMYFUNCTION("IF(ISBLANK(D41), 0, GOOGLEFINANCE(IF(ISBLANK(E41), D41, E41&"":""&D41), ""price""))"),82.85) -> 82.85 | I41: =IFERROR(__xludf.DUMMYFUNCTION("IF(ISBLANK(D41), 0, GOOGLEFINANCE(IF(ISBLANK(E41), D41, E41&"":""&D41), ""change""))"),-1.39) -> -1.39 | J41: =IFERROR(__xludf.DUMMYFUNCTION("IF(ISBLANK(D41), 0, GOOGLEFINANCE(IF(ISBLANK(E41), D41, E41&"":""&D41), ""changepct"")/100)"),-0.0165) -> -0.0165 | K41: 1 | L41: =K41 * H41 -> 82.85 | O41: =(P41*12)+(Q41*4)+(R41*2)+(S41*1) -> -0.9493035 | P41: =(TLT!F$278-TLT!F$256)/TLT!F$256 -> -0.051625458 | Q41: =(TLT!F$278-TLT!F$214)/TLT!F$214 -> -0.039754288 | R41: =(TLT!F$278-TLT!F$151)/TLT!F$151 -> -0.062252405 | S41: =(TLT!F$278-TLT!F$28)/TLT!F$28 -> -0.046276045
D42: TIP | F42: =IFERROR(__xludf.DUMMYFUNCTION("IF(ISBLANK(D42), ""-"", GOOGLEFINANCE(IF(ISBLANK(E42), D42, E42&"":""&D42), ""name""))"),"iShares TIPS Bond ETF") -> iShares TIPS Bond ETF | G42: 미국물가연동채 | H42: =IFERROR(__xludf.DUMMYFUNCTION("IF(ISBLANK(D42), 0, GOOGLEFINANCE(IF(ISBLANK(E42), D42, E42&"":""&D42), ""price""))"),107.77) -> 107.77 | I42: =IFERROR(__xludf.DUMMYFUNCTION("IF(ISBLANK(D42), 0, GOOGLEFINANCE(IF(ISBLANK(E42), D42, E42&"":""&D42), ""change""))"),0.11) -> 0.11 | J42: =IFERROR(__xludf.DUMMYFUNCTION("IF(ISBLANK(D42), 0, GOOGLEFINANCE(IF(ISBLANK(E42), D42, E42&"":""&D42), ""changepct"")/100)"),0.001) -> 0.001 | K42: 1 | L42: =K42 * H42 -> 107.77 | O42: =(P42*12)+(Q42*4)+(R42*2)+(S42*1) -> -0.42049844 | P42: =(TIP!$F$278-TIP!$F$256)/TIP!$F$256 -> -0.017593437 | Q42: =(TIP!$F$278-TIP!$F$214)/TIP!$F$214 -> -0.035787778 | R42: =(TIP!$F$278-TIP!$F$151)/TIP!$F$151 -> -0.023645588 | S42: =(TIP!$F$278-TIP!$F$28)/TIP!$F$28 -> -0.018934911
D43: LQD | F43: =IFERROR(__xludf.DUMMYFUNCTION("IF(ISBLANK(D43), ""-"", GOOGLEFINANCE(IF(ISBLANK(E43), D43, E43&"":""&D43), ""name""))"),"iShares iBoxx $ Inv Grade Corporate Bond ETF") -> iShares iBoxx $ Inv Grade Corporate Bond ETF | G43: 미국회사채 | H43: =IFERROR(__xludf.DUMMYFUNCTION("IF(ISBLANK(D43), 0, GOOGLEFINANCE(IF(ISBLANK(E43), D43, E43&"":""&D43), ""price""))"),106.22) -> 106.22 | I43: =IFERROR(__xludf.DUMMYFUNCTION("IF(ISBLANK(D43), 0, GOOGLEFINANCE(IF(ISBLANK(E43), D43, E43&"":""&D43), ""change""))"),-0.61) -> -0.61 | J43: =IFERROR(__xludf.DUMMYFUNCTION("IF(ISBLANK(D43), 0, GOOGLEFINANCE(IF(ISBLANK(E43), D43, E43&"":""&D43), ""changepct"")/100)"),-0.00569999999999999) -> -0.0057 | K43: 1 | L43: =K43 * H43 -> 106.22 | O43: =(P43*12)+(Q43*4)+(R43*2)+(S43*1) -> -0.58295137 | P43: =(LQD!F278-LQD!F256)/LQD!F256 -> -0.029954338 | Q43: =(LQD!F$278-LQD!F$214)/LQD!F$214 -> -0.028090402 | R43: =(LQD!F$278-LQD!F$151)/LQD!F$151 -> -0.042459209 | S43: =(LQD!F$278-LQD!F$28)/LQD!F$28 -> -0.026219289
D44: HYG | F44: =IFERROR(__xludf.DUMMYFUNCTION("IF(ISBLANK(D44), ""-"", GOOGLEFINANCE(IF(ISBLANK(E44), D44, E44&"":""&D44), ""name""))"),"iShares iBoxx $ High Yield Corporate Bond ETF") -> iShares iBoxx $ High Yield Corporate Bond ETF | G44: 미국하이일드 | H44: =IFERROR(__xludf.DUMMYFUNCTION("IF(ISBLANK(D44), 0, GOOGLEFINANCE(IF(ISBLANK(E44), D44, E44&"":""&D44), ""price""))"),79.24) -> 79.24 | I44: =IFERROR(__xludf.DUMMYFUNCTION("IF(ISBLANK(D44), 0, GOOGLEFINANCE(IF(ISBLANK(E44), D44, E44&"":""&D44), ""change""))"),-0.18) -> -0.18 | J44: =IFERROR(__xludf.DUMMYFUNCTION("IF(ISBLANK(D44), 0, GOOGLEFINANCE(IF(ISBLANK(E44), D44, E44&"":""&D44), ""changepct"")/100)"),-0.0023) -> -0.0023 | K44: 1 | L44: =K44 * H44 -> 79.24 | O44: =(P44*12)+(Q44*4)+(R44*2)+(S44*1) -> -0.21315027 | P44: =(HYG!F$278-HYG!F$256)/HYG!F$256 -> -0.0073907052 | Q44: =(HYG!F$278-HYG!F$214)/HYG!F$214 -> -0.015774438 | R44: =(HYG!F$278-HYG!F$151)/HYG!F$151 -> -0.023897512 | S44: =(HYG!F$278-HYG!F$28)/HYG!F$28 -> -0.013569028
...

Sheet BD
B1: 현재가 | C1: =TODAY()-1 -> 46232 | D1: =EDATE($C$1,-1) -> 46202 | E1: =EDATE($C$1,-2) -> 46171 | F1: =EDATE($C$1,-3) -> 46141 | G1: =EDATE($C$1,-4) -> 46110 | H1: =EDATE($C$1,-5) -> 46081 | I1: =EDATE($C$1,-6) -> 46051 | J1: =EDATE($C$1,-7) -> 46020 | K1: =EDATE($C$1,-8) -> 45990 | L1: =EDATE($C$1,-9) -> 45959 | M1: =EDATE($C$1,-10) -> 45929 | N1: =EDATE($C$1,-11) -> 45898 | O1: =TODAY()-362 -> 45871
A3: ㅣBAA중도형_공격자산 12종목
A4: 구간 | B4: 현재 | C4: 전 날 | D4: 1개월 전 | E4: 2개월 전 | F4: 3개월 전 | G4: 4개월 전 | H4: 5개월 전 | I4: 6개월 전 | J4: 7개월 전 | K4: 8개월 전 | L4: 9개월 전 | M4: 10개월 전 | N4: 11개월 전 | O4: 12개월 전 | P4: 12개월 이동평균 | Q4: 현재가격/12개월 이동평균 | R4: 1개월 수익률 | S4: 3개월 수익률 | T4: 6개월 수익률 | U4: 최근 1년 수익률 | V4: 1개월 수익률*12 | W4: 3개월 수익률*4 | X4: 6개월 수익률*2 | Y4: 12개월 수익률*1 | Z4: 모멘텀 스코어
A5: =관심종목!D10 -> SPY | B5: =관심종목!H10 -> 729.46 | C5: =VLOOKUP(C1,SPY!$B$27:$G$278,5,1) -> 740.86 | D5: =VLOOKUP(D1,SPY!$B$27:$G$278,5,1) -> 728.99 | E5: =VLOOKUP(E1,SPY!$B$27:$G$278,5,1) -> 754.6 | F5: =VLOOKUP(F1,SPY!$B$27:$G$278,5,1) -> 711.69 | G5: =VLOOKUP(G1,SPY!$B$27:$G$278,5,1) -> 634.09 | H5: =VLOOKUP(H1,SPY!$B$27:$G$278,5,1) -> 685.99 | I5: =VLOOKUP(I1,SPY!$B$27:$G$278,5,1) -> 695.42 | J5: =VLOOKUP(J1,SPY!$B$27:$G$278,5,1) -> 690.31 | ... O5: =VLOOKUP(O1,SPY!$B$27:$G$278,5,1) -> 621.72 | P5: =AVERAGE(D5:O5) -> 683.66667 | Q5: =B5/P5 -> 1.066982 | R5: =(B5/D5)-1 -> 0.00064472764 | S5: =(B5/F5)-1 -> 0.024968736 | T5: =(B5/I5)-1 -> 0.048948837 | U5: =(B5/O5)-1 -> 0.17329344 | V5: =R5*12 -> 0.0077367316 | W5: =S5*4 -> 0.099874946 | X5: =T5*2 -> 0.097897673 | Y5: =U5*1 -> 0.17329344 | Z5: =SUM(V5:Y5) -> 0.37880279
A6: =관심종목!D11 -> QQQ | B6: =관심종목!H11 -> 661.73 | C6: =VLOOKUP(C1,QQQ!$B$27:$G$278,5,1) -> 218.24 | D6: =VLOOKUP(D1,QQQ!$B$27:$G$278,5,1) -> 218.24 | E6: =VLOOKUP(E1,QQQ!$B$27:$G$278,5,1) -> 218.24 | F6: =VLOOKUP(F1,QQQ!$B$27:$G$278,5,1) -> 218.24 | G6: =VLOOKUP(G1,QQQ!$B$27:$G$278,5,1) -> 218.24 | H6: =VLOOKUP(H1,QQQ!$B$27:$G$278,5,1) -> 218.24 | I6: =VLOOKUP(I1,QQQ!$B$27:$G$278,5,1) -> 218.24 | J6: =VLOOKUP(J1,QQQ!$B$27:$G$278,5,1) -> 218.24 | ... O6: =VLOOKUP(O1,QQQ!$B$27:$G$278,5,1) -> 218.24 | P6: =AVERAGE(D6:O6) -> 218.24 | Q6: =B6/P6 -> 3.0321206 | R6: =(B6/D6)-1 -> 2.0321206 | S6: =(B6/F6)-1 -> 2.0321206 | T6: =(B6/I6)-1 -> 2.0321206 | U6: =(B6/O6)-1 -> 2.0321206 | V6: =R6*12 -> 24.385447 | W6: =S6*4 -> 8.1284824 | X6: =T6*2 -> 4.0642412 | Y6: =U6*1 -> 2.0321206 | Z6: =SUM(V6:Y6) -> 38.610291
A7: =관심종목!D12 -> IWM | B7: =관심종목!H12 -> 288.57 | C7: =VLOOKUP(C1,IWM!$B$27:$G$278,5,1) -> 293.37 | D7: =VLOOKUP(D1,IWM!$B$27:$G$278,5,1) -> 299.83 | E7: =VLOOKUP(E1,IWM!$B$27:$G$278,5,1) -> 292.03 | F7: =VLOOKUP(F1,IWM!$B$27:$G$278,5,1) -> 273.91 | G7: =VLOOKUP(G1,IWM!$B$27:$G$278,5,1) -> 243.1 | H7: =VLOOKUP(H1,IWM!$B$27:$G$278,5,1) -> 261.41 | I7: =VLOOKUP(I1,IWM!$B$27:$G$278,5,1) -> 263.3 | J7: =VLOOKUP(J1,IWM!$B$27:$G$278,5,1) -> 251.42 | ... O7: =VLOOKUP(O1,IWM!$B$27:$G$278,5,1) -> 214.92 | P7: =AVERAGE(D7:O7) -> 256.26583 | Q7: =B7/P7 -> 1.1260573 | R7: =(B7/D7)-1 -> -0.037554614 | S7: =(B7/F7)-1 -> 0.05352123 | T7: =(B7/I7)-1 -> 0.095974174 | U7: =(B7/O7)-1 -> 0.34268565 | V7: =R7*12 -> -0.45065537 | W7: =S7*4 -> 0.21408492 | X7: =T7*2 -> 0.19194835 | Y7: =U7*1 -> 0.34268565 | Z7: =SUM(V7:Y7) -> 0.29806355
A8: =관심종목!D13 -> VGK | B8: =관심종목!H13 -> 88.86 | C8: =VLOOKUP(C1,VGK!$B$27:$G$278,5,1) -> 89.23 | D8: =VLOOKUP(D1,VGK!$B$27:$G$278,5,1) -> 87.13 | E8: =VLOOKUP(E1,VGK!$B$27:$G$278,5,1) -> 89.03 | F8: =VLOOKUP(F1,VGK!$B$27:$G$278,5,1) -> 86.16 | G8: =VLOOKUP(G1,VGK!$B$27:$G$278,5,1) -> 79.45 | H8: =VLOOKUP(H1,VGK!$B$27:$G$278,5,1) -> 90.17 | I8: =VLOOKUP(I1,VGK!$B$27:$G$278,5,1) -> 87.85 | J8: =VLOOKUP(J1,VGK!$B$27:$G$278,5,1) -> 83.97 | ... O8: =VLOOKUP(O1,VGK!$B$27:$G$278,5,1) -> 75.26 | P8: =AVERAGE(D8:O8) -> 83.32 | Q8: =B8/P8 -> 1.0664906 | R8: =(B8/D8)-1 -> 0.019855388 | S8: =(B8/F8)-1 -> 0.031337047 | T8: =(B8/I8)-1 -> 0.01149687 | U8: =(B8/O8)-1 -> 0.18070688 | V8: =R8*12 -> 0.23826466 | W8: =S8*4 -> 0.12534819 | X8: =T8*2 -> 0.022993739 | Y8: =U8*1 -> 0.18070688 | Z8: =SUM(V8:Y8) -> 0.56731347
A9: =관심종목!D14 -> EWJ | B9: =관심종목!H14 -> 89.35 | C9: =VLOOKUP(C1,EWJ!$B$27:$G$278,5,1) -> 89.83 | D9: =VLOOKUP(D1,EWJ!$B$27:$G$278,5,1) -> 92.8 | E9: =VLOOKUP(E1,EWJ!$B$27:$G$278,5,1) -> 92.7 | F9: =VLOOKUP(F1,EWJ!$B$27:$G$278,5,1) -> 87.56 | G9: =VLOOKUP(G1,EWJ!$B$27:$G$278,5,1) -> 81.43 | H9: =VLOOKUP(H1,EWJ!$B$27:$G$278,5,1) -> 92.37 | I9: =VLOOKUP(I1,EWJ!$B$27:$G$278,5,1) -> 85.21 | J9: =VLOOKUP(J1,EWJ!$B$27:$G$278,5,1) -> 80.97 | ... O9: =VLOOKUP(O1,EWJ!$B$27:$G$278,5,1) -> 74.07 | P9: =AVERAGE(D9:O9) -> 84.481667 | Q9: =B9/P9 -> 1.0576259 | R9: =(B9/D9)-1 -> -0.037176724 | S9: =(B9/F9)-1 -> 0.020443125 | T9: =(B9/I9)-1 -> 0.048585847 | U9: =(B9/O9)-1 -> 0.20629135 | V9: =R9*12 -> -0.44612069 | W9: =S9*4 -> 0.081772499 | X9: =T9*2 -> 0.097171693 | Y9: =U9*1 -> 0.20629135 | Z9: =SUM(V9:Y9) -> -0.060885151
A10: =관심종목!D15 -> VWO | B10: =관심종목!H15 -> 56.92 | C10: =VLOOKUP(C1,VWO!$B$27:$G$278,5,1) -> 57.74 | D10: =VLOOKUP(D1,VWO!$B$27:$G$278,5,1) -> 58.58 | E10: =VLOOKUP(E1,VWO!$B$27:$G$278,5,1) -> 59.9 | F10: =VLOOKUP(F1,VWO!$B$27:$G$278,5,1) -> 58.32 | G10: =VLOOKUP(G1,VWO!$B$27:$G$278,5,1) -> 52.49 | H10: =VLOOKUP(H1,VWO!$B$27:$G$278,5,1) -> 58.1 | I10: =VLOOKUP(I1,VWO!$B$27:$G$278,5,1) -> 57.86 | J10: =VLOOKUP(J1,VWO!$B$27:$G$278,5,1) -> 54.02 | ... O10: =VLOOKUP(O1,VWO!$B$27:$G$278,5,1) -> 49.54 | P10: =AVERAGE(D10:O10) -> 55.329167 | Q10: =B10/P10 -> 1.0287522 | R10: =(B10/D10)-1 -> -0.028337316 | S10: =(B10/F10)-1 -> -0.024005487 | T10: =(B10/I10)-1 -> -0.016246111 | U10: =(B10/O10)-1 -> 0.14897053 | V10: =R10*12 -> -0.3400478 | W10: =S10*4 -> -0.096021948 | X10: =T10*2 -> -0.032492223 | Y10: =U10*1 -> 0.14897053 | Z10: =SUM(V10:Y10) -> -0.31959144
A11: =관심종목!D16 -> VEA | B11: =관심종목!H16 -> 68.95 | C11: =VLOOKUP(C1,VEA!$B$27:$G$278,5,1) -> 69.6 | D11: =VLOOKUP(D1,VEA!$B$27:$G$278,5,1) -> 70.56 | E11: =VLOOKUP(E1,VEA!$B$27:$G$278,5,1) -> 71.66 | F11: =VLOOKUP(F1,VEA!$B$27:$G$278,5,1) -> 67.73 | G11: =VLOOKUP(G1,VEA!$B$27:$G$278,5,1) -> 62.05 | H11: =VLOOKUP(H1,VEA!$B$27:$G$278,5,1) -> 70.24 | I11: =VLOOKUP(I1,VEA!$B$27:$G$278,5,1) -> #N/A | J11: =VLOOKUP(J1,VEA!$B$27:$G$278,5,1) -> #N/A | ... O11: =VLOOKUP(O1,VEA!$B$27:$G$278,5,1) -> #N/A | P11: =AVERAGE(D11:O11) -> #N/A | Q11: =B11/P11 -> #N/A | R11: =(B11/D11)-1 -> -0.02281746 | S11: =(B11/F11)-1 -> 0.018012697 | T11: =(B11/I11)-1 -> #N/A | U11: =(B11/O11)-1 -> #N/A | V11: =R11*12 -> -0.27380952 | W11: =S11*4 -> 0.07205079 | X11: =T11*2 -> #N/A | Y11: =U11*1 -> #N/A | Z11: =SUM(V11:Y11) -> #N/A
A12: =관심종목!D17 -> VNQ | B12: =관심종목!H17 -> 100.66 | C12: =VLOOKUP(C1,VNQ!$B$27:$G$278,5,1) -> 100.95 | D12: =VLOOKUP(D1,VNQ!$B$27:$G$278,5,1) -> 98.67 | E12: =VLOOKUP(E1,VNQ!$B$27:$G$278,5,1) -> 96.55 | F12: =VLOOKUP(F1,VNQ!$B$27:$G$278,5,1) -> 95.65 | G12: =VLOOKUP(G1,VNQ!$B$27:$G$278,5,1) -> 87 | H12: =VLOOKUP(H1,VNQ!$B$27:$G$278,5,1) -> 95.69 | I12: =VLOOKUP(I1,VNQ!$B$27:$G$278,5,1) -> 89.46 | J12: =VLOOKUP(J1,VNQ!$B$27:$G$278,5,1) -> 88.86 | ... O12: =VLOOKUP(O1,VNQ!$B$27:$G$278,5,1) -> 88.92 | P12: =AVERAGE(D12:O12) -> 92.1475 | Q12: =B12/P12 -> 1.0923791 | R12: =(B12/D12)-1 -> 0.020168238 | S12: =(B12/F12)-1 -> 0.052378463 | T12: =(B12/I12)-1 -> 0.12519562 | U12: =(B12/O12)-1 -> 0.13202879 | V12: =R12*12 -> 0.24201885 | W12: =S12*4 -> 0.20951385 | X12: =T12*2 -> 0.25039124 | Y12: =U12*1 -> 0.13202879 | Z12: =SUM(V12:Y12) -> 0.83395273
A13: =관심종목!D18 -> DBC | B13: =관심종목!H18 -> 29.42 | C13: =VLOOKUP(C1,DBC!$B$27:$G$278,5,1) -> 28.6 | D13: =VLOOKUP(D1,DBC!$B$27:$G$278,5,1) -> 26.57 | E13: =VLOOKUP(E1,DBC!$B$27:$G$278,5,1) -> 29.72 | F13: =VLOOKUP(F1,DBC!$B$27:$G$278,5,1) -> 30.34 | G13: =VLOOKUP(G1,DBC!$B$27:$G$278,5,1) -> 29.1 | H13: =VLOOKUP(H1,DBC!$B$27:$G$278,5,1) -> 25.1 | I13: =VLOOKUP(I1,DBC!$B$27:$G$278,5,1) -> 24.94 | J13: =VLOOKUP(J1,DBC!$B$27:$G$278,5,1) -> 22.7 | ... O13: =VLOOKUP(O1,DBC!$B$27:$G$278,5,1) -> 22.09 | P13: =AVERAGE(D13:O13) -> 25.1 | Q13: =B13/P13 -> 1.1721116 | R13: =(B13/D13)-1 -> 0.10726383 | S13: =(B13/F13)-1 -> -0.030323006 | T13: =(B13/I13)-1 -> 0.17963111 | U13: =(B13/O13)-1 -> 0.33182435 | V13: =R13*12 -> 1.287166 | W13: =S13*4 -> -0.12129202 | X13: =T13*2 -> 0.35926223 | Y13: =U13*1 -> 0.33182435 | Z13: =SUM(V13:Y13) -> 1.8569605
A14: =관심종목!D19 -> GLD | B14: =관심종목!H19 -> 371.08 | C14: =VLOOKUP(C1,GLD!$B$27:$G$278,5,1) -> 369.37 | D14: =VLOOKUP(D1,GLD!$B$27:$G$278,5,1) -> 373.63 | E14: =VLOOKUP(E1,GLD!$B$27:$G$278,5,1) -> 412.77 | F14: =VLOOKUP(F1,GLD!$B$27:$G$278,5,1) -> 421.91 | G14: =VLOOKUP(G1,GLD!$B$27:$G$278,5,1) -> 414.7 | H14: =VLOOKUP(H1,GLD!$B$27:$G$278,5,1) -> 483.75 | I14: =VLOOKUP(I1,GLD!$B$27:$G$278,5,1) -> 494.56 | J14: =VLOOKUP(J1,GLD!$B$27:$G$278,5,1) -> 416.74 | ... O14: =VLOOKUP(O1,GLD!$B$27:$G$278,5,1) -> 309.11 | P14: =AVERAGE(D14:O14) -> 395.1 | Q14: =B14/P14 -> 0.93920526 | R14: =(B14/D14)-1 -> -0.0068249338 | S14: =(B14/F14)-1 -> -0.12047593 | T14: =(B14/I14)-1 -> -0.24967648 | U14: =(B14/O14)-1 -> 0.20047879 | V14: =R14*12 -> -0.081899205 | W14: =S14*4 -> -0.48190372 | X14: =T14*2 -> -0.49935296 | Y14: =U14*1 -> 0.20047879 | Z14: =SUM(V14:Y14) -> -0.86267709
A15: =관심종목!D20 -> LQD | B15: =관심종목!H20 -> 106.22 | C15: =VLOOKUP(C1,LQD!$B$27:$G$278,5,1) -> 106.83 | D15: =VLOOKUP(D1,LQD!$B$27:$G$278,5,1) -> 109.5 | E15: =VLOOKUP(E1,LQD!$B$27:$G$278,5,1) -> 109.26 | F15: =VLOOKUP(F1,LQD!$B$27:$G$278,5,1) -> 109.34 | G15: =VLOOKUP(G1,LQD!$B$27:$G$278,5,1) -> 107.62 | H15: =VLOOKUP(H1,LQD!$B$27:$G$278,5,1) -> 111.68 | I15: =VLOOKUP(I1,LQD!$B$27:$G$278,5,1) -> 110.65 | J15: =VLOOKUP(J1,LQD!$B$27:$G$278,5,1) -> 110.64 | ... O15: =VLOOKUP(O1,LQD!$B$27:$G$278,5,1) -> 109.63 | P15: =AVERAGE(D15:O15) -> 110.37583 | Q15: =B15/P15 -> 0.96234834 | R15: =(B15/D15)-1 -> -0.029954338 | S15: =(B15/F15)-1 -> -0.028534845 | T15: =(B15/I15)-1 -> -0.04003615 | U15: =(B15/O15)-1 -> -0.031104625 | V15: =R15*12 -> -0.35945205 | W15: =S15*4 -> -0.11413938 | X15: =T15*2 -> -0.0800723 | Y15: =U15*1 -> -0.031104625 | Z15: =SUM(V15:Y15) -> -0.58476836
A16: =관심종목!D21 -> HYG | B16: =관심종목!H21 -> 79.24 | C16: =VLOOKUP(C1,HYG!$B$27:$G$278,5,1) -> 79.42 | D16: =VLOOKUP(D1,HYG!$B$27:$G$278,5,1) -> 79.83 | E16: =VLOOKUP(E1,HYG!$B$27:$G$278,5,1) -> 80.23 | F16: =VLOOKUP(F1,HYG!$B$27:$G$278,5,1) -> 80.4 | G16: =VLOOKUP(G1,HYG!$B$27:$G$278,5,1) -> 78.72 | H16: =VLOOKUP(H1,HYG!$B$27:$G$278,5,1) -> 80.72 | I16: =VLOOKUP(I1,HYG!$B$27:$G$278,5,1) -> 81.04 | J16: =VLOOKUP(J1,HYG!$B$27:$G$278,5,1) -> 80.6 | ... O16: =VLOOKUP(O1,HYG!$B$27:$G$278,5,1) -> 79.98 | P16: =AVERAGE(D16:O16) -> 80.483333 | Q16: =B16/P16 -> 0.98455167 | R16: =(B16/D16)-1 -> -0.0073907052 | S16: =(B16/F16)-1 -> -0.014427861 | T16: =(B16/I16)-1 -> -0.022211254 | U16: =(B16/O16)-1 -> -0.0092523131 | V16: =R16*12 -> -0.088688463 | W16: =S16*4 -> -0.057711443 | X16: =T16*2 -> -0.044422507 | Y16: =U16*1 -> -0.0092523131 | Z16: =SUM(V16:Y16) -> -0.20007473
A17: ㅣBAA중도형_안전자산
A18: 구간 | B18: 현재 | C18: 전 날 | D18: 1개월 전 | E18: 2개월 전 | F18: 3개월 전 | G18: 4개월 전 | H18: 5개월 전 | I18: 6개월 전 | J18: 7개월 전 | K18: 8개월 전 | L18: 9개월 전 | M18: 10개월 전 | N18: 11개월 전 | O18: 12개월 전 | P18: 12개월 이동평균 | Q18: 현재가격/12개월 이동평균 | R18: 1개월 수익률 | S18: 3개월 수익률 | T18: 6개월 수익률 | U18: 최근 1년 수익률 | V18: 1개월 수익률*12 | W18: 3개월 수익률*4 | X18: 6개월 수익률*2 | Y18: 12개월 수익률*1 | Z18: 모멘텀 스코어
A19: =관심종목!D27 -> LQD | B19: =관심종목!H27 -> 106.22 | C19: =VLOOKUP(C1,LQD!$B$27:$G$278,5,1) -> 106.83 | D19: =VLOOKUP($D$1,LQD!$B$27:$G$278,5,1) -> 109.5 | E19: =VLOOKUP(E1,LQD!$B$27:$G$278,5,1) -> 109.26 | F19: =VLOOKUP(F1,LQD!$B$27:$G$278,5,1) -> 109.34 | G19: =VLOOKUP(G1,LQD!$B$27:$G$278,5,1) -> 107.62 | H19: =VLOOKUP(H1,LQD!$B$27:$G$278,5,1) -> 111.68 | I19: =VLOOKUP(I1,LQD!$B$27:$G$278,5,1) -> 110.65 | J19: =VLOOKUP(J1,LQD!$B$27:$G$278,5,1) -> 110.64 | K19: =VLOOKUP(K1,LQD!$B$27:$G$278,5,1) -> 111.86 | L19: =VLOOKUP(L1,LQD!$B$27:$G$278,5,1) -> 112.92 | ... O19: =VLOOKUP(O1,LQD!$B$27:$G$278,5,1) -> 109.63 | P19: =AVERAGE(D19:O19) -> 110.37583 | Q19: =B19/P19 -> 0.96234834 | R19: =(B19/D19)-1 -> -0.029954338 | S19: =(B19/F19)-1 -> -0.028534845 | T19: =(B19/I19)-1 -> -0.04003615 | U19: =(B19/O19)-1 -> -0.031104625 | V19: =R19*12 -> -0.35945205 | W19: =S19*12 -> -0.34241815 | X19: =T19*2 -> -0.0800723 | Y19: =U19*1 -> -0.031104625 | Z19: =SUM(V19:Y19) -> -0.81304712
A20: =관심종목!D28 -> IEF | B20: =관심종목!H28 -> 93.17 | C20: =VLOOKUP(C1,IEF!$B$27:$G$278,5,1) -> 93.56 | D20: =VLOOKUP(D1,IEF!$B$27:$G$278,5,1) -> 95.03 | E20: =VLOOKUP(E1,IEF!$B$27:$G$278,5,1) -> 94.54 | F20: =VLOOKUP(F1,IEF!$B$27:$G$278,5,1) -> 95.25 | G20: =VLOOKUP(G1,IEF!$B$27:$G$278,5,1) -> 94.6 | H20: =VLOOKUP(H1,IEF!$B$27:$G$278,5,1) -> 97.99 | I20: =VLOOKUP(I1,IEF!$B$27:$G$278,5,1) -> 95.9 | J20: =VLOOKUP(J1,IEF!$B$27:$G$278,5,1) -> 96.44 | ... O20: =VLOOKUP(O1,IEF!$B$27:$G$278,5,1) -> 95.68 | P20: =AVERAGE(A20:N20) -> 95.693077 | Q20: =B20/P20 -> 0.97363365 | R20: =(B20/D20)-1 -> -0.019572766 | S20: =(B20/F20)-1 -> -0.02183727 | T20: =(B20/I20)-1 -> -0.028467153 | U20: =(B20/O20)-1 -> -0.026233278 | V20: =R20*12 -> -0.2348732 | W20: =S20*4 -> -0.087349081 | X20: =T20*2 -> -0.056934307 | Y20: =U20*1 -> -0.026233278 | Z20: =SUM(V20:Y20) -> -0.40538986
A21: =관심종목!D29 -> BIL | B21: =관심종목!H29 -> 91.64 | C21: =VLOOKUP(C1,BIL!$B$27:$G$278,5,1) -> 91.63 | D21: =VLOOKUP(D1,BIL!$B$27:$G$278,5,1) -> 91.63 | E21: =VLOOKUP(E1,BIL!$B$27:$G$278,5,1) -> 91.63 | F21: =VLOOKUP(F1,BIL!$B$27:$G$278,5,1) -> 91.63 | G21: =VLOOKUP(G1,BIL!$B$27:$G$278,5,1) -> 91.63 | H21: =VLOOKUP(H1,BIL!$B$27:$G$278,5,1) -> 91.62 | I21: =VLOOKUP(I1,BIL!$B$27:$G$278,5,1) -> 91.61 | J21: =VLOOKUP(J1,BIL!$B$27:$G$278,5,1) -> 91.36 | ... O21: =VLOOKUP(O1,BIL!$B$27:$G$278,5,1) -> 91.47 | P21: =AVERAGE(A21:N21) -> 91.636923 | Q21: =B21/P21 -> 1.0000336 | R21: =(B21/D21)-1 -> 0.00010913456 | S21: =(B21/F21)-1 -> 0.00010913456 | T21: =(B21/I21)-1 -> 0.00032747517 | U21: =(B21/O21)-1 -> 0.0018585329 | V21: =R21*12 -> 0.0013096148 | W21: =S21*4 -> 0.00043653825 | X21: =T21*2 -> 0.00065495033 | Y21: =U21*1 -> 0.0018585329 | Z21: =SUM(V21:Y21) -> 0.0042596362
A22: =관심종목!D30 -> TLT | B22: =관심종목!H30 -> 82.85 | C22: =VLOOKUP(C1,TLT!$B$27:$G$278,5,1) -> 84.24 | D22: =VLOOKUP(D1,TLT!$B$27:$G$278,5,1) -> 87.36 | E22: =VLOOKUP(E1,TLT!$B$27:$G$278,5,1) -> 85.74 | F22: =VLOOKUP(F1,TLT!$B$27:$G$278,5,1) -> 86.37 | G22: =VLOOKUP(G1,TLT!$B$27:$G$278,5,1) -> 85.64 | H22: =VLOOKUP(H1,TLT!$B$27:$G$278,5,1) -> 90.82 | I22: =VLOOKUP(I1,TLT!$B$27:$G$278,5,1) -> 87.6 | J22: =VLOOKUP(J1,TLT!$B$27:$G$278,5,1) -> 87.74 | ... O22: =VLOOKUP(O1,TLT!$B$27:$G$278,5,1) -> 87.82 | P22: =AVERAGE(A22:N22) -> 87.439231 | Q22: =B22/P22 -> 0.9475152 | R22: =(B22/D22)-1 -> -0.051625458 | S22: =(B22/F22)-1 -> -0.040754892 | T22: =(B22/I22)-1 -> -0.054223744 | U22: =(B22/O22)-1 -> -0.056593031 | V22: =R22*12 -> -0.61950549 | W22: =S22*4 -> -0.16301957 | X22: =T22*2 -> -0.10844749 | Y22: =U22*1 -> -0.056593031 | Z22: =SUM(V22:Y22) -> -0.94756558
A23: =관심종목!D31 -> TIP | B23: =관심종목!H31 -> 107.77 | C23: =VLOOKUP(C1,TIP!$B$27:$G$278,5,1) -> 107.66 | D23: =VLOOKUP(D1,TIP!$B$27:$G$278,5,1) -> 109.7 | E23: =VLOOKUP(E1,TIP!$B$27:$G$278,5,1) -> 111.18 | F23: =VLOOKUP(F1,TIP!$B$27:$G$278,5,1) -> 111.73 | G23: =VLOOKUP(G1,TIP!$B$27:$G$278,5,1) -> 109.67 | H23: =VLOOKUP(H1,TIP!$B$27:$G$278,5,1) -> 111.88 | I23: =VLOOKUP(I1,TIP!$B$27:$G$278,5,1) -> 110.44 | J23: =VLOOKUP(J1,TIP!$B$27:$G$278,5,1) -> 110.05 | ... O23: =VLOOKUP(O1,TIP!$B$27:$G$278,5,1) -> 110.17 | P23: =AVERAGE(A23:N23) -> 110.44385 | Q23: =B23/P23 -> 0.97578999 | R23: =(B23/D23)-1 -> -0.017593437 | S23: =(B23/F23)-1 -> -0.035442585 | T23: =(B23/I23)-1 -> -0.024176023 | U23: =(B23/O23)-1 -> -0.021784515 | V23: =R23*12 -> -0.21112124 | W23: =S23*4 -> -0.14177034 | X23: =T23*2 -> -0.048352046 | Y23: =U23*1 -> -0.021784515 | Z23: =SUM(V23:Y23) -> -0.42302814
A24: =관심종목!D32 -> BND | B24: =관심종목!H32 -> 72.38 | C24: =VLOOKUP(C1,BND!$B$27:$G$278,5,1) -> 72.64 | D24: =VLOOKUP(D1,BND!$B$27:$G$278,5,1) -> 73.67 | E24: =VLOOKUP(E1,BND!$B$27:$G$278,5,1) -> 73.42 | F24: =VLOOKUP(F1,BND!$B$27:$G$278,5,1) -> 73.72 | G24: =VLOOKUP(G1,BND!$B$27:$G$278,5,1) -> 73.11 | H24: =VLOOKUP(H1,BND!$B$27:$G$278,5,1) -> 75.17 | I24: =VLOOKUP(I1,BND!$B$27:$G$278,5,1) -> 74.25 | J24: =VLOOKUP(J1,BND!$B$27:$G$278,5,1) -> 74.19 | ... O24: =VLOOKUP(O1,BND!$B$27:$G$278,5,1) -> 73.59 | P24: =AVERAGE(A24:N24) -> 73.886923 | Q24: =B24/P24 -> 0.97960501 | R24: =(B24/D24)-1 -> -0.01751052 | S24: =(B24/F24)-1 -> -0.018176886 | T24: =(B24/I24)-1 -> -0.025185185 | U24: =(B24/O24)-1 -> -0.016442451 | V24: =R24*12 -> -0.21012624 | W24: =S24*4 -> -0.072707542 | X24: =T24*2 -> -0.05037037 | Y24: =U24*1 -> -0.016442451 | Z24: =SUM(V24:Y24) -> -0.3496466
A25: =관심종목!D33 -> DBC | B25: =관심종목!H33 -> 29.42 | C25: =VLOOKUP(C1,DBC!$B$27:$G$278,5,1) -> 28.6 | D25: =VLOOKUP(D1,DBC!$B$27:$G$278,5,1) -> 26.57 | E25: =VLOOKUP(E1,DBC!$B$27:$G$278,5,1) -> 29.72 | F25: =VLOOKUP(F1,DBC!$B$27:$G$278,5,1) -> 30.34 | G25: =VLOOKUP(G1,DBC!$B$27:$G$278,5,1) -> 29.1 | H25: =VLOOKUP(H1,DBC!$B$27:$G$278,5,1) -> 25.1 | I25: =VLOOKUP(I1,DBC!$B$27:$G$278,5,1) -> 24.94 | J25: =VLOOKUP(J1,DBC!$B$27:$G$278,5,1) -> 22.7 | ... O25: =VLOOKUP(O1,DBC!$B$27:$G$278,5,1) -> 22.09 | P25: =AVERAGE(A25:N25) -> 25.933077 | Q25: =B25/P25 -> 1.1344585 | R25: =(B25/D25)-1 -> 0.10726383 | S25: =(B25/F25)-1 -> -0.030323006 | T25: =(B25/I25)-1 -> 0.17963111 | U25: =(B25/O25)-1 -> 0.33182435 | V25: =R25*12 -> 1.287166 | W25: =S25*4 -> -0.12129202 | X25: =T25*2 -> 0.35926223 | Y25: =U25*1 -> 0.33182435 | Z25: =SUM(V25:Y25) -> 1.8569605
A27: ㅣ카나리아 자산군
B28: 현재 | C28: 전 날 | D28: 1개월 전 | E28: 2개월 전 | F28: 3개월 전 | G28: 4개월 전 | H28: 5개월 전 | I28: 6개월 전 | J28: 7개월 전 | K28: 8개월 전 | L28: 9개월 전 | M28: 10개월 전 | N28: 11개월 전 | O28: 12개월 전 | P28: 12개월 이동평균 | Q28: 현재가격/12개월 이동평균 | R28: 1개월 수익률 | S28: 3개월 수익률 | T28: 6개월 수익률 | U28: 최근 1년 수익률 | V28: 1개월 수익률*12 | W28: 3개월 수익률*4 | X28: 6개월 수익률*2 | Y28: 12개월 수익률*1 | Z28: 모멘텀 스코어
A29: SPY | B29: =관심종목!H22 -> 729.46 | C29: =VLOOKUP(C1,SPY!$B$27:$G$278,5,1) -> 740.86 | D29: =VLOOKUP(D1,SPY!$B$27:$G$278,5,1) -> 728.99 | E29: =VLOOKUP(E1,SPY!$B$27:$G$278,5,1) -> 754.6 | F29: =VLOOKUP(F1,SPY!$B$27:$G$278,5,1) -> 711.69 | G29: =VLOOKUP(G1,SPY!$B$27:$G$278,5,1) -> 634.09 | H29: =VLOOKUP(H1,SPY!$B$27:$G$278,5,1) -> 685.99 | I29: =VLOOKUP(I1,SPY!$B$27:$G$278,5,1) -> 695.42 | J29: =VLOOKUP(J1,SPY!$B$27:$G$278,5,1) -> 690.31 | ... O29: =VLOOKUP(O1,SPY!$B$27:$G$278,5,1) -> 621.72 | P29: =AVERAGE(D29:O29) -> 683.66667 | Q29: =B29/P29 -> 1.066982 | R29: =(B29/D29)-1 -> 0.00064472764 | S29: =(B29/F29)-1 -> 0.024968736 | T29: =(B29/I29)-1 -> 0.048948837 | U29: =(B29/O29)-1 -> 0.17329344 | V29: =R29*12 -> 0.0077367316 | W29: =S29*12 -> 0.29962484 | X29: =T29*2 -> 0.097897673 | Y29: =U29*1 -> 0.17329344 | Z29: =SUM(V29:Y29) -> 0.57855269
